Workbook

Sheet Справочник ИХ
A1: Код позиции | B1: Подгруппа груза | C1: Группа груза | D1: Класс
A2: 011 | B2: ПШЕНИЦА | C2: Хлебные грузы | D2: =VLOOKUP(A2,[1]Грузы!B:F,5,0) -> 2
A3: 012 | B3: РОЖЬ | C3: Хлебные грузы | D3: =VLOOKUP(A3,[1]Грузы!B:F,5,0) -> 2
A4: 013 | B4: ОВЕС | C4: Хлебные грузы | D4: =VLOOKUP(A4,[1]Грузы!B:F,5,0) -> 2
A5: 014 | B5: ЯЧМЕНЬ | C5: Хлебные грузы | D5: =VLOOKUP(A5,[1]Грузы!B:F,5,0) -> 2
A6: 015 | B6: ЗЕРНО КУКУРУЗЫ | C6: Хлебные грузы | D6: =VLOOKUP(A6,[1]Грузы!B:F,5,0) -> 2
A7: 016 | B7: ПОЧАТКИ КУКУРУЗЫ | C7: Хлебные грузы | D7: =VLOOKUP(A7,[1]Грузы!B:F,5,0) -> 2
A8: 017 | B8: РИС | C8: Хлебные грузы | D8: =VLOOKUP(A8,[1]Грузы!B:F,5,0) -> 2
A9: 018 | B9: ПРОЧИЕ ЗЕРНОВЫЕ | C9: Хлебные грузы | D9: =VLOOKUP(A9,[1]Грузы!B:F,5,0) -> 2
A10: 021 | B10: СЕМЕНА ТЕХНИЧЕСКИХ КУЛЬТУ | C10: Хлебные грузы | D10: =VLOOKUP(A10,[1]Грузы!B:F,5,0) -> 2
A11: 022 | B11: СЕМЕНА ХЛОПЧАТНИКА | C11: Остальные грузы | D11: =VLOOKUP(A11,[1]Грузы!B:F,5,0) -> 2
A12: 023 | B12: СЕМЕНА СВЕКЛЫ САХАРНОЙ | C12: Остальные грузы | D12: =VLOOKUP(A12,[1]Грузы!B:F,5,0) -> 2
A13: 024 | B13: СЕМЕНА ПРОЧИЕ | C13: Хлебные грузы | D13: =VLOOKUP(A13,[1]Грузы!B:F,5,0) -> 2
... A272: 758 | B272: ОТХОДЫ ХИМИЧЕСКОГО ПРОИЗВ | C272: Остальные грузы | D272: =VLOOKUP(A272,[1]Грузы!B:F,5,0) -> 3

Sheet ЕТСНГ
A1: КОДГРУЗА | B1: КОД позиции | C1: НАИМЕНОВАНИЕ | D1: Группа груза | E1: Класс | F1: Раздел ЕТСНГ | G1: Раздел ЕТСНГ корр
C2: Раздел 1. Продукция сельского хозяйства | E2: х
A3: 01000 | B3: =LEFT(A3,3) -> 010 | C3: Зерновые и зернобобовые культуры | D3: =IF(RIGHT(A3,3)="000",C3,VLOOKUP(B3,'Справочник ИХ'!A:C,3,0)) -> Зерновые и зернобобовые культуры | E3: =IF(RIGHT(A3,3)="000","х",VLOOKUP(B3,'Справочник ИХ'!A:D,4,0)) -> х | F3: Зерновые и зернобобовые культуры
A4: 01100 | B4: =LEFT(A4,3) -> 011 | C4: Пшеница | D4: =IF(RIGHT(A4,3)="000",C4,VLOOKUP(B4,'Справочник ИХ'!A:C,3,0)) -> Хлебные грузы | E4: =IF(RIGHT(A4,3)="000","х",VLOOKUP(B4,'Справочник ИХ'!A:D,4,0)) -> 2 | F4: Зерновые и зернобобовые культуры
A5: 01200 | B5: =LEFT(A5,3) -> 012 | C5: Рожь | D5: =IF(RIGHT(A5,3)="000",C5,VLOOKUP(B5,'Справочник ИХ'!A:C,3,0)) -> Хлебные грузы | E5: =IF(RIGHT(A5,3)="000","х",VLOOKUP(B5,'Справочник ИХ'!A:D,4,0)) -> 2 | F5: Зерновые и зернобобовые культуры
A6: 01300 | B6: =LEFT(A6,3) -> 013 | C6: Овес | D6: =IF(RIGHT(A6,3)="000",C6,VLOOKUP(B6,'Справочник ИХ'!A:C,3,0)) -> Хлебные грузы | E6: =IF(RIGHT(A6,3)="000","х",VLOOKUP(B6,'Справочник ИХ'!A:D,4,0)) -> 2 | F6: Зерновые и зернобобовые культуры
A7: 01400 | B7: =LEFT(A7,3) -> 014 | C7: Ячмень | D7: =IF(RIGHT(A7,3)="000",C7,VLOOKUP(B7,'Справочник ИХ'!A:C,3,0)) -> Хлебные грузы | E7: =IF(RIGHT(A7,3)="000","х",VLOOKUP(B7,'Справочник ИХ'!A:D,4,0)) -> 2 | F7: Зерновые и зернобобовые культуры
A8: 01500 | B8: =LEFT(A8,3) -> 015 | C8: Зерно кукурузы | D8: =IF(RIGHT(A8,3)="000",C8,VLOOKUP(B8,'Справочник ИХ'!A:C,3,0)) -> Хлебные грузы | E8: =IF(RIGHT(A8,3)="000","х",VLOOKUP(B8,'Справочник ИХ'!A:D,4,0)) -> 2 | F8: Зерновые и зернобобовые культуры
A9: 01600 | B9: =LEFT(A9,3) -> 016 | C9: Початки кукурузы | D9: =IF(RIGHT(A9,3)="000",C9,VLOOKUP(B9,'Справочник ИХ'!A:C,3,0)) -> Хлебные грузы | E9: =IF(RIGHT(A9,3)="000","х",VLOOKUP(B9,'Справочник ИХ'!A:D,4,0)) -> 2 | F9: Зерновые и зернобобовые культуры
A10: 01700 | B10: =LEFT(A10,3) -> 017 | C10: Рис | D10: =IF(RIGHT(A10,3)="000",C10,VLOOKUP(B10,'Справочник ИХ'!A:C,3,0)) -> Хлебные грузы | E10: =IF(RIGHT(A10,3)="000","х",VLOOKUP(B10,'Справочник ИХ'!A:D,4,0)) -> 2 | F10: Зерновые и зернобобовые культуры
A11: 01701 | B11: =LEFT(A11,3) -> 017 | C11: Рис нешелушеный (рис сырец) | D11: =IF(RIGHT(A11,3)="000",C11,VLOOKUP(B11,'Справочник ИХ'!A:C,3,0)) -> Хлебные грузы | E11: =IF(RIGHT(A11,3)="000","х",VLOOKUP(B11,'Справочник ИХ'!A:D,4,0)) -> 2 | F11: Зерновые и зернобобовые культуры
A12: 01702 | B12: =LEFT(A12,3) -> 017 | C12: Рис шелушеный (неполированый рис) | D12: =IF(RIGHT(A12,3)="000",C12,VLOOKUP(B12,'Справочник ИХ'!A:C,3,0)) -> Хлебные грузы | E12: =IF(RIGHT(A12,3)="000","х",VLOOKUP(B12,'Справочник ИХ'!A:D,4,0)) -> 2 | F12: Зерновые и зернобобовые культуры
A13: 01703 | B13: =LEFT(A13,3) -> 017 | C13: Рис прочий | D13: =IF(RIGHT(A13,3)="000",C13,VLOOKUP(B13,'Справочник ИХ'!A:C,3,0)) -> Хлебные грузы | E13: =IF(RIGHT(A13,3)="000","х",VLOOKUP(B13,'Справочник ИХ'!A:D,4,0)) -> 2 | F13: Зерновые и зернобобовые культуры
A14: 01800 | B14: =LEFT(A14,3) -> 018 | C14: Прочие зерновые | D14: =IF(RIGHT(A14,3)="000",C14,VLOOKUP(B14,'Справочник ИХ'!A:C,3,0)) -> Хлебные грузы | E14: =IF(RIGHT(A14,3)="000","х",VLOOKUP(B14,'Справочник ИХ'!A:D,4,0)) -> 2 | F14: Зерновые и зернобобовые культуры
... A305: 07806 | B305: =LEFT(A305,3) -> 078 | C305: Удобрения органические, не поименованные в алфавите | D305: =IF(RIGHT(A305,3)="000",C305,VLOOKUP(B305,'Справочник ИХ'!A:C,3,0)) -> Остальные грузы | E305: =IF(RIGHT(A305,3)="000","х",VLOOKUP(B305,'Справочник ИХ'!A:D,4,0)) -> 2 | F305: Прочая продукция сельского хозяйства
B306: =LEFT(A306,3) | C306: Раздел 2. Продукция лесной, деревообрабатывающей и целлюлозно-бумажной промышленности | D306: =C306 -> Раздел 2. Продукция лесной, деревообрабатывающей и целлюлозно-бумажной промышленности | E306: х | F306: Прочая продукция сельского хозяйства
A307: 08000 | B307: =LEFT(A307,3) -> 080 | C307: Лесоматериалы круглые | D307: =IF(RIGHT(A307,3)="000",C307,VLOOKUP(B307,'Справочник ИХ'!A:C,3,0)) -> Лесоматериалы круглые | E307: =IF(RIGHT(A307,3)="000","х",VLOOKUP(B307,'Справочник ИХ'!A:D,4,0)) -> х | F307: Лесоматериалы круглые
A308: 08100 | B308: =LEFT(A308,3) -> 081 | C308: Лесоматериалы круглые, кроме крепежных | D308: =IF(RIGHT(A308,3)="000",C308,VLOOKUP(B308,'Справочник ИХ'!A:C,3,0)) -> Лесные грузы | E308: =IF(RIGHT(A308,3)="000","х",VLOOKUP(B308,'Справочник ИХ'!A:D,4,0)) -> 1 | F308: Лесоматериалы круглые
A309: 08101 | B309: =LEFT(A309,3) -> 081 | C309: Бамбук | D309: =IF(RIGHT(A309,3)="000",C309,VLOOKUP(B309,'Справочник ИХ'!A:C,3,0)) -> Лесные грузы | E309: =IF(RIGHT(A309,3)="000","х",VLOOKUP(B309,'Справочник ИХ'!A:D,4,0)) -> 1 | F309: Лесоматериалы круглые
A310: 08102 | B310: =LEFT(A310,3) -> 081 | C310: Балансы всяких пород дерева длиной до 1,5 м включительно, кроме хвойных | D310: =IF(RIGHT(A310,3)="000",C310,VLOOKUP(B310,'Справочник ИХ'!A:C,3,0)) -> Лесные грузы | E310: =IF(RIGHT(A310,3)="000","х",VLOOKUP(B310,'Справочник ИХ'!A:D,4,0)) -> 1 | F310: Лесоматериалы круглые
A311: 08103 | B311: =LEFT(A311,3) -> 081 | C311: Балансы всяких пород дерева длиной свыше 1,5 м, кроме хвойных | D311: =IF(RIGHT(A311,3)="000",C311,VLOOKUP(B311,'Справочник ИХ'!A:C,3,0)) -> Лесные грузы | E311: =IF(RIGHT(A311,3)="000","х",VLOOKUP(B311,'Справочник ИХ'!A:D,4,0)) -> 1 | F311: Лесоматериалы круглые
A312: 08104 | B312: =LEFT(A312,3) -> 081 | C312: Балансы хвойных пород дерева | D312: =IF(RIGHT(A312,3)="000",C312,VLOOKUP(B312,'Справочник ИХ'!A:C,3,0)) -> Лесные грузы | E312: =IF(RIGHT(A312,3)="000","х",VLOOKUP(B312,'Справочник ИХ'!A:D,4,0)) -> 1 | F312: Лесоматериалы круглые
A313: 08105 | B313: =LEFT(A313,3) -> 081 | C313: Древесина экстрактовая | D313: =IF(RIGHT(A313,3)="000",C313,VLOOKUP(B313,'Справочник ИХ'!A:C,3,0)) -> Лесные грузы | E313: =IF(RIGHT(A313,3)="000","х",VLOOKUP(B313,'Справочник ИХ'!A:D,4,0)) -> 1 | F313: Лесоматериалы круглые
A314: 08106 | B314: =LEFT(A314,3) -> 081 | C314: Ель резонансовая круглая | D314: =IF(RIGHT(A314,3)="000",C314,VLOOKUP(B314,'Справочник ИХ'!A:C,3,0)) -> Лесные грузы | E314: =IF(RIGHT(A314,3)="000","х",VLOOKUP(B314,'Справочник ИХ'!A:D,4,0)) -> 1 | F314: Лесоматериалы круглые
A315: 08107 | B315: =LEFT(A315,3) -> 081 | C315: Жерди и колья | D315: =IF(RIGHT(A315,3)="000",C315,VLOOKUP(B315,'Справочник ИХ'!A:C,3,0)) -> Лесные грузы | E315: =IF(RIGHT(A315,3)="000","х",VLOOKUP(B315,'Справочник ИХ'!A:D,4,0)) -> 1 | F315: Лесоматериалы круглые
A316: 08108 | B316: =LEFT(A316,3) -> 081 | C316: Кряж всяких пород дерева | D316: =IF(RIGHT(A316,3)="000",C316,VLOOKUP(B316,'Справочник ИХ'!A:C,3,0)) -> Лесные грузы | E316: =IF(RIGHT(A316,3)="000","х",VLOOKUP(B316,'Справочник ИХ'!A:D,4,0)) -> 1 | F316: Лесоматериалы круглые
A317: 08109 | B317: =LEFT(A317,3) -> 081 | C317: Лесоматериалы всяких пород длиной до 2 м включительно | D317: =IF(RIGHT(A317,3)="000",C317,VLOOKUP(B317,'Справочник ИХ'!A:C,3,0)) -> Лесные грузы | E317: =IF(RIGHT(A317,3)="000","х",VLOOKUP(B317,'Справочник ИХ'!A:D,4,0)) -> 1 | F317: Лесоматериалы круглые
A318: 08110 | B318: =LEFT(A318,3) -> 081 | C318: Лесоматериалы всяких пород длиной свыше 2 м | D318: =IF(RIGHT(A318,3)="000",C318,VLOOKUP(B318,'Справочник ИХ'!A:C,3,0)) -> Лесные грузы | E318: =IF(RIGHT(A318,3)="000","х",VLOOKUP(B318,'Справочник ИХ'!A:D,4,0)) -> 1 | F318: Лесоматериалы круглые
... A372: 09410 | B372: =LEFT(A372,3) -> 094 | C372: Шпон лущеный и строганый | D372: =IF(RIGHT(A372,3)="000",C372,VLOOKUP(B372,'Справочник ИХ'!A:C,3,0)) -> Лесные грузы | E372: =IF(RIGHT(A372,3)="000","х",VLOOKUP(B372,'Справочник ИХ'!A:D,4,0)) -> 3 | F372: Продукция лесопильного и фанерного производства
A373: 10000 | B373: =LEFT(A373,3) -> 100 | C373: Дрова, древесина дровяная для технологических нужд, древесина измельченная | D373: =IF(RIGHT(A373,3)="000",C373,VLOOKUP(B373,'Справочник ИХ'!A:C,3,0)) -> Дрова, древесина дровяная для технологических нужд, древесина измельченная | E373: =IF(RIGHT(A373,3)="000","х",VLOOKUP(B373,'Справочник ИХ'!A:D,4,0)) -> х | F373: Дрова, древесина дровяная для технологических нужд, древесина измельченная
A374: 10100 | B374: =LEFT(A374,3) -> 101 | C374: Дрова | D374: =IF(RIGHT(A374,3)="000",C374,VLOOKUP(B374,'Справочник ИХ'!A:C,3,0)) -> Лесные грузы | E374: =IF(RIGHT(A374,3)="000","х",VLOOKUP(B374,'Справочник ИХ'!A:D,4,0)) -> 1 | F374: Дрова, древесина дровяная для технологических нужд, древесина измельченная
A375: 10101 | B375: =LEFT(A375,3) -> 101 | C375: Дрова долготье | D375: =IF(RIGHT(A375,3)="000",C375,VLOOKUP(B375,'Справочник ИХ'!A:C,3,0)) -> Лесные грузы | E375: =IF(RIGHT(A375,3)="000","х",VLOOKUP(B375,'Справочник ИХ'!A:D,4,0)) -> 1 | F375: Дрова, древесина дровяная для технологических нужд, древесина измельченная
A376: 10102 | B376: =LEFT(A376,3) -> 101 | C376: Дрова из всяких пород дерева, не поименованные в алфавите | D376: =IF(RIGHT(A376,3)="000",C376,VLOOKUP(B376,'Справочник ИХ'!A:C,3,0)) -> Лесные грузы | E376: =IF(RIGHT(A376,3)="000","х",VLOOKUP(B376,'Справочник ИХ'!A:D,4,0)) -> 1 | F376: Дрова, древесина дровяная для технологических нужд, древесина измельченная
A377: 10103 | B377: =LEFT(A377,3) -> 101 | C377: Корни, пни древесные | D377: =IF(RIGHT(A377,3)="000",C377,VLOOKUP(B377,'Справочник ИХ'!A:C,3,0)) -> Лесные грузы | E377: =IF(RIGHT(A377,3)="000","х",VLOOKUP(B377,'Справочник ИХ'!A:D,4,0)) -> 1 | F377: Дрова, древесина дровяная для технологических нужд, древесина измельченная
A378: 10104 | B378: =LEFT(A378,3) -> 101 | C378: Хворост | D378: =IF(RIGHT(A378,3)="000",C378,VLOOKUP(B378,'Справочник ИХ'!A:C,3,0)) -> Лесные грузы | E378: =IF(RIGHT(A378,3)="000","х",VLOOKUP(B378,'Справочник ИХ'!A:D,4,0)) -> 1 | F378: Дрова, древесина дровяная для технологических нужд, древесина измельченная
A379: 10200 | B379: =LEFT(A379,3) -> 102 | C379: Древесина дровяная для технологических нужд | D379: =IF(RIGHT(A379,3)="000",C379,VLOOKUP(B379,'Справочник ИХ'!A:C,3,0)) -> Лесные грузы | E379: =IF(RIGHT(A379,3)="000","х",VLOOKUP(B379,'Справочник ИХ'!A:D,4,0)) -> 1 | F379: Дрова, древесина дровяная для технологических нужд, древесина измельченная
A380: 10201 | B380: =LEFT(A380,3) -> 102 | C380: Древесина дровяная для гидролизного производства | D380: =IF(RIGHT(A380,3)="000",C380,VLOOKUP(B380,'Справочник ИХ'!A:C,3,0)) -> Лесные грузы | E380: =IF(RIGHT(A380,3)="000","х",VLOOKUP(B380,'Справочник ИХ'!A:D,4,0)) -> 1 | F380: Дрова, древесина дровяная для технологических нужд, древесина измельченная
A381: 10202 | B381: =LEFT(A381,3) -> 102 | C381: Древесина дровяная для технологических нужд, не поименованная в алфавите | D381: =IF(RIGHT(A381,3)="000",C381,VLOOKUP(B381,'Справочник ИХ'!A:C,3,0)) -> Лесные грузы | E381: =IF(RIGHT(A381,3)="000","х",VLOOKUP(B381,'Справочник ИХ'!A:D,4,0)) -> 1 | F381: Дрова, древесина дровяная для технологических нужд, древесина измельченная
A382: 10300 | B382: =LEFT(A382,3) -> 103 | C382: Древесина измельченная | D382: =IF(RIGHT(A382,3)="000",C382,VLOOKUP(B382,'Справочник ИХ'!A:C,3,0)) -> Лесные грузы | E382: =IF(RIGHT(A382,3)="000","х",VLOOKUP(B382,'Справочник ИХ'!A:D,4,0)) -> 1 | F382: Дрова, древесина дровяная для технологических нужд, древесина измельченная
A383: 10301 | B383: =LEFT(A383,3) -> 103 | C383: Мука древесная, не поименованная в алфавите | D383: =IF(RIGHT(A383,3)="000",C383,VLOOKUP(B383,'Справочник ИХ'!A:C,3,0)) -> Лесные грузы | E383: =IF(RIGHT(A383,3)="000","х",VLOOKUP(B383,'Справочник ИХ'!A:D,4,0)) -> 1 | F383: Дрова, древесина дровяная для технологических нужд, древесина измельченная
...

Sheet Лист1
A1: Остальные грузы

Sheet Лист2
A1: Головки маковые с зерном

Sheet Лист3
