Workbook
Name ccc: #REF!
Name cmndBase: #REF!
Name cmndDayMonthTo: #REF!
Name cmndDays: #REF!
Name cmndDocNum: #REF!
Name cmndDocSer: #REF!
Name cmndFIO: #REF!
Name cmndOrdDay: #REF!
Name cmndOrdMonth: #REF!
Name cmndOrdNum: #REF!
Name cmndOrdYear: #REF!
Name cmndPoint: #REF!
Name cmndPoint1: #REF!
Name cmndPos: #REF!
Name cmndYearTo: #REF!
Name cntAddition: #REF!
Name cntDay: #REF!
Name cntMonth: #REF!
Name cntName: #REF!
Name cntNumber: #REF!
Name cntPayer: #REF!
Name cntPayer1: #REF!
Name cntPayerAddr1: #REF!
Name cntPayerAddr2: #REF!
Name cntPayerBank1: #REF!
Name cntPayerBank2: #REF!
Name cntPayerBank3: #REF!
Name cntPayerCount: #REF!
Name cntPayerCountCor: #REF!
Name cntPriceC: #REF!
Name cntPriceR: #REF!
Name cntQnt: #REF!
Name cntSumC: #REF!
Name cntSumR: #REF!
Name cntSuppAddr1: #REF!
Name cntSuppAddr2: #REF!
Name cntSuppBank: #REF!
Name cntSuppCount: #REF!
Name cntSuppCountCor: #REF!
Name cntSupplier: #REF!
Name cntSuppMFO1: #REF!
Name cntSuppMFO2: #REF!
Name cntSuppTlf: #REF!
Name cntUnit: #REF!
Name cntYear: #REF!
Name DF_GRID_2: История [1]корректировок!$C$10:$I$11
Name DF_NAVPANEL_13: [2]Отчет!#REF!
Name DF_NAVPANEL_18: [2]Отчет!#REF!
Name dvrCustomer: #REF!
Name dvrDay: #REF!
Name dvrDocDay: #REF!
Name dvrDocIss: #REF!
Name dvrDocMonth: #REF!
Name dvrDocNum: #REF!
Name dvrDocSer: #REF!
Name dvrDocYear: #REF!
Name dvrMonth: #REF!
Name dvrName: #REF!
Name dvrNo: #REF!
Name dvrNumber: #REF!

Sheet Лесные
A2: параметры перевозок | Y2: действующие тарифные условия | AR2: Коэффициент сохранения грузовой базы ИПЕМ | AT2: Изменение тарифа ОАО "РЖД"
A3: Код группы груза | B3: Группа груза | C3: Код груза | D3: Наим груза | E3: Вид груза | F3: Дор отпр | G3: Дор наз | H3: Станц отпр РФ | I3: Станц назн РФ | J3: Средняя дальность(км) | K3: Род вагона | L3: Вид перевозки | M3: Признак контейнерной отправки | N3: Направление | O3: ОКПО компании | P3: Компания отправителя | Q3: Холдинг отправителя | R3: Объем перевозок (тн) | S3: Грузооборот, ткм | T3: Кол-во вагонов | U3: Кол-во контейнеров | V3: Провозная плата, руб | W3: Категория отправки | X3: Загрузка вагона | Y3: Расходы по оплате услуг ОАО 'РЖД', руб. за тонну гружёный рейс | Z3: Расходы по оплате услуг ОАО 'РЖД', руб. за тонну порожний рейс | AA3: Расходы по оплате услуг ОАО 'РЖД', руб. за тонну общая стоимость | AB3: Груженый рейс, суток | AC3: Порожний рейс, суток | AD3: ПРР | AE3: Расходы по оплате услуг операторов, руб. за тонну | AF3: Расходы на перевалку, руб. за тонну | AG3: Акциз/пошлина | AH3: Себестоимость добычи/производства, руб. т. | AI3: Стоимость 1 тонны на рынке, руб./т. | AJ3: Стоимость 1 тонны на рынке, $/т. | AK3: Общие транспортные расходы, руб. за тонну | AL3: Нетбэк, руб. за тонну | AM3: Общие расходы, руб. за тонну | AN3: Маржинальность | AO3: Транспортная составляющая в цене % | AP3: Инфраструктурная составляющая в цене % | AQ3: Инфраструктурная составляющая в транспортных затратах | AS3: Кэффициент загрузки предприятяи | AT3: -0.25 | AU3: -0.245 | AV3: -0.24 | AW3: -0.235 | AX3: -0.23 | AY3: -0.225 | AZ3: -0.22 | BA3: -0.215 | BB3: -0.21 | BC3: -0.205 | BD3: -0.2 | BE3: -0.195 | BF3: -0.19 | BG3: -0.185 | BH3: -0.18 | BI3: -0.175 | BJ3: -0.17 | BK3: -0.165 | BL3: -0.16 | BM3: -0.155 | BN3: -0.15 | BO3: -0.145 | BP3: -0.14 | BQ3: -0.135 | BR3: -0.13 | BS3: -0.125 | BT3: -0.12 | BU3: -0.115 | BV3: -0.11 | BW3: -0.105 | BX3: -0.1 | BY3: -0.095 | BZ3: -0.09 | CA3: -0.085 | CB3: -0.08 | CC3: -0.075 | CD3: -0.07 | CE3: -0.065 | CF3: -0.06 | CG3: -0.055 | CH3: -0.05 | CI3: -0.045 | CJ3: -0.04 | CK3: -0.035 | CL3: -0.03 | CM3: -0.025 | CN3: -0.02 | CO3: -0.015 | CP3: -0.01 | CQ3: -0.005 | CR3: 0 | CS3: 0.005 | CT3: 0.01 | CU3: 0.015 | CV3: 0.02 | CW3: 0.025 | CX3: 0.03 | CY3: 0.035 | CZ3: 0.04 | DA3: 0.045 | DB3: 0.05 | DC3: 0.055 | DD3: 0.06 | DE3: 0.065 | DF3: 0.07 | DG3: 0.075 | DH3: 0.08 | DI3: 0.085 | DJ3: 0.09 | DK3: 0.095 | DL3: 0.1 | DM3: 0.105 | DN3: 0.11 | DO3: 0.115 | DP3: 0.12 | DQ3: 0.125 | DR3: 0.13 | DS3: 0.135 | DT3: 0.14 | DU3: 0.145 | DV3: 0.15 | DW3: 0.155 | DX3: 0.16 | DY3: 0.165 | DZ3: 0.17 | EA3: 0.175 | EB3: 0.18 | EC3: 0.185 | ED3: 0.19 | EE3: 0.195 | EF3: 0.2 | EG3: 0.205 | EH3: 0.21 | EI3: 0.215 | EJ3: 0.22 | EK3: 0.225 | EL3: 0.23 | EM3: 0.235 | EN3: 0.24 | EO3: 0.245 | EP3: 0.25 | EQ3: 0.255 | ER3: 0.26 | ES3: 0.265 | ET3: 0.27 | EU3: 0.275 | EV3: 0.28 | EW3: 0.285 | EX3: 0.29 | EY3: 0.295 | EZ3: 0.3 | FA3: 0.305 | FB3: 0.31 | FC3: 0.315 | FD3: 0.32 | FE3: 0.325 | FF3: 0.33 | FG3: 0.335 | FH3: 0.34 | FI3: 0.345 | FJ3: 0.35 | FK3: 0.355 | FL3: 0.36 | FM3: 0.365 | FN3: 0.37 | FO3: 0.375 | FP3: 0.38 | FQ3: 0.385 | FR3: 0.39 | FS3: 0.395 | FT3: 0.4 | FU3: 0.405 | FV3: 0.41 | FW3: 0.415 | FX3: 0.42 | FY3: 0.425 | FZ3: 0.43 | GA3: 0.435 | GB3: 0.44 | GC3: 0.445 | GD3: 0.45 | GE3: 0.455 | GF3: 0.46 | GG3: 0.465 | GH3: 0.47 | GI3: 0.475 | GJ3: 0.48 | GK3: 0.485 | GL3: 0.49 | GM3: 0.495 | GN3: 0.5
A4: 6 | B4: Лесные грузы | C4: 09111 | D4: ПИЛМАТ ПР | E4: ПИЛОМАТЕРИАЛЫ | F4: КРС | G4: ДВС | H4: ЛЕСОСИБИРСК | I4: НАХОДКА-В-ЭК | J4: 806 | K4: Платформы | L4: Экспорт | M4: контейнерная | N4: Восточное | O4: 000005029043 | P4: АО "ЛЕСОСИБИРСКИЙ ЛДК № 1" | Q4: ГК "Сегежа" | R4: 94299 | S4: 547497806 | T4: 1231 | U4: 3202 | V4: 400589797 | W4: контейнерная | X4: 68 | Y4: =369536/X4 -> 5434.3529 | Z4: 0 | AA4: =Y4 -> 5434.3529 | AB4: 17 | AC4: 0 | AD4: 4 | AE4: ='Ставки аренды'!$B$4*SUM(Лесные!AB4+Лесные!AC4+Лесные!AD4)/Лесные!X4 -> 494.11765 | AF4: ='Ставки перевалки'!$B$2/X4*2 -> 661.76471 | AH4: =0.86*AI4 -> 21301.538 | AI4: =Цены!$C$3 -> 24769.231 | AN4: =(AI4-AH4-AG4-AF4-AE4-AA4)/AI4 -> -0.1260654 | AS4: 0.8 | AT4: =MIN(IF($AS4=100%,1,1+VLOOKUP(($AI4-$AH4-$AG4-$AF4-$AE4-$AA4*(1+AT$3))/$AI4,'Технический лист'!$A:$B,2,1)-VLOOKUP($AN4,'Технический лист'!$A:$B,2,1)),1+(1-$AS4)) -> 1.2 | AU4: =MIN(IF($AS4=100%,1,1+VLOOKUP(($AI4-$AH4-$AG4-$AF4-$AE4-$AA4*(1+AU$3))/$AI4,'Технический лист'!$A:$B,2,1)-VLOOKUP($AN4,'Технический лист'!$A:$B,2,1)),1+(1-$AS4)) -> 1.2 | AV4: =MIN(IF($AS4=100%,1,1+VLOOKUP(($AI4-$AH4-$AG4-$AF4-$AE4-$AA4*(1+AV$3))/$AI4,'Технический лист'!$A:$B,2,1)-VLOOKUP($AN4,'Технический лист'!$A:$B,2,1)),1+(1-$AS4)) -> 1.2 | AW4: =MIN(IF($AS4=100%,1,1+VLOOKUP(($AI4-$AH4-$AG4-$AF4-$AE4-$AA4*(1+AW$3))/$AI4,'Технический лист'!$A:$B,2,1)-VLOOKUP($AN4,'Технический лист'!$A:$B,2,1)),1+(1-$AS4)) -> 1.2 | AX4: =MIN(IF($AS4=100%,1,1+VLOOKUP(($AI4-$AH4-$AG4-$AF4-$AE4-$AA4*(1+AX$3))/$AI4,'Технический лист'!$A:$B,2,1)-VLOOKUP($AN4,'Технический лист'!$A:$B,2,1)),1+(1-$AS4)) -> 1.2 | AY4: =MIN(IF($AS4=100%,1,1+VLOOKUP(($AI4-$AH4-$AG4-$AF4-$AE4-$AA4*(1+AY$3))/$AI4,'Технический лист'!$A:$B,2,1)-VLOOKUP($AN4,'Технический лист'!$A:$B,2,1)),1+(1-$AS4)) -> 1.2 | AZ4: =MIN(IF($AS4=100%,1,1+VLOOKUP(($AI4-$AH4-$AG4-$AF4-$AE4-$AA4*(1+AZ$3))/$AI4,'Технический лист'!$A:$B,2,1)-VLOOKUP($AN4,'Технический лист'!$A:$B,2,1)),1+(1-$AS4)) -> 1.2 | BA4: =MIN(IF($AS4=100%,1,1+VLOOKUP(($AI4-$AH4-$AG4-$AF4-$AE4-$AA4*(1+BA$3))/$AI4,'Технический лист'!$A:$B,2,1)-VLOOKUP($AN4,'Технический лист'!$A:$B,2,1)),1+(1-$AS4)) -> 1.2 | ... CQ4: =MIN(IF($AS4=100%,1,1+VLOOKUP(($AI4-$AH4-$AG4-$AF4-$AE4-$AA4*(1+CQ$3))/$AI4,'Технический лист'!$A:$B,2,1)-VLOOKUP($AN4,'Технический лист'!$A:$B,2,1)),1+(1-$AS4)) -> 1.04 | CR4: 1 | CS4: =MIN(1,MAX(VLOOKUP(($AI4-$AH4-$AG4-$AF4-$AE4-$AA4*(1+CS$3))/$AI4,'[8]Технический лист'!$A:$B,2,1),(CR4-0.05))) -> 0.95 | CT4: =MIN(1,MAX(VLOOKUP(($AI4-$AH4-$AG4-$AF4-$AE4-$AA4*(1+CT$3))/$AI4,'[8]Технический лист'!$A:$B,2,1),(CS4-0.05))) -> 0.9 | CU4: =MIN(1,MAX(VLOOKUP(($AI4-$AH4-$AG4-$AF4-$AE4-$AA4*(1+CU$3))/$AI4,'[8]Технический лист'!$A:$B,2,1),(CT4-0.05))) -> 0.85 | CV4: =MIN(1,MAX(VLOOKUP(($AI4-$AH4-$AG4-$AF4-$AE4-$AA4*(1+CV$3))/$AI4,'[8]Технический лист'!$A:$B,2,1),(CU4-0.05))) -> 0.8 | CW4: =MIN(1,MAX(VLOOKUP(($AI4-$AH4-$AG4-$AF4-$AE4-$AA4*(1+CW$3))/$AI4,'[8]Технический лист'!$A:$B,2,1),(CV4-0.05))) -> 0.75 | CX4: =MIN(1,MAX(VLOOKUP(($AI4-$AH4-$AG4-$AF4-$AE4-$AA4*(1+CX$3))/$AI4,'[8]Технический лист'!$A:$B,2,1),(CW4-0.05))) -> 0.71 | CY4: =MIN(1,MAX(VLOOKUP(($AI4-$AH4-$AG4-$AF4-$AE4-$AA4*(1+CY$3))/$AI4,'[8]Технический лист'!$A:$B,2,1),(CX4-0.05))) -> 0.71 | CZ4: =MIN(1,MAX(VLOOKUP(($AI4-$AH4-$AG4-$AF4-$AE4-$AA4*(1+CZ$3))/$AI4,'[8]Технический лист'!$A:$B,2,1),(CY4-0.05))) -> 0.71 | ... GN4: =MIN(1,MAX(VLOOKUP(($AI4-$AH4-$AG4-$AF4-$AE4-$AA4*(1+GN$3))/$AI4,'[8]Технический лист'!$A:$B,2,1),(GM4-0.05))) -> 0
A5: 6 | B5: Лесные грузы | C5: 09111 | D5: ПИЛМАТ ПР | E5: ПИЛОМАТЕРИАЛЫ | F5: ВСБ | G5: ДВС | H5: ИГИРМА | I5: НАХОДКА-В-ЭК | J5: 668 | K5: Платформы | L5: Экспорт | M5: контейнерная | N5: Восточное | O5: 000093565189 | P5: ООО "ТАЙРИКУ-ИГИРМА ГРУПП" | Q5: ГК "Русская лесная группа" | R5: 83674 | S5: 390548917 | T5: 0 | U5: 2869 | V5: 300954270 | W5: контейнерная | X5: 68 | Y5: =312098/X5 -> 4589.6765 | Z5: 0 | AA5: =Y5 -> 4589.6765 | AB5: 14 | AC5: 0 | AD5: 4 | AE5: ='Ставки аренды'!$B$4*SUM(Лесные!AB5+Лесные!AC5+Лесные!AD5)/Лесные!X5 -> 423.52941 | AF5: ='Ставки перевалки'!$B$2/X5*2 -> 661.76471 | AH5: =0.85*AI5 -> 21053.846 | AI5: =Цены!$C$3 -> 24769.231 | AN5: =(AI5-AH5-AG5-AF5-AE5-AA5)/AI5 -> -0.079113719 | AS5: 0.8 | AT5: =MIN(IF($AS5=100%,1,1+VLOOKUP(($AI5-$AH5-$AG5-$AF5-$AE5-$AA5*(1+AT$3))/$AI5,'Технический лист'!$A:$B,2,1)-VLOOKUP($AN5,'Технический лист'!$A:$B,2,1)),1+(1-$AS5)) -> 1.195 | AU5: =MIN(IF($AS5=100%,1,1+VLOOKUP(($AI5-$AH5-$AG5-$AF5-$AE5-$AA5*(1+AU$3))/$AI5,'Технический лист'!$A:$B,2,1)-VLOOKUP($AN5,'Технический лист'!$A:$B,2,1)),1+(1-$AS5)) -> 1.195 | AV5: =MIN(IF($AS5=100%,1,1+VLOOKUP(($AI5-$AH5-$AG5-$AF5-$AE5-$AA5*(1+AV$3))/$AI5,'Технический лист'!$A:$B,2,1)-VLOOKUP($AN5,'Технический лист'!$A:$B,2,1)),1+(1-$AS5)) -> 1.195 | AW5: =MIN(IF($AS5=100%,1,1+VLOOKUP(($AI5-$AH5-$AG5-$AF5-$AE5-$AA5*(1+AW$3))/$AI5,'Технический лист'!$A:$B,2,1)-VLOOKUP($AN5,'Технический лист'!$A:$B,2,1)),1+(1-$AS5)) -> 1.18 | AX5: =MIN(IF($AS5=100%,1,1+VLOOKUP(($AI5-$AH5-$AG5-$AF5-$AE5-$AA5*(1+AX$3))/$AI5,'Технический лист'!$A:$B,2,1)-VLOOKUP($AN5,'Технический лист'!$A:$B,2,1)),1+(1-$AS5)) -> 1.18 | AY5: =MIN(IF($AS5=100%,1,1+VLOOKUP(($AI5-$AH5-$AG5-$AF5-$AE5-$AA5*(1+AY$3))/$AI5,'Технический лист'!$A:$B,2,1)-VLOOKUP($AN5,'Технический лист'!$A:$B,2,1)),1+(1-$AS5)) -> 1.18 | AZ5: =MIN(IF($AS5=100%,1,1+VLOOKUP(($AI5-$AH5-$AG5-$AF5-$AE5-$AA5*(1+AZ$3))/$AI5,'Технический лист'!$A:$B,2,1)-VLOOKUP($AN5,'Технический лист'!$A:$B,2,1)),1+(1-$AS5)) -> 1.18 | BA5: =MIN(IF($AS5=100%,1,1+VLOOKUP(($AI5-$AH5-$AG5-$AF5-$AE5-$AA5*(1+BA$3))/$AI5,'Технический лист'!$A:$B,2,1)-VLOOKUP($AN5,'Технический лист'!$A:$B,2,1)),1+(1-$AS5)) -> 1.18 | ... CQ5: =MIN(IF($AS5=100%,1,1+VLOOKUP(($AI5-$AH5-$AG5-$AF5-$AE5-$AA5*(1+CQ$3))/$AI5,'Технический лист'!$A:$B,2,1)-VLOOKUP($AN5,'Технический лист'!$A:$B,2,1)),1+(1-$AS5)) -> 1 | CR5: 1 | CS5: =MIN(1,MAX(VLOOKUP(($AI5-$AH5-$AG5-$AF5-$AE5-$AA5*(1+CS$3))/$AI5,'[8]Технический лист'!$A:$B,2,1),(CR5-0.05))) -> 0.95 | CT5: =MIN(1,MAX(VLOOKUP(($AI5-$AH5-$AG5-$AF5-$AE5-$AA5*(1+CT$3))/$AI5,'[8]Технический лист'!$A:$B,2,1),(CS5-0.05))) -> 0.9 | CU5: =MIN(1,MAX(VLOOKUP(($AI5-$AH5-$AG5-$AF5-$AE5-$AA5*(1+CU$3))/$AI5,'[8]Технический лист'!$A:$B,2,1),(CT5-0.05))) -> 0.885 | CV5: =MIN(1,MAX(VLOOKUP(($AI5-$AH5-$AG5-$AF5-$AE5-$AA5*(1+CV$3))/$AI5,'[8]Технический лист'!$A:$B,2,1),(CU5-0.05))) -> 0.885 | CW5: =MIN(1,MAX(VLOOKUP(($AI5-$AH5-$AG5-$AF5-$AE5-$AA5*(1+CW$3))/$AI5,'[8]Технический лист'!$A:$B,2,1),(CV5-0.05))) -> 0.885 | CX5: =MIN(1,MAX(VLOOKUP(($AI5-$AH5-$AG5-$AF5-$AE5-$AA5*(1+CX$3))/$AI5,'[8]Технический лист'!$A:$B,2,1),(CW5-0.05))) -> 0.885 | CY5: =MIN(1,MAX(VLOOKUP(($AI5-$AH5-$AG5-$AF5-$AE5-$AA5*(1+CY$3))/$AI5,'[8]Технический лист'!$A:$B,2,1),(CX5-0.05))) -> 0.87 | CZ5: =MIN(1,MAX(VLOOKUP(($AI5-$AH5-$AG5-$AF5-$AE5-$AA5*(1+CZ$3))/$AI5,'[8]Технический лист'!$A:$B,2,1),(CY5-0.05))) -> 0.87 | ... GN5: =MIN(1,MAX(VLOOKUP(($AI5-$AH5-$AG5-$AF5-$AE5-$AA5*(1+GN$3))/$AI5,'[8]Технический лист'!$A:$B,2,1),(GM5-0.05))) -> 0.49
A6: 6 | B6: Лесные грузы | C6: 12202 | D6: ПЛИТЫ ДСП | E6: ПЛИТЫ ДРЕВЕСНОСТРУЖЕЧНЫЕ | F6: ЗСБ | G6: ЗСБ | H6: ТОМСК-ГРУЗ. | I6: КУЛУНДА-ЭК-Р | J6: 09 | K6: Крытые | L6: Экспорт | M6: неконтейнерная | N6: Южное | O6: 00036308593 | P6: ООО "ГРЕЙС" | Q6: Прочие | R6: 147674 | S6: 134235464 | T6: 2222 | U6: 0 | V6: 271127201 | W6: повагонная | X6: 66 | Y6: 2029.14 | Z6: =AA6-Y6 -> 279.88 | AA6: 2309.02 | AB6: 6 | AC6: 2 | AD6: 4 | AE6: ='Ставки аренды'!$B$3*SUM(Лесные!AB6+Лесные!AC6+Лесные!AD6)/Лесные!X6 -> 545.45455 | AF6: 0 | AH6: =1.02*AI6 -> 24750 | AI6: =Цены!$C$5 -> 24264.706 | AN6: =(AI6-AH6-AG6-AF6-AE6-AA6)/AI6 -> -0.13763895 | AS6: 0.8 | AT6: =MIN(IF($AS6=100%,1,1+VLOOKUP(($AI6-$AH6-$AG6-$AF6-$AE6-$AA6*(1+AT$3))/$AI6,'Технический лист'!$A:$B,2,1)-VLOOKUP($AN6,'Технический лист'!$A:$B,2,1)),1+(1-$AS6)) -> 1.195 | AU6: =MIN(IF($AS6=100%,1,1+VLOOKUP(($AI6-$AH6-$AG6-$AF6-$AE6-$AA6*(1+AU$3))/$AI6,'Технический лист'!$A:$B,2,1)-VLOOKUP($AN6,'Технический лист'!$A:$B,2,1)),1+(1-$AS6)) -> 1.195 | AV6: =MIN(IF($AS6=100%,1,1+VLOOKUP(($AI6-$AH6-$AG6-$AF6-$AE6-$AA6*(1+AV$3))/$AI6,'Технический лист'!$A:$B,2,1)-VLOOKUP($AN6,'Технический лист'!$A:$B,2,1)),1+(1-$AS6)) -> 1.195 | AW6: =MIN(IF($AS6=100%,1,1+VLOOKUP(($AI6-$AH6-$AG6-$AF6-$AE6-$AA6*(1+AW$3))/$AI6,'Технический лист'!$A:$B,2,1)-VLOOKUP($AN6,'Технический лист'!$A:$B,2,1)),1+(1-$AS6)) -> 1.16 | AX6: =MIN(IF($AS6=100%,1,1+VLOOKUP(($AI6-$AH6-$AG6-$AF6-$AE6-$AA6*(1+AX$3))/$AI6,'Технический лист'!$A:$B,2,1)-VLOOKUP($AN6,'Технический лист'!$A:$B,2,1)),1+(1-$AS6)) -> 1.16 | AY6: =MIN(IF($AS6=100%,1,1+VLOOKUP(($AI6-$AH6-$AG6-$AF6-$AE6-$AA6*(1+AY$3))/$AI6,'Технический лист'!$A:$B,2,1)-VLOOKUP($AN6,'Технический лист'!$A:$B,2,1)),1+(1-$AS6)) -> 1.16 | AZ6: =MIN(IF($AS6=100%,1,1+VLOOKUP(($AI6-$AH6-$AG6-$AF6-$AE6-$AA6*(1+AZ$3))/$AI6,'Технический лист'!$A:$B,2,1)-VLOOKUP($AN6,'Технический лист'!$A:$B,2,1)),1+(1-$AS6)) -> 1.16 | BA6: =MIN(IF($AS6=100%,1,1+VLOOKUP(($AI6-$AH6-$AG6-$AF6-$AE6-$AA6*(1+BA$3))/$AI6,'Технический лист'!$A:$B,2,1)-VLOOKUP($AN6,'Технический лист'!$A:$B,2,1)),1+(1-$AS6)) -> 1.16 | ... CQ6: =MIN(IF($AS6=100%,1,1+VLOOKUP(($AI6-$AH6-$AG6-$AF6-$AE6-$AA6*(1+CQ$3))/$AI6,'Технический лист'!$A:$B,2,1)-VLOOKUP($AN6,'Технический лист'!$A:$B,2,1)),1+(1-$AS6)) -> 1 | CR6: 1 | CS6: =MIN(1,MAX(VLOOKUP(($AI6-$AH6-$AG6-$AF6-$AE6-$AA6*(1+CS$3))/$AI6,'[8]Технический лист'!$A:$B,2,1),(CR6-0.05))) -> 0.95 | CT6: =MIN(1,MAX(VLOOKUP(($AI6-$AH6-$AG6-$AF6-$AE6-$AA6*(1+CT$3))/$AI6,'[8]Технический лист'!$A:$B,2,1),(CS6-0.05))) -> 0.9 | CU6: =MIN(1,MAX(VLOOKUP(($AI6-$AH6-$AG6-$AF6-$AE6-$AA6*(1+CU$3))/$AI6,'[8]Технический лист'!$A:$B,2,1),(CT6-0.05))) -> 0.85 | CV6: =MIN(1,MAX(VLOOKUP(($AI6-$AH6-$AG6-$AF6-$AE6-$AA6*(1+CV$3))/$AI6,'[8]Технический лист'!$A:$B,2,1),(CU6-0.05))) -> 0.8 | CW6: =MIN(1,MAX(VLOOKUP(($AI6-$AH6-$AG6-$AF6-$AE6-$AA6*(1+CW$3))/$AI6,'[8]Технический лист'!$A:$B,2,1),(CV6-0.05))) -> 0.75 | CX6: =MIN(1,MAX(VLOOKUP(($AI6-$AH6-$AG6-$AF6-$AE6-$AA6*(1+CX$3))/$AI6,'[8]Технический лист'!$A:$B,2,1),(CW6-0.05))) -> 0.7 | CY6: =MIN(1,MAX(VLOOKUP(($AI6-$AH6-$AG6-$AF6-$AE6-$AA6*(1+CY$3))/$AI6,'[8]Технический лист'!$A:$B,2,1),(CX6-0.05))) -> 0.66 | CZ6: =MIN(1,MAX(VLOOKUP(($AI6-$AH6-$AG6-$AF6-$AE6-$AA6*(1+CZ$3))/$AI6,'[8]Технический лист'!$A:$B,2,1),(CY6-0.05))) -> 0.66 | ... GN6: =MIN(1,MAX(VLOOKUP(($AI6-$AH6-$AG6-$AF6-$AE6-$AA6*(1+GN$3))/$AI6,'[8]Технический лист'!$A:$B,2,1),(GM6-0.05))) -> 0.39
A7: 6 | B7: Лесные грузы | C7: 09111 | D7: ПИЛМАТ ПР | E7: ПИЛОМАТЕРИАЛЫ | F7: СВР | G7: ЗАБ | H7: АЛЯБЬЕВО | I7: ЗАБАЙКАЛ ЭК | J7: 524 | K7: Платформы | L7: Экспорт | M7: контейнерная | N7: Восточное | O7: 00072309814 | P7: АО "ЮГОРСКИЙ ЛЕСОПРОМЫШЛЕННЫЙ ХОЛДИНГ" | Q7: О "Югорский ЛПХ" | R7: 43568 | S7: 240656735 | T7: 0 | U7: 1509 | V7: 185370932 | W7: контейнерная | X7: 68 | Y7: =362574/X7 -> 5331.9706 | Z7: 0 | AA7: =Y7 -> 5331.9706 | AB7: 16 | AC7: 0 | AD7: 4 | AE7: ='Ставки аренды'!$B$4*SUM(Лесные!AB7+Лесные!AC7+Лесные!AD7)/Лесные!X7 -> 470.58824 | AF7: 0 | AH7: =0.74*AI7 -> 18329.231 | AI7: =Цены!$C$3 -> 24769.231 | AN7: =(AI7-AH7-AG7-AF7-AE7-AA7)/AI7 -> 0.025735203 | AS7: 0.8 | AT7: =MIN(IF($AS7=100%,1,1+VLOOKUP(($AI7-$AH7-$AG7-$AF7-$AE7-$AA7*(1+AT$3))/$AI7,'Технический лист'!$A:$B,2,1)-VLOOKUP($AN7,'Технический лист'!$A:$B,2,1)),1+(1-$AS7)) -> 1.2 | AU7: =MIN(IF($AS7=100%,1,1+VLOOKUP(($AI7-$AH7-$AG7-$AF7-$AE7-$AA7*(1+AU$3))/$AI7,'Технический лист'!$A:$B,2,1)-VLOOKUP($AN7,'Технический лист'!$A:$B,2,1)),1+(1-$AS7)) -> 1.2 | AV7: =MIN(IF($AS7=100%,1,1+VLOOKUP(($AI7-$AH7-$AG7-$AF7-$AE7-$AA7*(1+AV$3))/$AI7,'Технический лист'!$A:$B,2,1)-VLOOKUP($AN7,'Технический лист'!$A:$B,2,1)),1+(1-$AS7)) -> 1.2 | AW7: =MIN(IF($AS7=100%,1,1+VLOOKUP(($AI7-$AH7-$AG7-$AF7-$AE7-$AA7*(1+AW$3))/$AI7,'Технический лист'!$A:$B,2,1)-VLOOKUP($AN7,'Технический лист'!$A:$B,2,1)),1+(1-$AS7)) -> 1.2 | AX7: =MIN(IF($AS7=100%,1,1+VLOOKUP(($AI7-$AH7-$AG7-$AF7-$AE7-$AA7*(1+AX$3))/$AI7,'Технический лист'!$A:$B,2,1)-VLOOKUP($AN7,'Технический лист'!$A:$B,2,1)),1+(1-$AS7)) -> 1.2 | AY7: =MIN(IF($AS7=100%,1,1+VLOOKUP(($AI7-$AH7-$AG7-$AF7-$AE7-$AA7*(1+AY$3))/$AI7,'Технический лист'!$A:$B,2,1)-VLOOKUP($AN7,'Технический лист'!$A:$B,2,1)),1+(1-$AS7)) -> 1.175 | AZ7: =MIN(IF($AS7=100%,1,1+VLOOKUP(($AI7-$AH7-$AG7-$AF7-$AE7-$AA7*(1+AZ$3))/$AI7,'Технический лист'!$A:$B,2,1)-VLOOKUP($AN7,'Технический лист'!$A:$B,2,1)),1+(1-$AS7)) -> 1.175 | BA7: =MIN(IF($AS7=100%,1,1+VLOOKUP(($AI7-$AH7-$AG7-$AF7-$AE7-$AA7*(1+BA$3))/$AI7,'Технический лист'!$A:$B,2,1)-VLOOKUP($AN7,'Технический лист'!$A:$B,2,1)),1+(1-$AS7)) -> 1.175 | ... CQ7: =MIN(IF($AS7=100%,1,1+VLOOKUP(($AI7-$AH7-$AG7-$AF7-$AE7-$AA7*(1+CQ$3))/$AI7,'Технический лист'!$A:$B,2,1)-VLOOKUP($AN7,'Технический лист'!$A:$B,2,1)),1+(1-$AS7)) -> 1 | CR7: 1 | CS7: =MIN(1,MAX(VLOOKUP(($AI7-$AH7-$AG7-$AF7-$AE7-$AA7*(1+CS$3))/$AI7,'[8]Технический лист'!$A:$B,2,1),(CR7-0.05))) -> 1 | CT7: =MIN(1,MAX(VLOOKUP(($AI7-$AH7-$AG7-$AF7-$AE7-$AA7*(1+CT$3))/$AI7,'[8]Технический лист'!$A:$B,2,1),(CS7-0.05))) -> 1 | CU7: =MIN(1,MAX(VLOOKUP(($AI7-$AH7-$AG7-$AF7-$AE7-$AA7*(1+CU$3))/$AI7,'[8]Технический лист'!$A:$B,2,1),(CT7-0.05))) -> 1 | CV7: =MIN(1,MAX(VLOOKUP(($AI7-$AH7-$AG7-$AF7-$AE7-$AA7*(1+CV$3))/$AI7,'[8]Технический лист'!$A:$B,2,1),(CU7-0.05))) -> 1 | CW7: =MIN(1,MAX(VLOOKUP(($AI7-$AH7-$AG7-$AF7-$AE7-$AA7*(1+CW$3))/$AI7,'[8]Технический лист'!$A:$B,2,1),(CV7-0.05))) -> 1 | CX7: =MIN(1,MAX(VLOOKUP(($AI7-$AH7-$AG7-$AF7-$AE7-$AA7*(1+CX$3))/$AI7,'[8]Технический лист'!$A:$B,2,1),(CW7-0.05))) -> 1 | CY7: =MIN(1,MAX(VLOOKUP(($AI7-$AH7-$AG7-$AF7-$AE7-$AA7*(1+CY$3))/$AI7,'[8]Технический лист'!$A:$B,2,1),(CX7-0.05))) -> 1 | CZ7: =MIN(1,MAX(VLOOKUP(($AI7-$AH7-$AG7-$AF7-$AE7-$AA7*(1+CZ$3))/$AI7,'[8]Технический лист'!$A:$B,2,1),(CY7-0.05))) -> 1 | ... GN7: =MIN(1,MAX(VLOOKUP(($AI7-$AH7-$AG7-$AF7-$AE7-$AA7*(1+GN$3))/$AI7,'[8]Технический лист'!$A:$B,2,1),(GM7-0.05))) -> 0.885
A8: 6 | B8: Лесные грузы | C8: 12202 | D8: ПЛИТЫ ДСП | E8: ПЛИТЫ ДРЕВЕСНОСТРУЖЕЧНЫЕ | F8: МСК | G8: СКВ | H8: ЭЛЕКТРОГОРСК | I8: САМУР-ЭКСП | J8: 303 | K8: Крытые | L8: Экспорт | M8: неконтейнерная | N8: Южное | O8: 000058242280 | P8: ООО "УЛЬТРАДЕКОР" | Q8: ГК "Кроношпан" | R8: 41499 | S8: 95560050 | T8: 628 | U8: 0 | V8: 141253702 | W8: повагонная | X8: 66 | Y8: 3748.76 | Z8: =AA8-Y8 -> 612.5 | AA8: 4361.26 | AB8: 12 | AC8: 3 | AD8: 4 | AE8: ='Ставки аренды'!$B$3*SUM(Лесные!AB8+Лесные!AC8+Лесные!AD8)/Лесные!X8 -> 863.63636 | AF8: 0 | AH8: =0.68*AI8 -> 16500 | AI8: =Цены!$C$5 -> 24264.706 | AN8: =(AI8-AH8-AG8-AF8-AE8-AA8)/AI8 -> 0.10467094 | AS8: 0.8 | AT8: =MIN(IF($AS8=100%,1,1+VLOOKUP(($AI8-$AH8-$AG8-$AF8-$AE8-$AA8*(1+AT$3))/$AI8,'Технический лист'!$A:$B,2,1)-VLOOKUP($AN8,'Технический лист'!$A:$B,2,1)),1+(1-$AS8)) -> 1.2 | AU8: =MIN(IF($AS8=100%,1,1+VLOOKUP(($AI8-$AH8-$AG8-$AF8-$AE8-$AA8*(1+AU$3))/$AI8,'Технический лист'!$A:$B,2,1)-VLOOKUP($AN8,'Технический лист'!$A:$B,2,1)),1+(1-$AS8)) -> 1.2 | AV8: =MIN(IF($AS8=100%,1,1+VLOOKUP(($AI8-$AH8-$AG8-$AF8-$AE8-$AA8*(1+AV$3))/$AI8,'Технический лист'!$A:$B,2,1)-VLOOKUP($AN8,'Технический лист'!$A:$B,2,1)),1+(1-$AS8)) -> 1.2 | AW8: =MIN(IF($AS8=100%,1,1+VLOOKUP(($AI8-$AH8-$AG8-$AF8-$AE8-$AA8*(1+AW$3))/$AI8,'Технический лист'!$A:$B,2,1)-VLOOKUP($AN8,'Технический лист'!$A:$B,2,1)),1+(1-$AS8)) -> 1.2 | AX8: =MIN(IF($AS8=100%,1,1+VLOOKUP(($AI8-$AH8-$AG8-$AF8-$AE8-$AA8*(1+AX$3))/$AI8,'Технический лист'!$A:$B,2,1)-VLOOKUP($AN8,'Технический лист'!$A:$B,2,1)),1+(1-$AS8)) -> 1.2 | AY8: =MIN(IF($AS8=100%,1,1+VLOOKUP(($AI8-$AH8-$AG8-$AF8-$AE8-$AA8*(1+AY$3))/$AI8,'Технический лист'!$A:$B,2,1)-VLOOKUP($AN8,'Технический лист'!$A:$B,2,1)),1+(1-$AS8)) -> 1.2 | AZ8: =MIN(IF($AS8=100%,1,1+VLOOKUP(($AI8-$AH8-$AG8-$AF8-$AE8-$AA8*(1+AZ$3))/$AI8,'Технический лист'!$A:$B,2,1)-VLOOKUP($AN8,'Технический лист'!$A:$B,2,1)),1+(1-$AS8)) -> 1.2 | BA8: =MIN(IF($AS8=100%,1,1+VLOOKUP(($AI8-$AH8-$AG8-$AF8-$AE8-$AA8*(1+BA$3))/$AI8,'Технический лист'!$A:$B,2,1)-VLOOKUP($AN8,'Технический лист'!$A:$B,2,1)),1+(1-$AS8)) -> 1.2 | ... CQ8: =MIN(IF($AS8=100%,1,1+VLOOKUP(($AI8-$AH8-$AG8-$AF8-$AE8-$AA8*(1+CQ$3))/$AI8,'Технический лист'!$A:$B,2,1)-VLOOKUP($AN8,'Технический лист'!$A:$B,2,1)),1+(1-$AS8)) -> 1.035 | CR8: 1 | CS8: =MIN(1,MAX(VLOOKUP(($AI8-$AH8-$AG8-$AF8-$AE8-$AA8*(1+CS$3))/$AI8,'[8]Технический лист'!$A:$B,2,1),(CR8-0.05))) -> 1 | CT8: =MIN(1,MAX(VLOOKUP(($AI8-$AH8-$AG8-$AF8-$AE8-$AA8*(1+CT$3))/$AI8,'[8]Технический лист'!$A:$B,2,1),(CS8-0.05))) -> 1 | CU8: =MIN(1,MAX(VLOOKUP(($AI8-$AH8-$AG8-$AF8-$AE8-$AA8*(1+CU$3))/$AI8,'[8]Технический лист'!$A:$B,2,1),(CT8-0.05))) -> 1 | CV8: =MIN(1,MAX(VLOOKUP(($AI8-$AH8-$AG8-$AF8-$AE8-$AA8*(1+CV$3))/$AI8,'[8]Технический лист'!$A:$B,2,1),(CU8-0.05))) -> 1 | CW8: =MIN(1,MAX(VLOOKUP(($AI8-$AH8-$AG8-$AF8-$AE8-$AA8*(1+CW$3))/$AI8,'[8]Технический лист'!$A:$B,2,1),(CV8-0.05))) -> 1 | CX8: =MIN(1,MAX(VLOOKUP(($AI8-$AH8-$AG8-$AF8-$AE8-$AA8*(1+CX$3))/$AI8,'[8]Технический лист'!$A:$B,2,1),(CW8-0.05))) -> 1 | CY8: =MIN(1,MAX(VLOOKUP(($AI8-$AH8-$AG8-$AF8-$AE8-$AA8*(1+CY$3))/$AI8,'[8]Технический лист'!$A:$B,2,1),(CX8-0.05))) -> 1 | CZ8: =MIN(1,MAX(VLOOKUP(($AI8-$AH8-$AG8-$AF8-$AE8-$AA8*(1+CZ$3))/$AI8,'[8]Технический лист'!$A:$B,2,1),(CY8-0.05))) -> 1 | ... GN8: =MIN(1,MAX(VLOOKUP(($AI8-$AH8-$AG8-$AF8-$AE8-$AA8*(1+GN$3))/$AI8,'[8]Технический лист'!$A:$B,2,1),(GM8-0.05))) -> 1
A9: 6 | B9: Лесные грузы | C9: 09111 | D9: ПИЛМАТ ПР | E9: ПИЛОМАТЕРИАЛЫ | F9: СЕВ | G9: ЗАБ | H9: ОНЕГА | I9: ЗАБАЙКАЛ ЭК | J9: 991 | K9: Платформы | L9: Экспорт | M9: контейнерная | N9: Восточное | O9: 000000255987 | P9: АО "ОНЕЖСКИЙ ЛДК" | Q9: ГК "Сегежа" | R9: 27821 | S9: 194488314 | T9: 0 | U9: 1004 | V9: 138317952 | W9: контейнерная | X9: 68 | Y9: =404346/X9 -> 5946.2647 | Z9: 0 | AA9: =Y9 -> 5946.2647 | AB9: 20 | AC9: 0 | AD9: 4 | AE9: ='Ставки аренды'!$B$4*SUM(Лесные!AB9+Лесные!AC9+Лесные!AD9)/Лесные!X9 -> 564.70588 | AF9: 0 | AH9: =0.86*AI9 -> 21301.538 | AI9: =Цены!$C$3 -> 24769.231 | AN9: =(AI9-AH9-AG9-AF9-AE9-AA9)/AI9 -> -0.12286527 | AS9: 0.8 | AT9: =MIN(IF($AS9=100%,1,1+VLOOKUP(($AI9-$AH9-$AG9-$AF9-$AE9-$AA9*(1+AT$3))/$AI9,'Технический лист'!$A:$B,2,1)-VLOOKUP($AN9,'Технический лист'!$A:$B,2,1)),1+(1-$AS9)) -> 1.2 | AU9: =MIN(IF($AS9=100%,1,1+VLOOKUP(($AI9-$AH9-$AG9-$AF9-$AE9-$AA9*(1+AU$3))/$AI9,'Технический лист'!$A:$B,2,1)-VLOOKUP($AN9,'Технический лист'!$A:$B,2,1)),1+(1-$AS9)) -> 1.2 | AV9: =MIN(IF($AS9=100%,1,1+VLOOKUP(($AI9-$AH9-$AG9-$AF9-$AE9-$AA9*(1+AV$3))/$AI9,'Технический лист'!$A:$B,2,1)-VLOOKUP($AN9,'Технический лист'!$A:$B,2,1)),1+(1-$AS9)) -> 1.2 | AW9: =MIN(IF($AS9=100%,1,1+VLOOKUP(($AI9-$AH9-$AG9-$AF9-$AE9-$AA9*(1+AW$3))/$AI9,'Технический лист'!$A:$B,2,1)-VLOOKUP($AN9,'Технический лист'!$A:$B,2,1)),1+(1-$AS9)) -> 1.2 | AX9: =MIN(IF($AS9=100%,1,1+VLOOKUP(($AI9-$AH9-$AG9-$AF9-$AE9-$AA9*(1+AX$3))/$AI9,'Технический лист'!$A:$B,2,1)-VLOOKUP($AN9,'Технический лист'!$A:$B,2,1)),1+(1-$AS9)) -> 1.2 | AY9: =MIN(IF($AS9=100%,1,1+VLOOKUP(($AI9-$AH9-$AG9-$AF9-$AE9-$AA9*(1+AY$3))/$AI9,'Технический лист'!$A:$B,2,1)-VLOOKUP($AN9,'Технический лист'!$A:$B,2,1)),1+(1-$AS9)) -> 1.2 | AZ9: =MIN(IF($AS9=100%,1,1+VLOOKUP(($AI9-$AH9-$AG9-$AF9-$AE9-$AA9*(1+AZ$3))/$AI9,'Технический лист'!$A:$B,2,1)-VLOOKUP($AN9,'Технический лист'!$A:$B,2,1)),1+(1-$AS9)) -> 1.2 | BA9: =MIN(IF($AS9=100%,1,1+VLOOKUP(($AI9-$AH9-$AG9-$AF9-$AE9-$AA9*(1+BA$3))/$AI9,'Технический лист'!$A:$B,2,1)-VLOOKUP($AN9,'Технический лист'!$A:$B,2,1)),1+(1-$AS9)) -> 1.2 | ... CQ9: =MIN(IF($AS9=100%,1,1+VLOOKUP(($AI9-$AH9-$AG9-$AF9-$AE9-$AA9*(1+CQ$3))/$AI9,'Технический лист'!$A:$B,2,1)-VLOOKUP($AN9,'Технический лист'!$A:$B,2,1)),1+(1-$AS9)) -> 1 | CR9: 1 | CS9: =MIN(1,MAX(VLOOKUP(($AI9-$AH9-$AG9-$AF9-$AE9-$AA9*(1+CS$3))/$AI9,'[8]Технический лист'!$A:$B,2,1),(CR9-0.05))) -> 0.95 | CT9: =MIN(1,MAX(VLOOKUP(($AI9-$AH9-$AG9-$AF9-$AE9-$AA9*(1+CT$3))/$AI9,'[8]Технический лист'!$A:$B,2,1),(CS9-0.05))) -> 0.9 | CU9: =MIN(1,MAX(VLOOKUP(($AI9-$AH9-$AG9-$AF9-$AE9-$AA9*(1+CU$3))/$AI9,'[8]Технический лист'!$A:$B,2,1),(CT9-0.05))) -> 0.85 | CV9: =MIN(1,MAX(VLOOKUP(($AI9-$AH9-$AG9-$AF9-$AE9-$AA9*(1+CV$3))/$AI9,'[8]Технический лист'!$A:$B,2,1),(CU9-0.05))) -> 0.8 | CW9: =MIN(1,MAX(VLOOKUP(($AI9-$AH9-$AG9-$AF9-$AE9-$AA9*(1+CW$3))/$AI9,'[8]Технический лист'!$A:$B,2,1),(CV9-0.05))) -> 0.75 | CX9: =MIN(1,MAX(VLOOKUP(($AI9-$AH9-$AG9-$AF9-$AE9-$AA9*(1+CX$3))/$AI9,'[8]Технический лист'!$A:$B,2,1),(CW9-0.05))) -> 0.71 | CY9: =MIN(1,MAX(VLOOKUP(($AI9-$AH9-$AG9-$AF9-$AE9-$AA9*(1+CY$3))/$AI9,'[8]Технический лист'!$A:$B,2,1),(CX9-0.05))) -> 0.71 | CZ9: =MIN(1,MAX(VLOOKUP(($AI9-$AH9-$AG9-$AF9-$AE9-$AA9*(1+CZ$3))/$AI9,'[8]Технический лист'!$A:$B,2,1),(CY9-0.05))) -> 0.71 | ... GN9: =MIN(1,MAX(VLOOKUP(($AI9-$AH9-$AG9-$AF9-$AE9-$AA9*(1+GN$3))/$AI9,'[8]Технический лист'!$A:$B,2,1),(GM9-0.05))) -> 0
A10: 6 | B10: Лесные грузы | C10: 09111 | D10: ПИЛМАТ ПР | E10: ПИЛОМАТЕРИАЛЫ | F10: ВСБ | G10: ДВС | H10: ИГИРМА | I10: ВЛАДИВОСТ-ЭК | J10: 609 | K10: Платформы | L10: Экспорт | M10: контейнерная | N10: Восточное | O10: 000080279097 | P10: ООО "ЛЕСРЕСУРС" | Q10: ГК "Лесресурс" | R10: 38704 | S10: 178405389 | T10: 0 | U10: 1323 | V10: 137364084 | W10: контейнерная | X10: 68 | Y10: =308618/X10 -> 4538.5 | Z10: 0 | AA10: =Y10 -> 4538.5 | AB10: 13 | AC10: 0 | AD10: 4 | AE10: ='Ставки аренды'!$B$4*SUM(Лесные!AB10+Лесные!AC10+Лесные!AD10)/Лесные!X10 -> 400 | AF10: ='Ставки перевалки'!$B$2/X10*2 -> 661.76471 | AH10: =0.71*AI10 -> 17586.154 | AI10: =Цены!$C$3 -> 24769.231 | AN10: =(AI10-AH10-AG10-AF10-AE10-AA10)/AI10 -> 0.063902357 | AS10: 0.8 | AT10: =MIN(IF($AS10=100%,1,1+VLOOKUP(($AI10-$AH10-$AG10-$AF10-$AE10-$AA10*(1+AT$3))/$AI10,'Технический лист'!$A:$B,2,1)-VLOOKUP($AN10,'Технический лист'!$A:$B,2,1)),1+(1-$AS10)) -> 1.2 | AU10: =MIN(IF($AS10=100%,1,1+VLOOKUP(($AI10-$AH10-$AG10-$AF10-$AE10-$AA10*(1+AU$3))/$AI10,'Технический лист'!$A:$B,2,1)-VLOOKUP($AN10,'Технический лист'!$A:$B,2,1)),1+(1-$AS10)) -> 1.2 | AV10: =MIN(IF($AS10=100%,1,1+VLOOKUP(($AI10-$AH10-$AG10-$AF10-$AE10-$AA10*(1+AV$3))/$AI10,'Технический лист'!$A:$B,2,1)-VLOOKUP($AN10,'Технический лист'!$A:$B,2,1)),1+(1-$AS10)) -> 1.2 | AW10: =MIN(IF($AS10=100%,1,1+VLOOKUP(($AI10-$AH10-$AG10-$AF10-$AE10-$AA10*(1+AW$3))/$AI10,'Технический лист'!$A:$B,2,1)-VLOOKUP($AN10,'Технический лист'!$A:$B,2,1)),1+(1-$AS10)) -> 1.2 | AX10: =MIN(IF($AS10=100%,1,1+VLOOKUP(($AI10-$AH10-$AG10-$AF10-$AE10-$AA10*(1+AX$3))/$AI10,'Технический лист'!$A:$B,2,1)-VLOOKUP($AN10,'Технический лист'!$A:$B,2,1)),1+(1-$AS10)) -> 1.2 | AY10: =MIN(IF($AS10=100%,1,1+VLOOKUP(($AI10-$AH10-$AG10-$AF10-$AE10-$AA10*(1+AY$3))/$AI10,'Технический лист'!$A:$B,2,1)-VLOOKUP($AN10,'Технический лист'!$A:$B,2,1)),1+(1-$AS10)) -> 1.2 | AZ10: =MIN(IF($AS10=100%,1,1+VLOOKUP(($AI10-$AH10-$AG10-$AF10-$AE10-$AA10*(1+AZ$3))/$AI10,'Технический лист'!$A:$B,2,1)-VLOOKUP($AN10,'Технический лист'!$A:$B,2,1)),1+(1-$AS10)) -> 1.2 | BA10: =MIN(IF($AS10=100%,1,1+VLOOKUP(($AI10-$AH10-$AG10-$AF10-$AE10-$AA10*(1+BA$3))/$AI10,'Технический лист'!$A:$B,2,1)-VLOOKUP($AN10,'Технический лист'!$A:$B,2,1)),1+(1-$AS10)) -> 1.2 | ... CQ10: =MIN(IF($AS10=100%,1,1+VLOOKUP(($AI10-$AH10-$AG10-$AF10-$AE10-$AA10*(1+CQ$3))/$AI10,'Технический лист'!$A:$B,2,1)-VLOOKUP($AN10,'Технический лист'!$A:$B,2,1)),1+(1-$AS10)) -> 1 | CR10: 1 | CS10: =MIN(1,MAX(VLOOKUP(($AI10-$AH10-$AG10-$AF10-$AE10-$AA10*(1+CS$3))/$AI10,'[8]Технический лист'!$A:$B,2,1),(CR10-0.05))) -> 1 | CT10: =MIN(1,MAX(VLOOKUP(($AI10-$AH10-$AG10-$AF10-$AE10-$AA10*(1+CT$3))/$AI10,'[8]Технический лист'!$A:$B,2,1),(CS10-0.05))) -> 1 | CU10: =MIN(1,MAX(VLOOKUP(($AI10-$AH10-$AG10-$AF10-$AE10-$AA10*(1+CU$3))/$AI10,'[8]Технический лист'!$A:$B,2,1),(CT10-0.05))) -> 1 | CV10: =MIN(1,MAX(VLOOKUP(($AI10-$AH10-$AG10-$AF10-$AE10-$AA10*(1+CV$3))/$AI10,'[8]Технический лист'!$A:$B,2,1),(CU10-0.05))) -> 1 | CW10: =MIN(1,MAX(VLOOKUP(($AI10-$AH10-$AG10-$AF10-$AE10-$AA10*(1+CW$3))/$AI10,'[8]Технический лист'!$A:$B,2,1),(CV10-0.05))) -> 1 | CX10: =MIN(1,MAX(VLOOKUP(($AI10-$AH10-$AG10-$AF10-$AE10-$AA10*(1+CX$3))/$AI10,'[8]Технический лист'!$A:$B,2,1),(CW10-0.05))) -> 1 | CY10: =MIN(1,MAX(VLOOKUP(($AI10-$AH10-$AG10-$AF10-$AE10-$AA10*(1+CY$3))/$AI10,'[8]Технический лист'!$A:$B,2,1),(CX10-0.05))) -> 1 | CZ10: =MIN(1,MAX(VLOOKUP(($AI10-$AH10-$AG10-$AF10-$AE10-$AA10*(1+CZ$3))/$AI10,'[8]Технический лист'!$A:$B,2,1),(CY10-0.05))) -> 1 | ... GN10: =MIN(1,MAX(VLOOKUP(($AI10-$AH10-$AG10-$AF10-$AE10-$AA10*(1+GN$3))/$AI10,'[8]Технический лист'!$A:$B,2,1),(GM10-0.05))) -> 0.98
A11: 6 | B11: Лесные грузы | C11: 09407 | D11: ФАНЕРА КЛЕЕНАЯ | E11: ФАНЕРА И ШПОН | F11: ГОР | G11: ИФР | H11: ПОЛОЙ | I11: МИХ-СЕМ-Э | J11: 604 | K11: Платформы | L11: Экспорт | M11: контейнерная | N11: Восточное | O11: 000093222532 | P11: ООО "ВЯТСКИЙ ФАНЕРНЫЙ КОМБИНАТ" | Q11: ГК "Сегежа" | R11: 20735 | S11: 157665729 | T11: 0 | U11: 704 | V11: 129424691 | W11: контейнерная | X11: 66 | Y11: =432194/X11 -> 6548.3939 | Z11: 0 | AA11: =Y11 -> 6548.3939 | AB11: 23 | AC11: 0 | AD11: 4 | AE11: ='Ставки аренды'!$B$4*SUM(Лесные!AB11+Лесные!AC11+Лесные!AD11)/Лесные!X11 -> 654.54545 | AF11: 0 | AH11: =0.86*AI11 -> 56391.429 | AI11: =Цены!$C$7 -> 65571.429 | AN11: =(AI11-AH11-AG11-AF11-AE11-AA11)/AI11 -> 0.030151251 | AS11: 0.8 | AT11: =MIN(IF($AS11=100%,1,1+VLOOKUP(($AI11-$AH11-$AG11-$AF11-$AE11-$AA11*(1+AT$3))/$AI11,'Технический лист'!$A:$B,2,1)-VLOOKUP($AN11,'Технический лист'!$A:$B,2,1)),1+(1-$AS11)) -> 1.09 | AU11: =MIN(IF($AS11=100%,1,1+VLOOKUP(($AI11-$AH11-$AG11-$AF11-$AE11-$AA11*(1+AU$3))/$AI11,'Технический лист'!$A:$B,2,1)-VLOOKUP($AN11,'Технический лист'!$A:$B,2,1)),1+(1-$AS11)) -> 1.07 | AV11: =MIN(IF($AS11=100%,1,1+VLOOKUP(($AI11-$AH11-$AG11-$AF11-$AE11-$AA11*(1+AV$3))/$AI11,'Технический лист'!$A:$B,2,1)-VLOOKUP($AN11,'Технический лист'!$A:$B,2,1)),1+(1-$AS11)) -> 1.07 | AW11: =MIN(IF($AS11=100%,1,1+VLOOKUP(($AI11-$AH11-$AG11-$AF11-$AE11-$AA11*(1+AW$3))/$AI11,'Технический лист'!$A:$B,2,1)-VLOOKUP($AN11,'Технический лист'!$A:$B,2,1)),1+(1-$AS11)) -> 1.07 | AX11: =MIN(IF($AS11=100%,1,1+VLOOKUP(($AI11-$AH11-$AG11-$AF11-$AE11-$AA11*(1+AX$3))/$AI11,'Технический лист'!$A:$B,2,1)-VLOOKUP($AN11,'Технический лист'!$A:$B,2,1)),1+(1-$AS11)) -> 1.07 | AY11: =MIN(IF($AS11=100%,1,1+VLOOKUP(($AI11-$AH11-$AG11-$AF11-$AE11-$AA11*(1+AY$3))/$AI11,'Технический лист'!$A:$B,2,1)-VLOOKUP($AN11,'Технический лист'!$A:$B,2,1)),1+(1-$AS11)) -> 1.07 | AZ11: =MIN(IF($AS11=100%,1,1+VLOOKUP(($AI11-$AH11-$AG11-$AF11-$AE11-$AA11*(1+AZ$3))/$AI11,'Технический лист'!$A:$B,2,1)-VLOOKUP($AN11,'Технический лист'!$A:$B,2,1)),1+(1-$AS11)) -> 1.07 | BA11: =MIN(IF($AS11=100%,1,1+VLOOKUP(($AI11-$AH11-$AG11-$AF11-$AE11-$AA11*(1+BA$3))/$AI11,'Технический лист'!$A:$B,2,1)-VLOOKUP($AN11,'Технический лист'!$A:$B,2,1)),1+(1-$AS11)) -> 1.07 | ... CQ11: =MIN(IF($AS11=100%,1,1+VLOOKUP(($AI11-$AH11-$AG11-$AF11-$AE11-$AA11*(1+CQ$3))/$AI11,'Технический лист'!$A:$B,2,1)-VLOOKUP($AN11,'Технический лист'!$A:$B,2,1)),1+(1-$AS11)) -> 1 | CR11: 1 | CS11: =MIN(1,MAX(VLOOKUP(($AI11-$AH11-$AG11-$AF11-$AE11-$AA11*(1+CS$3))/$AI11,'[8]Технический лист'!$A:$B,2,1),(CR11-0.05))) -> 1 | CT11: =MIN(1,MAX(VLOOKUP(($AI11-$AH11-$AG11-$AF11-$AE11-$AA11*(1+CT$3))/$AI11,'[8]Технический лист'!$A:$B,2,1),(CS11-0.05))) -> 1 | CU11: =MIN(1,MAX(VLOOKUP(($AI11-$AH11-$AG11-$AF11-$AE11-$AA11*(1+CU$3))/$AI11,'[8]Технический лист'!$A:$B,2,1),(CT11-0.05))) -> 1 | CV11: =MIN(1,MAX(VLOOKUP(($AI11-$AH11-$AG11-$AF11-$AE11-$AA11*(1+CV$3))/$AI11,'[8]Технический лист'!$A:$B,2,1),(CU11-0.05))) -> 1 | CW11: =MIN(1,MAX(VLOOKUP(($AI11-$AH11-$AG11-$AF11-$AE11-$AA11*(1+CW$3))/$AI11,'[8]Технический лист'!$A:$B,2,1),(CV11-0.05))) -> 1 | CX11: =MIN(1,MAX(VLOOKUP(($AI11-$AH11-$AG11-$AF11-$AE11-$AA11*(1+CX$3))/$AI11,'[8]Технический лист'!$A:$B,2,1),(CW11-0.05))) -> 1 | CY11: =MIN(1,MAX(VLOOKUP(($AI11-$AH11-$AG11-$AF11-$AE11-$AA11*(1+CY$3))/$AI11,'[8]Технический лист'!$A:$B,2,1),(CX11-0.05))) -> 1 | CZ11: =MIN(1,MAX(VLOOKUP(($AI11-$AH11-$AG11-$AF11-$AE11-$AA11*(1+CZ$3))/$AI11,'[8]Технический лист'!$A:$B,2,1),(CY11-0.05))) -> 1 | ... GN11: =MIN(1,MAX(VLOOKUP(($AI11-$AH11-$AG11-$AF11-$AE11-$AA11*(1+GN$3))/$AI11,'[8]Технический лист'!$A:$B,2,1),(GM11-0.05))) -> 0.99
A12: 6 | B12: Лесные грузы | C12: 12202 | D12: ПЛИТЫ ДСП | E12: ПЛИТЫ ДРЕВЕСНОСТРУЖЕЧНЫЕ | F12: КБШ | G12: ЮУР | H12: ШАКША | I12: ОРСК-НВГР-ЭК | J12: 24 | K12: Крытые | L12: Экспорт | M12: неконтейнерная | N12: Южное | O12: 000038502891 | P12: ООО "УЛЬТРАДИЗАЙН" | Q12: ГК "Кроношпан" | R12: 68577 | S12: 49660473 | T12: 1056 | U12: 0 | V12: 108884824 | W12: повагонная | X12: 66 | Y12: 1726.48 | Z12: =AA12-Y12 -> 215.75 | AA12: 1942.23 | AB12: 5 | AC12: 1 | AD12: 4 | AE12: ='Ставки аренды'!$B$3*SUM(Лесные!AB12+Лесные!AC12+Лесные!AD12)/Лесные!X12 -> 454.54545 | AF12: 0 | AH12: =0.83*AI12 -> 20139.706 | AI12: =Цены!$C$5 -> 24264.706 | AN12: =(AI12-AH12-AG12-AF12-AE12-AA12)/AI12 -> 0.071223799 | AS12: 0.8 | AT12: =MIN(IF($AS12=100%,1,1+VLOOKUP(($AI12-$AH12-$AG12-$AF12-$AE12-$AA12*(1+AT$3))/$AI12,'Технический лист'!$A:$B,2,1)-VLOOKUP($AN12,'Технический лист'!$A:$B,2,1)),1+(1-$AS12)) -> 1.11 | AU12: =MIN(IF($AS12=100%,1,1+VLOOKUP(($AI12-$AH12-$AG12-$AF12-$AE12-$AA12*(1+AU$3))/$AI12,'Технический лист'!$A:$B,2,1)-VLOOKUP($AN12,'Технический лист'!$A:$B,2,1)),1+(1-$AS12)) -> 1.11 | AV12: =MIN(IF($AS12=100%,1,1+VLOOKUP(($AI12-$AH12-$AG12-$AF12-$AE12-$AA12*(1+AV$3))/$AI12,'Технический лист'!$A:$B,2,1)-VLOOKUP($AN12,'Технический лист'!$A:$B,2,1)),1+(1-$AS12)) -> 1.11 | AW12: =MIN(IF($AS12=100%,1,1+VLOOKUP(($AI12-$AH12-$AG12-$AF12-$AE12-$AA12*(1+AW$3))/$AI12,'Технический лист'!$A:$B,2,1)-VLOOKUP($AN12,'Технический лист'!$A:$B,2,1)),1+(1-$AS12)) -> 1.11 | AX12: =MIN(IF($AS12=100%,1,1+VLOOKUP(($AI12-$AH12-$AG12-$AF12-$AE12-$AA12*(1+AX$3))/$AI12,'Технический лист'!$A:$B,2,1)-VLOOKUP($AN12,'Технический лист'!$A:$B,2,1)),1+(1-$AS12)) -> 1.08 | AY12: =MIN(IF($AS12=100%,1,1+VLOOKUP(($AI12-$AH12-$AG12-$AF12-$AE12-$AA12*(1+AY$3))/$AI12,'Технический лист'!$A:$B,2,1)-VLOOKUP($AN12,'Технический лист'!$A:$B,2,1)),1+(1-$AS12)) -> 1.08 | AZ12: =MIN(IF($AS12=100%,1,1+VLOOKUP(($AI12-$AH12-$AG12-$AF12-$AE12-$AA12*(1+AZ$3))/$AI12,'Технический лист'!$A:$B,2,1)-VLOOKUP($AN12,'Технический лист'!$A:$B,2,1)),1+(1-$AS12)) -> 1.08 | BA12: =MIN(IF($AS12=100%,1,1+VLOOKUP(($AI12-$AH12-$AG12-$AF12-$AE12-$AA12*(1+BA$3))/$AI12,'Технический лист'!$A:$B,2,1)-VLOOKUP($AN12,'Технический лист'!$A:$B,2,1)),1+(1-$AS12)) -> 1.08 | ... CQ12: =MIN(IF($AS12=100%,1,1+VLOOKUP(($AI12-$AH12-$AG12-$AF12-$AE12-$AA12*(1+CQ$3))/$AI12,'Технический лист'!$A:$B,2,1)-VLOOKUP($AN12,'Технический лист'!$A:$B,2,1)),1+(1-$AS12)) -> 1 | CR12: 1 | CS12: =MIN(1,MAX(VLOOKUP(($AI12-$AH12-$AG12-$AF12-$AE12-$AA12*(1+CS$3))/$AI12,'[8]Технический лист'!$A:$B,2,1),(CR12-0.05))) -> 1 | CT12: =MIN(1,MAX(VLOOKUP(($AI12-$AH12-$AG12-$AF12-$AE12-$AA12*(1+CT$3))/$AI12,'[8]Технический лист'!$A:$B,2,1),(CS12-0.05))) -> 1 | CU12: =MIN(1,MAX(VLOOKUP(($AI12-$AH12-$AG12-$AF12-$AE12-$AA12*(1+CU$3))/$AI12,'[8]Технический лист'!$A:$B,2,1),(CT12-0.05))) -> 1 | CV12: =MIN(1,MAX(VLOOKUP(($AI12-$AH12-$AG12-$AF12-$AE12-$AA12*(1+CV$3))/$AI12,'[8]Технический лист'!$A:$B,2,1),(CU12-0.05))) -> 1 | CW12: =MIN(1,MAX(VLOOKUP(($AI12-$AH12-$AG12-$AF12-$AE12-$AA12*(1+CW$3))/$AI12,'[8]Технический лист'!$A:$B,2,1),(CV12-0.05))) -> 1 | CX12: =MIN(1,MAX(VLOOKUP(($AI12-$AH12-$AG12-$AF12-$AE12-$AA12*(1+CX$3))/$AI12,'[8]Технический лист'!$A:$B,2,1),(CW12-0.05))) -> 1 | CY12: =MIN(1,MAX(VLOOKUP(($AI12-$AH12-$AG12-$AF12-$AE12-$AA12*(1+CY$3))/$AI12,'[8]Технический лист'!$A:$B,2,1),(CX12-0.05))) -> 1 | CZ12: =MIN(1,MAX(VLOOKUP(($AI12-$AH12-$AG12-$AF12-$AE12-$AA12*(1+CZ$3))/$AI12,'[8]Технический лист'!$A:$B,2,1),(CY12-0.05))) -> 1 | ... GN12: =MIN(1,MAX(VLOOKUP(($AI12-$AH12-$AG12-$AF12-$AE12-$AA12*(1+GN$3))/$AI12,'[8]Технический лист'!$A:$B,2,1),(GM12-0.05))) -> 1
A13: 6 | B13: Лесные грузы | C13: 09111 | D13: ПИЛМАТ ПР | E13: ПИЛОМАТЕРИАЛЫ | F13: СЕВ | G13: ЗАБ | H13: ХАРОВСКАЯ | I13: ЗАБАЙКАЛ ЭК | J13: 428 | K13: Платформы | L13: Экспорт | M13: контейнерная | N13: Восточное | O13: 000057114611 | P13: ООО "ХАРОВСКЛЕСПРОМ" | Q13: ГК "Вологодские лесопромышленники" | R13: 22193 | S13: 142654904 | T13: 0 | U13: 756 | V13: 100712036 | W13: контейнерная | X13: 68 | Y13: =390422/X13 -> 5741.5 | Z13: 0 | AA13: =Y13 -> 5741.5 | AB13: 19 | AC13: 0 | AD13: 4 | AE13: ='Ставки аренды'!$B$4*SUM(Лесные!AB13+Лесные!AC13+Лесные!AD13)/Лесные!X13 -> 541.17647 | AF13: 0 | AH13: =0.73*AI13 -> 18081.538 | AI13: =Цены!$C$3 -> 24769.231 | AN13: =(AI13-AH13-AG13-AF13-AE13-AA13)/AI13 -> 0.016351571 | AS13: 0.8 | AT13: =MIN(IF($AS13=100%,1,1+VLOOKUP(($AI13-$AH13-$AG13-$AF13-$AE13-$AA13*(1+AT$3))/$AI13,'Технический лист'!$A:$B,2,1)-VLOOKUP($AN13,'Технический лист'!$A:$B,2,1)),1+(1-$AS13)) -> 1.2 | AU13: =MIN(IF($AS13=100%,1,1+VLOOKUP(($AI13-$AH13-$AG13-$AF13-$AE13-$AA13*(1+AU$3))/$AI13,'Технический лист'!$A:$B,2,1)-VLOOKUP($AN13,'Технический лист'!$A:$B,2,1)),1+(1-$AS13)) -> 1.2 | AV13: =MIN(IF($AS13=100%,1,1+VLOOKUP(($AI13-$AH13-$AG13-$AF13-$AE13-$AA13*(1+AV$3))/$AI13,'Технический лист'!$A:$B,2,1)-VLOOKUP($AN13,'Технический лист'!$A:$B,2,1)),1+(1-$AS13)) -> 1.2 | AW13: =MIN(IF($AS13=100%,1,1+VLOOKUP(($AI13-$AH13-$AG13-$AF13-$AE13-$AA13*(1+AW$3))/$AI13,'Технический лист'!$A:$B,2,1)-VLOOKUP($AN13,'Технический лист'!$A:$B,2,1)),1+(1-$AS13)) -> 1.2 | AX13: =MIN(IF($AS13=100%,1,1+VLOOKUP(($AI13-$AH13-$AG13-$AF13-$AE13-$AA13*(1+AX$3))/$AI13,'Технический лист'!$A:$B,2,1)-VLOOKUP($AN13,'Технический лист'!$A:$B,2,1)),1+(1-$AS13)) -> 1.18 | AY13: =MIN(IF($AS13=100%,1,1+VLOOKUP(($AI13-$AH13-$AG13-$AF13-$AE13-$AA13*(1+AY$3))/$AI13,'Технический лист'!$A:$B,2,1)-VLOOKUP($AN13,'Технический лист'!$A:$B,2,1)),1+(1-$AS13)) -> 1.18 | AZ13: =MIN(IF($AS13=100%,1,1+VLOOKUP(($AI13-$AH13-$AG13-$AF13-$AE13-$AA13*(1+AZ$3))/$AI13,'Технический лист'!$A:$B,2,1)-VLOOKUP($AN13,'Технический лист'!$A:$B,2,1)),1+(1-$AS13)) -> 1.18 | BA13: =MIN(IF($AS13=100%,1,1+VLOOKUP(($AI13-$AH13-$AG13-$AF13-$AE13-$AA13*(1+BA$3))/$AI13,'Технический лист'!$A:$B,2,1)-VLOOKUP($AN13,'Технический лист'!$A:$B,2,1)),1+(1-$AS13)) -> 1.18 | ... CQ13: =MIN(IF($AS13=100%,1,1+VLOOKUP(($AI13-$AH13-$AG13-$AF13-$AE13-$AA13*(1+CQ$3))/$AI13,'Технический лист'!$A:$B,2,1)-VLOOKUP($AN13,'Технический лист'!$A:$B,2,1)),1+(1-$AS13)) -> 1 | CR13: 1 | CS13: =MIN(1,MAX(VLOOKUP(($AI13-$AH13-$AG13-$AF13-$AE13-$AA13*(1+CS$3))/$AI13,'[8]Технический лист'!$A:$B,2,1),(CR13-0.05))) -> 1 | CT13: =MIN(1,MAX(VLOOKUP(($AI13-$AH13-$AG13-$AF13-$AE13-$AA13*(1+CT$3))/$AI13,'[8]Технический лист'!$A:$B,2,1),(CS13-0.05))) -> 1 | CU13: =MIN(1,MAX(VLOOKUP(($AI13-$AH13-$AG13-$AF13-$AE13-$AA13*(1+CU$3))/$AI13,'[8]Технический лист'!$A:$B,2,1),(CT13-0.05))) -> 1 | CV13: =MIN(1,MAX(VLOOKUP(($AI13-$AH13-$AG13-$AF13-$AE13-$AA13*(1+CV$3))/$AI13,'[8]Технический лист'!$A:$B,2,1),(CU13-0.05))) -> 1 | CW13: =MIN(1,MAX(VLOOKUP(($AI13-$AH13-$AG13-$AF13-$AE13-$AA13*(1+CW$3))/$AI13,'[8]Технический лист'!$A:$B,2,1),(CV13-0.05))) -> 1 | CX13: =MIN(1,MAX(VLOOKUP(($AI13-$AH13-$AG13-$AF13-$AE13-$AA13*(1+CX$3))/$AI13,'[8]Технический лист'!$A:$B,2,1),(CW13-0.05))) -> 1 | CY13: =MIN(1,MAX(VLOOKUP(($AI13-$AH13-$AG13-$AF13-$AE13-$AA13*(1+CY$3))/$AI13,'[8]Технический лист'!$A:$B,2,1),(CX13-0.05))) -> 1 | CZ13: =MIN(1,MAX(VLOOKUP(($AI13-$AH13-$AG13-$AF13-$AE13-$AA13*(1+CZ$3))/$AI13,'[8]Технический лист'!$A:$B,2,1),(CY13-0.05))) -> 1 | ... GN13: =MIN(1,MAX(VLOOKUP(($AI13-$AH13-$AG13-$AF13-$AE13-$AA13*(1+GN$3))/$AI13,'[8]Технический лист'!$A:$B,2,1),(GM13-0.05))) -> 0.84
A14: 6 | B14: Лесные грузы | C14: 09111 | D14: ПИЛМАТ ПР | E14: ПИЛОМАТЕРИАЛЫ | F14: КРС | G14: СКВ | H14: ЛЕСОСИБИРСК | I14: НОВОРОСС-ЭКС | J14: 084 | K14: Платформы для лесоматериалов | L14: Экспорт | M14: неконтейнерная | N14: Южное | O14: 000005029043 | P14: АО "ЛЕСОСИБИРСКИЙ ЛДК № 1" | Q14: ГК "Сегежа" | R14: 28936 | S14: 147104514 | T14: 607 | U14: 0 | V14: 100344551 | W14: групповая | X14: 47 | Y14: 5412.43 | Z14: =AA14-Y14 -> 3970.57 | AA14: 9383 | AB14: 16 | AC14: 16 | AD14: 4 | AE14: ='Ставки аренды'!$B$5*SUM(Лесные!AB14+Лесные!AC14+Лесные!AD14)/Лесные!X14 -> 842.55319 | AF14: ='Ставки перевалки'!B5 -> 1538.4615 | AH14: =0.86*AI14 -> 21301.538 | AI14: =Цены!$C$3 -> 24769.231 | AN14: =(AI14-AH14-AG14-AF14-AE14-AA14)/AI14 -> -0.33494469 | AS14: 0.8 | AT14: =MIN(IF($AS14=100%,1,1+VLOOKUP(($AI14-$AH14-$AG14-$AF14-$AE14-$AA14*(1+AT$3))/$AI14,'Технический лист'!$A:$B,2,1)-VLOOKUP($AN14,'Технический лист'!$A:$B,2,1)),1+(1-$AS14)) -> 1 | AU14: =MIN(IF($AS14=100%,1,1+VLOOKUP(($AI14-$AH14-$AG14-$AF14-$AE14-$AA14*(1+AU$3))/$AI14,'Технический лист'!$A:$B,2,1)-VLOOKUP($AN14,'Технический лист'!$A:$B,2,1)),1+(1-$AS14)) -> 1 | AV14: =MIN(IF($AS14=100%,1,1+VLOOKUP(($AI14-$AH14-$AG14-$AF14-$AE14-$AA14*(1+AV$3))/$AI14,'Технический лист'!$A:$B,2,1)-VLOOKUP($AN14,'Технический лист'!$A:$B,2,1)),1+(1-$AS14)) -> 1 | AW14: =MIN(IF($AS14=100%,1,1+VLOOKUP(($AI14-$AH14-$AG14-$AF14-$AE14-$AA14*(1+AW$3))/$AI14,'Технический лист'!$A:$B,2,1)-VLOOKUP($AN14,'Технический лист'!$A:$B,2,1)),1+(1-$AS14)) -> 1 | AX14: =MIN(IF($AS14=100%,1,1+VLOOKUP(($AI14-$AH14-$AG14-$AF14-$AE14-$AA14*(1+AX$3))/$AI14,'Технический лист'!$A:$B,2,1)-VLOOKUP($AN14,'Технический лист'!$A:$B,2,1)),1+(1-$AS14)) -> 1 | AY14: =MIN(IF($AS14=100%,1,1+VLOOKUP(($AI14-$AH14-$AG14-$AF14-$AE14-$AA14*(1+AY$3))/$AI14,'Технический лист'!$A:$B,2,1)-VLOOKUP($AN14,'Технический лист'!$A:$B,2,1)),1+(1-$AS14)) -> 1 | AZ14: =MIN(IF($AS14=100%,1,1+VLOOKUP(($AI14-$AH14-$AG14-$AF14-$AE14-$AA14*(1+AZ$3))/$AI14,'Технический лист'!$A:$B,2,1)-VLOOKUP($AN14,'Технический лист'!$A:$B,2,1)),1+(1-$AS14)) -> 1 | BA14: =MIN(IF($AS14=100%,1,1+VLOOKUP(($AI14-$AH14-$AG14-$AF14-$AE14-$AA14*(1+BA$3))/$AI14,'Технический лист'!$A:$B,2,1)-VLOOKUP($AN14,'Технический лист'!$A:$B,2,1)),1+(1-$AS14)) -> 1 | ... CQ14: =MIN(IF($AS14=100%,1,1+VLOOKUP(($AI14-$AH14-$AG14-$AF14-$AE14-$AA14*(1+CQ$3))/$AI14,'Технический лист'!$A:$B,2,1)-VLOOKUP($AN14,'Технический лист'!$A:$B,2,1)),1+(1-$AS14)) -> 1 | CR14: 1 | CS14: =MIN(1,MAX(VLOOKUP(($AI14-$AH14-$AG14-$AF14-$AE14-$AA14*(1+CS$3))/$AI14,'[8]Технический лист'!$A:$B,2,1),(CR14-0.05))) -> 0.95 | CT14: =MIN(1,MAX(VLOOKUP(($AI14-$AH14-$AG14-$AF14-$AE14-$AA14*(1+CT$3))/$AI14,'[8]Технический лист'!$A:$B,2,1),(CS14-0.05))) -> 0.9 | CU14: =MIN(1,MAX(VLOOKUP(($AI14-$AH14-$AG14-$AF14-$AE14-$AA14*(1+CU$3))/$AI14,'[8]Технический лист'!$A:$B,2,1),(CT14-0.05))) -> 0.85 | CV14: =MIN(1,MAX(VLOOKUP(($AI14-$AH14-$AG14-$AF14-$AE14-$AA14*(1+CV$3))/$AI14,'[8]Технический лист'!$A:$B,2,1),(CU14-0.05))) -> 0.8 | CW14: =MIN(1,MAX(VLOOKUP(($AI14-$AH14-$AG14-$AF14-$AE14-$AA14*(1+CW$3))/$AI14,'[8]Технический лист'!$A:$B,2,1),(CV14-0.05))) -> 0.75 | CX14: =MIN(1,MAX(VLOOKUP(($AI14-$AH14-$AG14-$AF14-$AE14-$AA14*(1+CX$3))/$AI14,'[8]Технический лист'!$A:$B,2,1),(CW14-0.05))) -> 0.7 | CY14: =MIN(1,MAX(VLOOKUP(($AI14-$AH14-$AG14-$AF14-$AE14-$AA14*(1+CY$3))/$AI14,'[8]Технический лист'!$A:$B,2,1),(CX14-0.05))) -> 0.65 | CZ14: =MIN(1,MAX(VLOOKUP(($AI14-$AH14-$AG14-$AF14-$AE14-$AA14*(1+CZ$3))/$AI14,'[8]Технический лист'!$A:$B,2,1),(CY14-0.05))) -> 0.6 | ... GN14: =MIN(1,MAX(VLOOKUP(($AI14-$AH14-$AG14-$AF14-$AE14-$AA14*(1+GN$3))/$AI14,'[8]Технический лист'!$A:$B,2,1),(GM14-0.05))) -> 0
A15: 6 | B15: Лесные грузы | C15: 09111 | D15: ПИЛМАТ ПР | E15: ПИЛОМАТЕРИАЛЫ | F15: СЕВ | G15: ПРВ | H15: КОСТЫЛЕВО | I15: ОЗИНКИ-Э-РОС | J15: 147 | K15: Платформы | L15: Экспорт | M15: контейнерная | N15: Южное | O15: 000090255910 | P15: ООО "ГК "УЛК" | Q15: ГК "УЛК" | R15: 52880 | S15: 113514793 | T15: 0 | U15: 1798 | V15: 95157290 | W15: контейнерная | X15: 68 | Y15: =168628/X15 -> 2479.8235 | Z15: 0 | AA15: =Y15 -> 2479.8235 | AB15: 9 | AC15: 0 | AD15: 4 | AE15: ='Ставки аренды'!$B$4*SUM(Лесные!AB15+Лесные!AC15+Лесные!AD15)/Лесные!X15 -> 305.88235 | AF15: 0 | AH15: =1.18*AI15 -> 29227.692 | AI15: =Цены!$C$3 -> 24769.231 | AN15: =(AI15-AH15-AG15-AF15-AE15-AA15)/AI15 -> -0.29246639 | AS15: 0.8 | AT15: =MIN(IF($AS15=100%,1,1+VLOOKUP(($AI15-$AH15-$AG15-$AF15-$AE15-$AA15*(1+AT$3))/$AI15,'Технический лист'!$A:$B,2,1)-VLOOKUP($AN15,'Технический лист'!$A:$B,2,1)),1+(1-$AS15)) -> 1 | AU15: =MIN(IF($AS15=100%,1,1+VLOOKUP(($AI15-$AH15-$AG15-$AF15-$AE15-$AA15*(1+AU$3))/$AI15,'Технический лист'!$A:$B,2,1)-VLOOKUP($AN15,'Технический лист'!$A:$B,2,1)),1+(1-$AS15)) -> 1 | AV15: =MIN(IF($AS15=100%,1,1+VLOOKUP(($AI15-$AH15-$AG15-$AF15-$AE15-$AA15*(1+AV$3))/$AI15,'Технический лист'!$A:$B,2,1)-VLOOKUP($AN15,'Технический лист'!$A:$B,2,1)),1+(1-$AS15)) -> 1 | AW15: =MIN(IF($AS15=100%,1,1+VLOOKUP(($AI15-$AH15-$AG15-$AF15-$AE15-$AA15*(1+AW$3))/$AI15,'Технический лист'!$A:$B,2,1)-VLOOKUP($AN15,'Технический лист'!$A:$B,2,1)),1+(1-$AS15)) -> 1 | AX15: =MIN(IF($AS15=100%,1,1+VLOOKUP(($AI15-$AH15-$AG15-$AF15-$AE15-$AA15*(1+AX$3))/$AI15,'Технический лист'!$A:$B,2,1)-VLOOKUP($AN15,'Технический лист'!$A:$B,2,1)),1+(1-$AS15)) -> 1 | AY15: =MIN(IF($AS15=100%,1,1+VLOOKUP(($AI15-$AH15-$AG15-$AF15-$AE15-$AA15*(1+AY$3))/$AI15,'Технический лист'!$A:$B,2,1)-VLOOKUP($AN15,'Технический лист'!$A:$B,2,1)),1+(1-$AS15)) -> 1 | AZ15: =MIN(IF($AS15=100%,1,1+VLOOKUP(($AI15-$AH15-$AG15-$AF15-$AE15-$AA15*(1+AZ$3))/$AI15,'Технический лист'!$A:$B,2,1)-VLOOKUP($AN15,'Технический лист'!$A:$B,2,1)),1+(1-$AS15)) -> 1 | BA15: =MIN(IF($AS15=100%,1,1+VLOOKUP(($AI15-$AH15-$AG15-$AF15-$AE15-$AA15*(1+BA$3))/$AI15,'Технический лист'!$A:$B,2,1)-VLOOKUP($AN15,'Технический лист'!$A:$B,2,1)),1+(1-$AS15)) -> 1 | ... CQ15: =MIN(IF($AS15=100%,1,1+VLOOKUP(($AI15-$AH15-$AG15-$AF15-$AE15-$AA15*(1+CQ$3))/$AI15,'Технический лист'!$A:$B,2,1)-VLOOKUP($AN15,'Технический лист'!$A:$B,2,1)),1+(1-$AS15)) -> 1 | CR15: 1 | CS15: =MIN(1,MAX(VLOOKUP(($AI15-$AH15-$AG15-$AF15-$AE15-$AA15*(1+CS$3))/$AI15,'[8]Технический лист'!$A:$B,2,1),(CR15-0.05))) -> 0.95 | CT15: =MIN(1,MAX(VLOOKUP(($AI15-$AH15-$AG15-$AF15-$AE15-$AA15*(1+CT$3))/$AI15,'[8]Технический лист'!$A:$B,2,1),(CS15-0.05))) -> 0.9 | CU15: =MIN(1,MAX(VLOOKUP(($AI15-$AH15-$AG15-$AF15-$AE15-$AA15*(1+CU$3))/$AI15,'[8]Технический лист'!$A:$B,2,1),(CT15-0.05))) -> 0.85 | CV15: =MIN(1,MAX(VLOOKUP(($AI15-$AH15-$AG15-$AF15-$AE15-$AA15*(1+CV$3))/$AI15,'[8]Технический лист'!$A:$B,2,1),(CU15-0.05))) -> 0.8 | CW15: =MIN(1,MAX(VLOOKUP(($AI15-$AH15-$AG15-$AF15-$AE15-$AA15*(1+CW$3))/$AI15,'[8]Технический лист'!$A:$B,2,1),(CV15-0.05))) -> 0.75 | CX15: =MIN(1,MAX(VLOOKUP(($AI15-$AH15-$AG15-$AF15-$AE15-$AA15*(1+CX$3))/$AI15,'[8]Технический лист'!$A:$B,2,1),(CW15-0.05))) -> 0.7 | CY15: =MIN(1,MAX(VLOOKUP(($AI15-$AH15-$AG15-$AF15-$AE15-$AA15*(1+CY$3))/$AI15,'[8]Технический лист'!$A:$B,2,1),(CX15-0.05))) -> 0.65 | CZ15: =MIN(1,MAX(VLOOKUP(($AI15-$AH15-$AG15-$AF15-$AE15-$AA15*(1+CZ$3))/$AI15,'[8]Технический лист'!$A:$B,2,1),(CY15-0.05))) -> 0.6 | ... GN15: =MIN(1,MAX(VLOOKUP(($AI15-$AH15-$AG15-$AF15-$AE15-$AA15*(1+GN$3))/$AI15,'[8]Технический лист'!$A:$B,2,1),(GM15-0.05))) -> 0
A16: 6 | B16: Лесные грузы | C16: 09407 | D16: ФАНЕРА КЛЕЕНАЯ | E16: ФАНЕРА И ШПОН | F16: ГОР | G16: ЗАБ | H16: ПОЛОЙ | I16: ЗАБАЙКАЛ ЭК | J16: 693 | K16: Платформы | L16: Экспорт | M16: контейнерная | N16: Восточное | O16: 000093222532 | P16: ООО "ВЯТСКИЙ ФАНЕРНЫЙ КОМБИНАТ" | Q16: ГК "Сегежа" | R16: 20684 | S16: 117756708 | T16: 0 | U16: 700 | V16: 87303104 | W16: контейнерная | X16: 66 | Y16: =362574/X16 -> 5493.5455 | Z16: 0 | AA16: =Y16 -> 5493.5455 | AB16: 17 | AC16: 0 | AD16: 4 | AE16: ='Ставки аренды'!$B$4*SUM(Лесные!AB16+Лесные!AC16+Лесные!AD16)/Лесные!X16 -> 509.09091 | AF16: 0 | AH16: =0.86*AI16 -> 56391.429 | AI16: =Цены!$C$7 -> 65571.429 | AN16: =(AI16-AH16-AG16-AF16-AE16-AA16)/AI16 -> 0.048456526 | AS16: 0.8 | AT16: =MIN(IF($AS16=100%,1,1+VLOOKUP(($AI16-$AH16-$AG16-$AF16-$AE16-$AA16*(1+AT$3))/$AI16,'Технический лист'!$A:$B,2,1)-VLOOKUP($AN16,'Технический лист'!$A:$B,2,1)),1+(1-$AS16)) -> 1.085 | AU16: =MIN(IF($AS16=100%,1,1+VLOOKUP(($AI16-$AH16-$AG16-$AF16-$AE16-$AA16*(1+AU$3))/$AI16,'Технический лист'!$A:$B,2,1)-VLOOKUP($AN16,'Технический лист'!$A:$B,2,1)),1+(1-$AS16)) -> 1.085 | AV16: =MIN(IF($AS16=100%,1,1+VLOOKUP(($AI16-$AH16-$AG16-$AF16-$AE16-$AA16*(1+AV$3))/$AI16,'Технический лист'!$A:$B,2,1)-VLOOKUP($AN16,'Технический лист'!$A:$B,2,1)),1+(1-$AS16)) -> 1.085 | AW16: =MIN(IF($AS16=100%,1,1+VLOOKUP(($AI16-$AH16-$AG16-$AF16-$AE16-$AA16*(1+AW$3))/$AI16,'Технический лист'!$A:$B,2,1)-VLOOKUP($AN16,'Технический лист'!$A:$B,2,1)),1+(1-$AS16)) -> 1.085 | AX16: =MIN(IF($AS16=100%,1,1+VLOOKUP(($AI16-$AH16-$AG16-$AF16-$AE16-$AA16*(1+AX$3))/$AI16,'Технический лист'!$A:$B,2,1)-VLOOKUP($AN16,'Технический лист'!$A:$B,2,1)),1+(1-$AS16)) -> 1.085 | AY16: =MIN(IF($AS16=100%,1,1+VLOOKUP(($AI16-$AH16-$AG16-$AF16-$AE16-$AA16*(1+AY$3))/$AI16,'Технический лист'!$A:$B,2,1)-VLOOKUP($AN16,'Технический лист'!$A:$B,2,1)),1+(1-$AS16)) -> 1.085 | AZ16: =MIN(IF($AS16=100%,1,1+VLOOKUP(($AI16-$AH16-$AG16-$AF16-$AE16-$AA16*(1+AZ$3))/$AI16,'Технический лист'!$A:$B,2,1)-VLOOKUP($AN16,'Технический лист'!$A:$B,2,1)),1+(1-$AS16)) -> 1.085 | BA16: =MIN(IF($AS16=100%,1,1+VLOOKUP(($AI16-$AH16-$AG16-$AF16-$AE16-$AA16*(1+BA$3))/$AI16,'Технический лист'!$A:$B,2,1)-VLOOKUP($AN16,'Технический лист'!$A:$B,2,1)),1+(1-$AS16)) -> 1.085 | ... CQ16: =MIN(IF($AS16=100%,1,1+VLOOKUP(($AI16-$AH16-$AG16-$AF16-$AE16-$AA16*(1+CQ$3))/$AI16,'Технический лист'!$A:$B,2,1)-VLOOKUP($AN16,'Технический лист'!$A:$B,2,1)),1+(1-$AS16)) -> 1 | CR16: 1 | CS16: =MIN(1,MAX(VLOOKUP(($AI16-$AH16-$AG16-$AF16-$AE16-$AA16*(1+CS$3))/$AI16,'[8]Технический лист'!$A:$B,2,1),(CR16-0.05))) -> 1 | CT16: =MIN(1,MAX(VLOOKUP(($AI16-$AH16-$AG16-$AF16-$AE16-$AA16*(1+CT$3))/$AI16,'[8]Технический лист'!$A:$B,2,1),(CS16-0.05))) -> 1 | CU16: =MIN(1,MAX(VLOOKUP(($AI16-$AH16-$AG16-$AF16-$AE16-$AA16*(1+CU$3))/$AI16,'[8]Технический лист'!$A:$B,2,1),(CT16-0.05))) -> 1 | CV16: =MIN(1,MAX(VLOOKUP(($AI16-$AH16-$AG16-$AF16-$AE16-$AA16*(1+CV$3))/$AI16,'[8]Технический лист'!$A:$B,2,1),(CU16-0.05))) -> 1 | CW16: =MIN(1,MAX(VLOOKUP(($AI16-$AH16-$AG16-$AF16-$AE16-$AA16*(1+CW$3))/$AI16,'[8]Технический лист'!$A:$B,2,1),(CV16-0.05))) -> 1 | CX16: =MIN(1,MAX(VLOOKUP(($AI16-$AH16-$AG16-$AF16-$AE16-$AA16*(1+CX$3))/$AI16,'[8]Технический лист'!$A:$B,2,1),(CW16-0.05))) -> 1 | CY16: =MIN(1,MAX(VLOOKUP(($AI16-$AH16-$AG16-$AF16-$AE16-$AA16*(1+CY$3))/$AI16,'[8]Технический лист'!$A:$B,2,1),(CX16-0.05))) -> 1 | CZ16: =MIN(1,MAX(VLOOKUP(($AI16-$AH16-$AG16-$AF16-$AE16-$AA16*(1+CZ$3))/$AI16,'[8]Технический лист'!$A:$B,2,1),(CY16-0.05))) -> 1 | ... GN16: =MIN(1,MAX(VLOOKUP(($AI16-$AH16-$AG16-$AF16-$AE16-$AA16*(1+GN$3))/$AI16,'[8]Технический лист'!$A:$B,2,1),(GM16-0.05))) -> 1
A17: 6 | B17: Лесные грузы | C17: 09111 | D17: ПИЛМАТ ПР | E17: ПИЛОМАТЕРИАЛЫ | F17: СЕВ | G17: ПРВ | H17: СУХОНА | I17: ОЗИНКИ-Э-РОС | J17: 777 | K17: Платформы | L17: Экспорт | M17: контейнерная | N17: Южное | O17: 000052036415 | P17: АО "С-ДОК" | Q17: ГК "Сегежа" | R17: 51016 | S17: 90648917 | T17: 0 | U17: 1796 | V17: 82696820 | W17: контейнерная | X17: 68 | Y17: =147430/X17 -> 2168.0882 | Z17: 0 | AA17: =Y17 -> 2168.0882 | AB17: 8 | AC17: 0 | AD17: 4 | AE17: ='Ставки аренды'!$B$4*SUM(Лесные!AB17+Лесные!AC17+Лесные!AD17)/Лесные!X17 -> 282.35294 | AF17: 0 | AH17: =0.86*AI17 -> 21301.538 | AI17: =Цены!$C$3 -> 24769.231 | AN17: =(AI17-AH17-AG17-AF17-AE17-AA17)/AI17 -> 0.041069145 | AS17: 0.8 | AT17: =MIN(IF($AS17=100%,1,1+VLOOKUP(($AI17-$AH17-$AG17-$AF17-$AE17-$AA17*(1+AT$3))/$AI17,'Технический лист'!$A:$B,2,1)-VLOOKUP($AN17,'Технический лист'!$A:$B,2,1)),1+(1-$AS17)) -> 1.08 | AU17: =MIN(IF($AS17=100%,1,1+VLOOKUP(($AI17-$AH17-$AG17-$AF17-$AE17-$AA17*(1+AU$3))/$AI17,'Технический лист'!$A:$B,2,1)-VLOOKUP($AN17,'Технический лист'!$A:$B,2,1)),1+(1-$AS17)) -> 1.08 | AV17: =MIN(IF($AS17=100%,1,1+VLOOKUP(($AI17-$AH17-$AG17-$AF17-$AE17-$AA17*(1+AV$3))/$AI17,'Технический лист'!$A:$B,2,1)-VLOOKUP($AN17,'Технический лист'!$A:$B,2,1)),1+(1-$AS17)) -> 1.08 | AW17: =MIN(IF($AS17=100%,1,1+VLOOKUP(($AI17-$AH17-$AG17-$AF17-$AE17-$AA17*(1+AW$3))/$AI17,'Технический лист'!$A:$B,2,1)-VLOOKUP($AN17,'Технический лист'!$A:$B,2,1)),1+(1-$AS17)) -> 1.08 | AX17: =MIN(IF($AS17=100%,1,1+VLOOKUP(($AI17-$AH17-$AG17-$AF17-$AE17-$AA17*(1+AX$3))/$AI17,'Технический лист'!$A:$B,2,1)-VLOOKUP($AN17,'Технический лист'!$A:$B,2,1)),1+(1-$AS17)) -> 1.08 | AY17: =MIN(IF($AS17=100%,1,1+VLOOKUP(($AI17-$AH17-$AG17-$AF17-$AE17-$AA17*(1+AY$3))/$AI17,'Технический лист'!$A:$B,2,1)-VLOOKUP($AN17,'Технический лист'!$A:$B,2,1)),1+(1-$AS17)) -> 1.08 | AZ17: =MIN(IF($AS17=100%,1,1+VLOOKUP(($AI17-$AH17-$AG17-$AF17-$AE17-$AA17*(1+AZ$3))/$AI17,'Технический лист'!$A:$B,2,1)-VLOOKUP($AN17,'Технический лист'!$A:$B,2,1)),1+(1-$AS17)) -> 1.08 | BA17: =MIN(IF($AS17=100%,1,1+VLOOKUP(($AI17-$AH17-$AG17-$AF17-$AE17-$AA17*(1+BA$3))/$AI17,'Технический лист'!$A:$B,2,1)-VLOOKUP($AN17,'Технический лист'!$A:$B,2,1)),1+(1-$AS17)) -> 1.06 | ... CQ17: =MIN(IF($AS17=100%,1,1+VLOOKUP(($AI17-$AH17-$AG17-$AF17-$AE17-$AA17*(1+CQ$3))/$AI17,'Технический лист'!$A:$B,2,1)-VLOOKUP($AN17,'Технический лист'!$A:$B,2,1)),1+(1-$AS17)) -> 1 | CR17: 1 | CS17: =MIN(1,MAX(VLOOKUP(($AI17-$AH17-$AG17-$AF17-$AE17-$AA17*(1+CS$3))/$AI17,'[8]Технический лист'!$A:$B,2,1),(CR17-0.05))) -> 1 | CT17: =MIN(1,MAX(VLOOKUP(($AI17-$AH17-$AG17-$AF17-$AE17-$AA17*(1+CT$3))/$AI17,'[8]Технический лист'!$A:$B,2,1),(CS17-0.05))) -> 1 | CU17: =MIN(1,MAX(VLOOKUP(($AI17-$AH17-$AG17-$AF17-$AE17-$AA17*(1+CU$3))/$AI17,'[8]Технический лист'!$A:$B,2,1),(CT17-0.05))) -> 1 | CV17: =MIN(1,MAX(VLOOKUP(($AI17-$AH17-$AG17-$AF17-$AE17-$AA17*(1+CV$3))/$AI17,'[8]Технический лист'!$A:$B,2,1),(CU17-0.05))) -> 1 | CW17: =MIN(1,MAX(VLOOKUP(($AI17-$AH17-$AG17-$AF17-$AE17-$AA17*(1+CW$3))/$AI17,'[8]Технический лист'!$A:$B,2,1),(CV17-0.05))) -> 1 | CX17: =MIN(1,MAX(VLOOKUP(($AI17-$AH17-$AG17-$AF17-$AE17-$AA17*(1+CX$3))/$AI17,'[8]Технический лист'!$A:$B,2,1),(CW17-0.05))) -> 1 | CY17: =MIN(1,MAX(VLOOKUP(($AI17-$AH17-$AG17-$AF17-$AE17-$AA17*(1+CY$3))/$AI17,'[8]Технический лист'!$A:$B,2,1),(CX17-0.05))) -> 1 | CZ17: =MIN(1,MAX(VLOOKUP(($AI17-$AH17-$AG17-$AF17-$AE17-$AA17*(1+CZ$3))/$AI17,'[8]Технический лист'!$A:$B,2,1),(CY17-0.05))) -> 1 | ... GN17: =MIN(1,MAX(VLOOKUP(($AI17-$AH17-$AG17-$AF17-$AE17-$AA17*(1+GN$3))/$AI17,'[8]Технический лист'!$A:$B,2,1),(GM17-0.05))) -> 1
A18: 6 | B18: Лесные грузы | C18: 09111 | D18: ПИЛМАТ ПР | E18: ПИЛОМАТЕРИАЛЫ | F18: СЕВ | G18: ОКТ | H18: КОСТЫЛЕВО | I18: НОВ.ПОРТ-ЭКС | J18: 017 | K18: Платформы | L18: Экспорт | M18: контейнерная | N18: Северо-Западное | O18: 000090255910 | P18: ООО "ГК "УЛК" | Q18: ГК "УЛК" | R18: 35993 | S18: 36599968 | T18: 784 | U18: 1214 | V18: 34549384 | W18: контейнерная | X18: 68 | Y18: =96844/X18 -> 1424.1765 | Z18: 0 | AA18: =Y18 -> 1424.1765 | AB18: 8 | AC18: 0 | AD18: 4 | AE18: ='Ставки аренды'!$B$4*SUM(Лесные!AB18+Лесные!AC18+Лесные!AD18)/Лесные!X18 -> 282.35294 | AF18: ='Ставки перевалки'!$B$2/X18*2 -> 661.76471 | AH18: =1.18*AI18 -> 29227.692 | AI18: =Цены!$C$3 -> 24769.231 | AN18: =(AI18-AH18-AG18-AF18-AE18-AA18)/AI18 -> -0.27561436 | AS18: 0.8 | AT18: =MIN(IF($AS18=100%,1,1+VLOOKUP(($AI18-$AH18-$AG18-$AF18-$AE18-$AA18*(1+AT$3))/$AI18,'Технический лист'!$A:$B,2,1)-VLOOKUP($AN18,'Технический лист'!$A:$B,2,1)),1+(1-$AS18)) -> 1 | AU18: =MIN(IF($AS18=100%,1,1+VLOOKUP(($AI18-$AH18-$AG18-$AF18-$AE18-$AA18*(1+AU$3))/$AI18,'Технический лист'!$A:$B,2,1)-VLOOKUP($AN18,'Технический лист'!$A:$B,2,1)),1+(1-$AS18)) -> 1 | AV18: =MIN(IF($AS18=100%,1,1+VLOOKUP(($AI18-$AH18-$AG18-$AF18-$AE18-$AA18*(1+AV$3))/$AI18,'Технический лист'!$A:$B,2,1)-VLOOKUP($AN18,'Технический лист'!$A:$B,2,1)),1+(1-$AS18)) -> 1 | AW18: =MIN(IF($AS18=100%,1,1+VLOOKUP(($AI18-$AH18-$AG18-$AF18-$AE18-$AA18*(1+AW$3))/$AI18,'Технический лист'!$A:$B,2,1)-VLOOKUP($AN18,'Технический лист'!$A:$B,2,1)),1+(1-$AS18)) -> 1 | AX18: =MIN(IF($AS18=100%,1,1+VLOOKUP(($AI18-$AH18-$AG18-$AF18-$AE18-$AA18*(1+AX$3))/$AI18,'Технический лист'!$A:$B,2,1)-VLOOKUP($AN18,'Технический лист'!$A:$B,2,1)),1+(1-$AS18)) -> 1 | AY18: =MIN(IF($AS18=100%,1,1+VLOOKUP(($AI18-$AH18-$AG18-$AF18-$AE18-$AA18*(1+AY$3))/$AI18,'Технический лист'!$A:$B,2,1)-VLOOKUP($AN18,'Технический лист'!$A:$B,2,1)),1+(1-$AS18)) -> 1 | AZ18: =MIN(IF($AS18=100%,1,1+VLOOKUP(($AI18-$AH18-$AG18-$AF18-$AE18-$AA18*(1+AZ$3))/$AI18,'Технический лист'!$A:$B,2,1)-VLOOKUP($AN18,'Технический лист'!$A:$B,2,1)),1+(1-$AS18)) -> 1 | BA18: =MIN(IF($AS18=100%,1,1+VLOOKUP(($AI18-$AH18-$AG18-$AF18-$AE18-$AA18*(1+BA$3))/$AI18,'Технический лист'!$A:$B,2,1)-VLOOKUP($AN18,'Технический лист'!$A:$B,2,1)),1+(1-$AS18)) -> 1 | ... CQ18: =MIN(IF($AS18=100%,1,1+VLOOKUP(($AI18-$AH18-$AG18-$AF18-$AE18-$AA18*(1+CQ$3))/$AI18,'Технический лист'!$A:$B,2,1)-VLOOKUP($AN18,'Технический лист'!$A:$B,2,1)),1+(1-$AS18)) -> 1 | CR18: 1 | CS18: =MIN(1,MAX(VLOOKUP(($AI18-$AH18-$AG18-$AF18-$AE18-$AA18*(1+CS$3))/$AI18,'[8]Технический лист'!$A:$B,2,1),(CR18-0.05))) -> 0.95 | CT18: =MIN(1,MAX(VLOOKUP(($AI18-$AH18-$AG18-$AF18-$AE18-$AA18*(1+CT$3))/$AI18,'[8]Технический лист'!$A:$B,2,1),(CS18-0.05))) -> 0.9 | CU18: =MIN(1,MAX(VLOOKUP(($AI18-$AH18-$AG18-$AF18-$AE18-$AA18*(1+CU$3))/$AI18,'[8]Технический лист'!$A:$B,2,1),(CT18-0.05))) -> 0.85 | CV18: =MIN(1,MAX(VLOOKUP(($AI18-$AH18-$AG18-$AF18-$AE18-$AA18*(1+CV$3))/$AI18,'[8]Технический лист'!$A:$B,2,1),(CU18-0.05))) -> 0.8 | CW18: =MIN(1,MAX(VLOOKUP(($AI18-$AH18-$AG18-$AF18-$AE18-$AA18*(1+CW$3))/$AI18,'[8]Технический лист'!$A:$B,2,1),(CV18-0.05))) -> 0.75 | CX18: =MIN(1,MAX(VLOOKUP(($AI18-$AH18-$AG18-$AF18-$AE18-$AA18*(1+CX$3))/$AI18,'[8]Технический лист'!$A:$B,2,1),(CW18-0.05))) -> 0.7 | CY18: =MIN(1,MAX(VLOOKUP(($AI18-$AH18-$AG18-$AF18-$AE18-$AA18*(1+CY$3))/$AI18,'[8]Технический лист'!$A:$B,2,1),(CX18-0.05))) -> 0.65 | CZ18: =MIN(1,MAX(VLOOKUP(($AI18-$AH18-$AG18-$AF18-$AE18-$AA18*(1+CZ$3))/$AI18,'[8]Технический лист'!$A:$B,2,1),(CY18-0.05))) -> 0.6 | ... GN18: =MIN(1,MAX(VLOOKUP(($AI18-$AH18-$AG18-$AF18-$AE18-$AA18*(1+GN$3))/$AI18,'[8]Технический лист'!$A:$B,2,1),(GM18-0.05))) -> 0
