Workbook
Name ccc: #REF!
Name cmndBase: #REF!
Name cmndDayMonthTo: #REF!
Name cmndDays: #REF!
Name cmndDocNum: #REF!
Name cmndDocSer: #REF!
Name cmndFIO: #REF!
Name cmndOrdDay: #REF!
Name cmndOrdMonth: #REF!
Name cmndOrdNum: #REF!
Name cmndOrdYear: #REF!
Name cmndPoint: #REF!
Name cmndPoint1: #REF!
Name cmndPos: #REF!
Name cmndYearTo: #REF!
Name cntAddition: #REF!
Name cntDay: #REF!
Name cntMonth: #REF!
Name cntName: #REF!
Name cntNumber: #REF!
Name cntPayer: #REF!
Name cntPayer1: #REF!
Name cntPayerAddr1: #REF!
Name cntPayerAddr2: #REF!
Name cntPayerBank1: #REF!
Name cntPayerBank2: #REF!
Name cntPayerBank3: #REF!
Name cntPayerCount: #REF!
Name cntPayerCountCor: #REF!
Name cntPriceC: #REF!
Name cntPriceR: #REF!
Name cntQnt: #REF!
Name cntSumC: #REF!
Name cntSumR: #REF!
Name cntSuppAddr1: #REF!
Name cntSuppAddr2: #REF!
Name cntSuppBank: #REF!
Name cntSuppCount: #REF!
Name cntSuppCountCor: #REF!
Name cntSupplier: #REF!
Name cntSuppMFO1: #REF!
Name cntSuppMFO2: #REF!
Name cntSuppTlf: #REF!
Name cntUnit: #REF!
Name cntYear: #REF!
Name DF_GRID_2: История [1]корректировок!$C$10:$I$11
Name DF_NAVPANEL_13: [2]Отчет!#REF!
Name DF_NAVPANEL_18: [2]Отчет!#REF!
Name dvrCustomer: #REF!
Name dvrDay: #REF!
Name dvrDocDay: #REF!
Name dvrDocIss: #REF!
Name dvrDocMonth: #REF!
Name dvrDocNum: #REF!
Name dvrDocSer: #REF!
Name dvrDocYear: #REF!
Name dvrMonth: #REF!
Name dvrName: #REF!
Name dvrNo: #REF!
Name dvrNumber: #REF!

Sheet ЧМ,ЦМ,Руда,Кокс
IS1: индексация жд тарифа | IU1: индексация заданная | IV1: =1+(IX1/1000) | IW1: корректировка
A2: параметры перевозок | X2: параметры расчета тарифа | AC2: экономика перевозок в текущих условиях | AT2: для усреднения | AU2: Коэффициент загрузки предприятия | AV2: трнаспортная с индексацией | CX2: Изменение тарифа ОАО "РЖД" | IS2: =ROUND(IU2,2) | IT2: =IF(IS2<0,"скидка","индексация") | IU2: 0.12 | IV2: 1 | IW2: при корректировке коэфф НЕ может принимать значения >1, если у ИПЕМ он <=1, т.е. груз нечувствителен
A3: Тип металлургии | B3: Код группы груза | C3: Группа груза | D3: Код груза | E3: Наим груза | F3: Вид груза | G3: Дор отпр | H3: Дор наз | I3: Станц отпр РФ | J3: Станц назн РФ | K3: Средняя дальность(км) | L3: Род вагона | M3: Вид перевозки | N3: Признак контейнерной отправки | O3: Направление | P3: ОКПО компании | Q3: Компания отправителя | R3: Холдинг отправителя | S3: Объем перевозок (тн) | T3: Грузооборот, ткм | U3: Кол-во вагонов | V3: Кол-во контейнеров | W3: Провозная плата, руб | X3: Загрузка вагона | Y3: Категория отправки | Z3: Груженый рейс, дней | AA3: Порожний рейс, дней | AB3: Погрузка-разгрузка, дней | AC3: Расходы по оплате услуг ОАО 'РЖД', руб. за тонну гружёный рейс | AD3: Расходы по оплате услуг ОАО 'РЖД', руб. за тонну порожний рейс | AE3: Расходы по оплате услуг ОАО 'РЖД', руб. за тонну общая стоимость (тарифные условия 2026 года) | AF3: Расходы по оплате услуг операторов, руб. за тонну | AG3: Расходы на перевалку, руб. за тонну | AH3: Акциз/пошлина | AI3: Себестоимость добычи/производства, руб. т. | AJ3: Стоимость 1 тонны на рынке, руб./т. | AK3: Стоимость 1 тонны на рынке, $/т. | AL3: Общие транспортные расходы, руб. за тонну | AM3: Нетбэк, руб. за тонну | AN3: Общие расходы, руб. за тонну | AO3: Маржинальность в текущих условиях | AP3: Транспортная составляющая в цене % | AQ3: Инфраструктурная составляющая в цене % | AR3: Инфраструктурная составляющая в транспортных затратах | AS3: Коэффициент сохранения базы В РАСЧЕТ | AT3: объем* коэфф | AV3: Маржинальность с индексацией | AW3: Транспортная составляющая в цене % | AX3: Инфраструктурная составляющая в цене % | AY3: Инфраструктурная составляющая в транспортных затратах | AZ3: =ROUND(BA3-0.5%,3) | BA3: =ROUND(BB3-0.5%,3) | BB3: =ROUND(BC3-0.5%,3) | BC3: =ROUND(BD3-0.5%,3) | BD3: =ROUND(BE3-0.5%,3) | BE3: =ROUND(BF3-0.5%,3) | BF3: =ROUND(BG3-0.5%,3) | BG3: =ROUND(BH3-0.5%,3) | ... CW3: =ROUND(CX3-0.5%,3) | CX3: -0.25 | CY3: -0.245 | CZ3: -0.24 | DA3: -0.235 | DB3: -0.23 | DC3: -0.225 | DD3: -0.22 | DE3: -0.215 | DF3: -0.21 | DG3: -0.205 | DH3: -0.2 | DI3: -0.195 | DJ3: -0.19 | DK3: -0.185 | DL3: -0.18 | DM3: -0.175 | DN3: -0.17 | DO3: -0.165 | DP3: -0.16 | DQ3: -0.155 | DR3: -0.15 | DS3: -0.145 | DT3: -0.14 | DU3: -0.135 | DV3: -0.13 | DW3: -0.125 | DX3: -0.12 | DY3: -0.115 | DZ3: -0.11 | EA3: -0.105 | EB3: -0.1 | EC3: -0.095 | ED3: -0.09 | EE3: -0.085 | EF3: -0.08 | EG3: -0.075 | EH3: -0.07 | EI3: -0.065 | EJ3: -0.06 | EK3: -0.055 | EL3: -0.05 | EM3: -0.045 | EN3: -0.04 | EO3: -0.035 | EP3: -0.03 | EQ3: -0.025 | ER3: -0.02 | ES3: -0.015 | ET3: -0.01 | EU3: -0.005 | EV3: 0 | EW3: 0.005 | EX3: 0.01 | EY3: 0.015 | EZ3: 0.02 | FA3: 0.025 | FB3: 0.03 | FC3: 0.035 | FD3: 0.04 | FE3: 0.045 | FF3: 0.05 | FG3: 0.055 | FH3: 0.06 | FI3: 0.065 | FJ3: 0.07 | FK3: 0.075 | FL3: 0.08 | FM3: 0.085 | FN3: 0.09 | FO3: 0.095 | FP3: 0.1 | FQ3: 0.105 | FR3: 0.11 | FS3: 0.115 | FT3: 0.12 | FU3: 0.125 | FV3: 0.13 | FW3: 0.135 | FX3: 0.14 | FY3: 0.145 | FZ3: 0.15 | GA3: 0.155 | GB3: 0.16 | GC3: 0.165 | GD3: 0.17 | GE3: 0.175 | GF3: 0.18 | GG3: 0.185 | GH3: 0.19 | GI3: 0.195 | GJ3: 0.2 | GK3: 0.205 | GL3: 0.21 | GM3: 0.215 | GN3: 0.22 | GO3: 0.225 | GP3: 0.23 | GQ3: 0.235 | GR3: 0.24 | GS3: 0.245 | GT3: 0.25 | GU3: 0.255 | GV3: 0.26 | GW3: 0.265 | GX3: 0.27 | GY3: 0.275 | GZ3: 0.28 | HA3: 0.285 | HB3: 0.29 | HC3: 0.295 | HD3: 0.3 | HE3: 0.305 | HF3: 0.31 | HG3: 0.315 | HH3: 0.32 | HI3: 0.325 | HJ3: 0.33 | HK3: 0.335 | HL3: 0.34 | HM3: 0.345 | HN3: 0.35 | HO3: 0.355 | HP3: 0.36 | HQ3: 0.365 | HR3: 0.37 | HS3: 0.375 | HT3: 0.38 | HU3: 0.385 | HV3: 0.39 | HW3: 0.395 | HX3: 0.4 | HY3: 0.405 | HZ3: 0.41 | IA3: 0.415 | IB3: 0.42 | IC3: 0.425 | ID3: 0.43 | IE3: 0.435 | IF3: 0.44 | IG3: 0.445 | IH3: 0.45 | II3: 0.455 | IJ3: 0.46 | IK3: 0.465 | IL3: 0.47 | IM3: 0.475 | IN3: 0.48 | IO3: 0.485 | IP3: 0.49 | IQ3: 0.495 | IR3: 0.5 | IS3: Коэффициент сохранения базы ИПЕМ | IT3: Коэффициент сохранения базы с корректировкой | IW3: при корректировке коэфф МОЖЕТ принимать значения >1, если у ИПЕМ он <=1, т.е. груз нечувствителен
A4: ЧМ (сырье) | B4: 2 | C4: Кокс каменноугольный | D4: 17103 | E4: Кокс доменный фракции свыше 25 мм | F4: КОКС КАМЕННОУГОЛЬНЫЙ | G4: СВР | H4: СВР | I4: ГУБАХА | J4: СМЫЧКА | K4: 309 | L4: Полувагоны | M4: Внутр. перевозки | N4: вагонная | O4: Южное | P4: '000053496484 | Q4: 'ОАО "Губахинский кокс" | R4: ЗАО "Стройсервис" | S4: 108133 | T4: 33413188 | U4: 2161 | V4: 0 | W4: 56573433 | X4: 52 | Y4: групповая | Z4: 4 | AA4: 4 | AB4: 4 | AC4: 555.75 | AD4: =AE4-AC4 | AE4: 698.02 | AF4: =(Z4+AA4+AB4)*'Ставки аренды'!$B$3/X4 | AG4: 0 | AH4: 0 | AI4: =0.855*AJ4 | AJ4: =Цены!$D$9 | AK4: =AJ4/Цены!$B$1 | AL4: =AE4+AF4+AG4 | AM4: =AJ4-AL4 | AN4: =AI4+AH4+AG4+AF4+AE4 | AO4: =(AJ4-AN4)/AJ4 | AP4: =AL4/AJ4 | AQ4: =AE4/AJ4 | AR4: =AE4/AL4 | AS4: 1 | AT4: =S4*AS4 | AU4: 0.9 | AV4: =(AJ4-(AE4*(1+$IS$2)+AF4+AG4+AH4+AI4))/AJ4 | AW4: =(AE4*(1+$IS$2)+AF4+AG4)/AJ4 | AX4: =(AE4*(1+$IS$2))/AJ4 | AY4: =(AE4*(1+$IS$2))/(AE4*(1+$IS$2)+AF4+AG4) | AZ4: =MIN(IF($AU4=100%,1,1+VLOOKUP(($AJ4-$AI4-$AH4-$AG4-$AF4-$AE4*(1+AZ$3))/$AJ4,'Технический лист'!$A:$B,2,1)-VLOOKUP($AO4,'Технический лист'!$A:$B,2,1)),1+(1-$AU4)) | BA4: =MIN(IF($AU4=100%,1,1+VLOOKUP(($AJ4-$AI4-$AH4-$AG4-$AF4-$AE4*(1+BA$3))/$AJ4,'Технический лист'!$A:$B,2,1)-VLOOKUP($AO4,'Технический лист'!$A:$B,2,1)),1+(1-$AU4)) | BB4: =MIN(IF($AU4=100%,1,1+VLOOKUP(($AJ4-$AI4-$AH4-$AG4-$AF4-$AE4*(1+BB$3))/$AJ4,'Технический лист'!$A:$B,2,1)-VLOOKUP($AO4,'Технический лист'!$A:$B,2,1)),1+(1-$AU4)) | BC4: =MIN(IF($AU4=100%,1,1+VLOOKUP(($AJ4-$AI4-$AH4-$AG4-$AF4-$AE4*(1+BC$3))/$AJ4,'Технический лист'!$A:$B,2,1)-VLOOKUP($AO4,'Технический лист'!$A:$B,2,1)),1+(1-$AU4)) | BD4: =MIN(IF($AU4=100%,1,1+VLOOKUP(($AJ4-$AI4-$AH4-$AG4-$AF4-$AE4*(1+BD$3))/$AJ4,'Технический лист'!$A:$B,2,1)-VLOOKUP($AO4,'Технический лист'!$A:$B,2,1)),1+(1-$AU4)) | BE4: =MIN(IF($AU4=100%,1,1+VLOOKUP(($AJ4-$AI4-$AH4-$AG4-$AF4-$AE4*(1+BE$3))/$AJ4,'Технический лист'!$A:$B,2,1)-VLOOKUP($AO4,'Технический лист'!$A:$B,2,1)),1+(1-$AU4)) | BF4: =MIN(IF($AU4=100%,1,1+VLOOKUP(($AJ4-$AI4-$AH4-$AG4-$AF4-$AE4*(1+BF$3))/$AJ4,'Технический лист'!$A:$B,2,1)-VLOOKUP($AO4,'Технический лист'!$A:$B,2,1)),1+(1-$AU4)) | BG4: =MIN(IF($AU4=100%,1,1+VLOOKUP(($AJ4-$AI4-$AH4-$AG4-$AF4-$AE4*(1+BG$3))/$AJ4,'Технический лист'!$A:$B,2,1)-VLOOKUP($AO4,'Технический лист'!$A:$B,2,1)),1+(1-$AU4)) | ... EU4: =MIN(IF($AU4=100%,1,1+VLOOKUP(($AJ4-$AI4-$AH4-$AG4-$AF4-$AE4*(1+EU$3))/$AJ4,'Технический лист'!$A:$B,2,1)-VLOOKUP($AO4,'Технический лист'!$A:$B,2,1)),1+(1-$AU4)) | EV4: 1 | EW4: =MIN(1,MAX(VLOOKUP(($AJ4-$AI4-$AH4-$AG4-$AF4-$AE4*(1+EW$3))/$AJ4,'Технический лист'!$A:$B,2,1),(EV4-0.05))) | EX4: =MIN(1,MAX(VLOOKUP(($AJ4-$AI4-$AH4-$AG4-$AF4-$AE4*(1+EX$3))/$AJ4,'Технический лист'!$A:$B,2,1),(EW4-0.05))) | EY4: =MIN(1,MAX(VLOOKUP(($AJ4-$AI4-$AH4-$AG4-$AF4-$AE4*(1+EY$3))/$AJ4,'Технический лист'!$A:$B,2,1),(EX4-0.05))) | EZ4: =MIN(1,MAX(VLOOKUP(($AJ4-$AI4-$AH4-$AG4-$AF4-$AE4*(1+EZ$3))/$AJ4,'Технический лист'!$A:$B,2,1),(EY4-0.05))) | FA4: =MIN(1,MAX(VLOOKUP(($AJ4-$AI4-$AH4-$AG4-$AF4-$AE4*(1+FA$3))/$AJ4,'Технический лист'!$A:$B,2,1),(EZ4-0.05))) | FB4: =MIN(1,MAX(VLOOKUP(($AJ4-$AI4-$AH4-$AG4-$AF4-$AE4*(1+FB$3))/$AJ4,'Технический лист'!$A:$B,2,1),(FA4-0.05))) | FC4: =MIN(1,MAX(VLOOKUP(($AJ4-$AI4-$AH4-$AG4-$AF4-$AE4*(1+FC$3))/$AJ4,'Технический лист'!$A:$B,2,1),(FB4-0.05))) | FD4: =MIN(1,MAX(VLOOKUP(($AJ4-$AI4-$AH4-$AG4-$AF4-$AE4*(1+FD$3))/$AJ4,'Технический лист'!$A:$B,2,1),(FC4-0.05))) | ... IR4: =MIN(1,MAX(VLOOKUP(($AJ4-$AI4-$AH4-$AG4-$AF4-$AE4*(1+IR$3))/$AJ4,'Технический лист'!$A:$B,2,1),(IQ4-0.05)))
A5: ЧМ (сырье) | B5: 2 | C5: Кокс каменноугольный | D5: 17103 | E5: Кокс доменный фракции свыше 25 мм | F5: КОКС КАМЕННОУГОЛЬНЫЙ | G5: СВР | H5: МСК | I5: ГУБАХА | J5: ЯСНАЯ ПОЛЯНА | K5: 1800 | L5: Полувагоны | M5: Внутр. перевозки | N5: вагонная | O5: Северо-Западное | P5: '000053496484 | Q5: 'ОАО "Губахинский кокс" | R5: ЗАО "Стройсервис" | S5: 127346 | T5: 229253986 | U5: 2434 | V5: 0 | W5: 186802087 | X5: 52 | Y5: групповая | Z5: 8 | AA5: 6 | AB5: 4 | AC5: 1614.63 | AD5: =AE5-AC5 | AE5: 2298.48 | AF5: =(Z5+AA5+AB5)*'Ставки аренды'!$B$3/X5 | AG5: 0 | AH5: 0 | AI5: =0.855*AJ5 | AJ5: =Цены!$D$9 | AK5: =AJ5/Цены!$B$1 | AL5: =AE5+AF5+AG5 | AM5: =AJ5-AL5 | AN5: =AI5+AH5+AG5+AF5+AE5 | AO5: =(AJ5-AN5)/AJ5 | AP5: =AL5/AJ5 | AQ5: =AE5/AJ5 | AR5: =AE5/AL5 | AS5: 1 | AT5: =S5*AS5 | AU5: 0.9 | AV5: =(AJ5-(AE5*(1+$IS$2)+AF5+AG5+AH5+AI5))/AJ5 | AW5: =(AE5*(1+$IS$2)+AF5+AG5)/AJ5 | AX5: =(AE5*(1+$IS$2))/AJ5 | AY5: =(AE5*(1+$IS$2))/(AE5*(1+$IS$2)+AF5+AG5) | AZ5: =MIN(IF($AU5=100%,1,1+VLOOKUP(($AJ5-$AI5-$AH5-$AG5-$AF5-$AE5*(1+AZ$3))/$AJ5,'Технический лист'!$A:$B,2,1)-VLOOKUP($AO5,'Технический лист'!$A:$B,2,1)),1+(1-$AU5)) | BA5: =MIN(IF($AU5=100%,1,1+VLOOKUP(($AJ5-$AI5-$AH5-$AG5-$AF5-$AE5*(1+BA$3))/$AJ5,'Технический лист'!$A:$B,2,1)-VLOOKUP($AO5,'Технический лист'!$A:$B,2,1)),1+(1-$AU5)) | BB5: =MIN(IF($AU5=100%,1,1+VLOOKUP(($AJ5-$AI5-$AH5-$AG5-$AF5-$AE5*(1+BB$3))/$AJ5,'Технический лист'!$A:$B,2,1)-VLOOKUP($AO5,'Технический лист'!$A:$B,2,1)),1+(1-$AU5)) | BC5: =MIN(IF($AU5=100%,1,1+VLOOKUP(($AJ5-$AI5-$AH5-$AG5-$AF5-$AE5*(1+BC$3))/$AJ5,'Технический лист'!$A:$B,2,1)-VLOOKUP($AO5,'Технический лист'!$A:$B,2,1)),1+(1-$AU5)) | BD5: =MIN(IF($AU5=100%,1,1+VLOOKUP(($AJ5-$AI5-$AH5-$AG5-$AF5-$AE5*(1+BD$3))/$AJ5,'Технический лист'!$A:$B,2,1)-VLOOKUP($AO5,'Технический лист'!$A:$B,2,1)),1+(1-$AU5)) | BE5: =MIN(IF($AU5=100%,1,1+VLOOKUP(($AJ5-$AI5-$AH5-$AG5-$AF5-$AE5*(1+BE$3))/$AJ5,'Технический лист'!$A:$B,2,1)-VLOOKUP($AO5,'Технический лист'!$A:$B,2,1)),1+(1-$AU5)) | BF5: =MIN(IF($AU5=100%,1,1+VLOOKUP(($AJ5-$AI5-$AH5-$AG5-$AF5-$AE5*(1+BF$3))/$AJ5,'Технический лист'!$A:$B,2,1)-VLOOKUP($AO5,'Технический лист'!$A:$B,2,1)),1+(1-$AU5)) | BG5: =MIN(IF($AU5=100%,1,1+VLOOKUP(($AJ5-$AI5-$AH5-$AG5-$AF5-$AE5*(1+BG$3))/$AJ5,'Технический лист'!$A:$B,2,1)-VLOOKUP($AO5,'Технический лист'!$A:$B,2,1)),1+(1-$AU5)) | ... EU5: =MIN(IF($AU5=100%,1,1+VLOOKUP(($AJ5-$AI5-$AH5-$AG5-$AF5-$AE5*(1+EU$3))/$AJ5,'Технический лист'!$A:$B,2,1)-VLOOKUP($AO5,'Технический лист'!$A:$B,2,1)),1+(1-$AU5)) | EV5: 1 | EW5: =MIN(1,MAX(VLOOKUP(($AJ5-$AI5-$AH5-$AG5-$AF5-$AE5*(1+EW$3))/$AJ5,'Технический лист'!$A:$B,2,1),(EV5-0.05))) | EX5: =MIN(1,MAX(VLOOKUP(($AJ5-$AI5-$AH5-$AG5-$AF5-$AE5*(1+EX$3))/$AJ5,'Технический лист'!$A:$B,2,1),(EW5-0.05))) | EY5: =MIN(1,MAX(VLOOKUP(($AJ5-$AI5-$AH5-$AG5-$AF5-$AE5*(1+EY$3))/$AJ5,'Технический лист'!$A:$B,2,1),(EX5-0.05))) | EZ5: =MIN(1,MAX(VLOOKUP(($AJ5-$AI5-$AH5-$AG5-$AF5-$AE5*(1+EZ$3))/$AJ5,'Технический лист'!$A:$B,2,1),(EY5-0.05))) | FA5: =MIN(1,MAX(VLOOKUP(($AJ5-$AI5-$AH5-$AG5-$AF5-$AE5*(1+FA$3))/$AJ5,'Технический лист'!$A:$B,2,1),(EZ5-0.05))) | FB5: =MIN(1,MAX(VLOOKUP(($AJ5-$AI5-$AH5-$AG5-$AF5-$AE5*(1+FB$3))/$AJ5,'Технический лист'!$A:$B,2,1),(FA5-0.05))) | FC5: =MIN(1,MAX(VLOOKUP(($AJ5-$AI5-$AH5-$AG5-$AF5-$AE5*(1+FC$3))/$AJ5,'Технический лист'!$A:$B,2,1),(FB5-0.05))) | FD5: =MIN(1,MAX(VLOOKUP(($AJ5-$AI5-$AH5-$AG5-$AF5-$AE5*(1+FD$3))/$AJ5,'Технический лист'!$A:$B,2,1),(FC5-0.05))) | ... IR5: =MIN(1,MAX(VLOOKUP(($AJ5-$AI5-$AH5-$AG5-$AF5-$AE5*(1+IR$3))/$AJ5,'Технический лист'!$A:$B,2,1),(IQ5-0.05)))
A6: ЧМ (сырье) | B6: 2 | C6: Кокс каменноугольный | D6: 17105 | E6: Кокс лигнитовый | F6: КОКС КАМЕННОУГОЛЬНЫЙ | G6: СВР | H6: МСК | I6: ГУБАХА | J6: КРАСНОЕ-ЭКСП | K6: 2237 | L6: Полувагоны | M6: Экспорт | N6: вагонная | O6: Северо-Западное | P6: '000053496484 | Q6: 'ОАО "Губахинский кокс" | R6: ЗАО "Стройсервис" | S6: 2377 | T6: 5315872 | U6: 52 | V6: 0 | W6: 4995010 | X6: 52 | Y6: групповая | Z6: 12 | AA6: 8 | AB6: 4 | AC6: 2011.46 | AD6: =AE6-AC6 | AE6: 2750.4 | AF6: =(Z6+AA6+AB6)*'Ставки аренды'!$B$3/X6 | AG6: 0 | AH6: 0 | AI6: =0.855*AJ6 | AJ6: =Цены!$C$8*'Курсы валют'!$B$2 | AK6: =AJ6/Цены!$B$1 | AL6: =AE6+AF6+AG6 | AM6: =AJ6-AL6 | AN6: =AI6+AH6+AG6+AF6+AE6 | AO6: =(AJ6-AN6)/AJ6 | AP6: =AL6/AJ6 | AQ6: =AE6/AJ6 | AR6: =AE6/AL6 | AS6: 1 | AT6: =S6*AS6 | AU6: 0.9 | AV6: =(AJ6-(AE6*(1+$IS$2)+AF6+AG6+AH6+AI6))/AJ6 | AW6: =(AE6*(1+$IS$2)+AF6+AG6)/AJ6 | AX6: =(AE6*(1+$IS$2))/AJ6 | AY6: =(AE6*(1+$IS$2))/(AE6*(1+$IS$2)+AF6+AG6) | AZ6: =MIN(IF($AU6=100%,1,1+VLOOKUP(($AJ6-$AI6-$AH6-$AG6-$AF6-$AE6*(1+AZ$3))/$AJ6,'Технический лист'!$A:$B,2,1)-VLOOKUP($AO6,'Технический лист'!$A:$B,2,1)),1+(1-$AU6)) | BA6: =MIN(IF($AU6=100%,1,1+VLOOKUP(($AJ6-$AI6-$AH6-$AG6-$AF6-$AE6*(1+BA$3))/$AJ6,'Технический лист'!$A:$B,2,1)-VLOOKUP($AO6,'Технический лист'!$A:$B,2,1)),1+(1-$AU6)) | BB6: =MIN(IF($AU6=100%,1,1+VLOOKUP(($AJ6-$AI6-$AH6-$AG6-$AF6-$AE6*(1+BB$3))/$AJ6,'Технический лист'!$A:$B,2,1)-VLOOKUP($AO6,'Технический лист'!$A:$B,2,1)),1+(1-$AU6)) | BC6: =MIN(IF($AU6=100%,1,1+VLOOKUP(($AJ6-$AI6-$AH6-$AG6-$AF6-$AE6*(1+BC$3))/$AJ6,'Технический лист'!$A:$B,2,1)-VLOOKUP($AO6,'Технический лист'!$A:$B,2,1)),1+(1-$AU6)) | BD6: =MIN(IF($AU6=100%,1,1+VLOOKUP(($AJ6-$AI6-$AH6-$AG6-$AF6-$AE6*(1+BD$3))/$AJ6,'Технический лист'!$A:$B,2,1)-VLOOKUP($AO6,'Технический лист'!$A:$B,2,1)),1+(1-$AU6)) | BE6: =MIN(IF($AU6=100%,1,1+VLOOKUP(($AJ6-$AI6-$AH6-$AG6-$AF6-$AE6*(1+BE$3))/$AJ6,'Технический лист'!$A:$B,2,1)-VLOOKUP($AO6,'Технический лист'!$A:$B,2,1)),1+(1-$AU6)) | BF6: =MIN(IF($AU6=100%,1,1+VLOOKUP(($AJ6-$AI6-$AH6-$AG6-$AF6-$AE6*(1+BF$3))/$AJ6,'Технический лист'!$A:$B,2,1)-VLOOKUP($AO6,'Технический лист'!$A:$B,2,1)),1+(1-$AU6)) | BG6: =MIN(IF($AU6=100%,1,1+VLOOKUP(($AJ6-$AI6-$AH6-$AG6-$AF6-$AE6*(1+BG$3))/$AJ6,'Технический лист'!$A:$B,2,1)-VLOOKUP($AO6,'Технический лист'!$A:$B,2,1)),1+(1-$AU6)) | ... EU6: =MIN(IF($AU6=100%,1,1+VLOOKUP(($AJ6-$AI6-$AH6-$AG6-$AF6-$AE6*(1+EU$3))/$AJ6,'Технический лист'!$A:$B,2,1)-VLOOKUP($AO6,'Технический лист'!$A:$B,2,1)),1+(1-$AU6)) | EV6: 1 | EW6: =MIN(1,MAX(VLOOKUP(($AJ6-$AI6-$AH6-$AG6-$AF6-$AE6*(1+EW$3))/$AJ6,'Технический лист'!$A:$B,2,1),(EV6-0.05))) | EX6: =MIN(1,MAX(VLOOKUP(($AJ6-$AI6-$AH6-$AG6-$AF6-$AE6*(1+EX$3))/$AJ6,'Технический лист'!$A:$B,2,1),(EW6-0.05))) | EY6: =MIN(1,MAX(VLOOKUP(($AJ6-$AI6-$AH6-$AG6-$AF6-$AE6*(1+EY$3))/$AJ6,'Технический лист'!$A:$B,2,1),(EX6-0.05))) | EZ6: =MIN(1,MAX(VLOOKUP(($AJ6-$AI6-$AH6-$AG6-$AF6-$AE6*(1+EZ$3))/$AJ6,'Технический лист'!$A:$B,2,1),(EY6-0.05))) | FA6: =MIN(1,MAX(VLOOKUP(($AJ6-$AI6-$AH6-$AG6-$AF6-$AE6*(1+FA$3))/$AJ6,'Технический лист'!$A:$B,2,1),(EZ6-0.05))) | FB6: =MIN(1,MAX(VLOOKUP(($AJ6-$AI6-$AH6-$AG6-$AF6-$AE6*(1+FB$3))/$AJ6,'Технический лист'!$A:$B,2,1),(FA6-0.05))) | FC6: =MIN(1,MAX(VLOOKUP(($AJ6-$AI6-$AH6-$AG6-$AF6-$AE6*(1+FC$3))/$AJ6,'Технический лист'!$A:$B,2,1),(FB6-0.05))) | FD6: =MIN(1,MAX(VLOOKUP(($AJ6-$AI6-$AH6-$AG6-$AF6-$AE6*(1+FD$3))/$AJ6,'Технический лист'!$A:$B,2,1),(FC6-0.05))) | ... IR6: =MIN(1,MAX(VLOOKUP(($AJ6-$AI6-$AH6-$AG6-$AF6-$AE6*(1+IR$3))/$AJ6,'Технический лист'!$A:$B,2,1),(IQ6-0.05)))
A7: ЧМ (сырье) | B7: 2 | C7: Кокс каменноугольный | D7: 17108 | E7: Кокс литейный КЛ-3 | F7: КОКС КАМЕННОУГОЛЬНЫЙ | G7: СВР | H7: СВР | I7: СМЫЧКА | J7: КАЧКАНАР | K7: 103 | L7: Полувагоны | M7: Внутр. перевозки | N7: вагонная | O7: Южное | P7: '000000186269 | Q7: АО "ЕВРАЗ НТМК" | R7: ООО "ЕвразХолдинг" | S7: 107630 | T7: 11085971 | U7: 1721 | V7: 0 | W7: 26484037 | X7: 62 | Y7: маршрутная | Z7: 3 | AA7: 3 | AB7: 4 | AC7: 278.6 | AD7: =AE7-AC7 | AE7: 335.73 | AF7: =(Z7+AA7+AB7)*'Ставки аренды'!$B$3/X7 | AG7: 0 | AH7: 0 | AI7: =0.71*AVERAGE(AJ7,AJ8) | AJ7: =Цены!$D$9 | AK7: =AJ7/Цены!$B$1 | AL7: =AE7+AF7+AG7 | AM7: =AJ7-AL7 | AN7: =AI7+AH7+AG7+AF7+AE7 | AO7: =(AJ7-AN7)/AJ7 | AP7: =AL7/AJ7 | AQ7: =AE7/AJ7 | AR7: =AE7/AL7 | AS7: 1 | AT7: =S7*AS7 | AU7: 1 | AV7: =(AJ7-(AE7*(1+$IS$2)+AF7+AG7+AH7+AI7))/AJ7 | AW7: =(AE7*(1+$IS$2)+AF7+AG7)/AJ7 | AX7: =(AE7*(1+$IS$2))/AJ7 | AY7: =(AE7*(1+$IS$2))/(AE7*(1+$IS$2)+AF7+AG7) | AZ7: =MIN(IF($AU7=100%,1,1+VLOOKUP(($AJ7-$AI7-$AH7-$AG7-$AF7-$AE7*(1+AZ$3))/$AJ7,'Технический лист'!$A:$B,2,1)-VLOOKUP($AO7,'Технический лист'!$A:$B,2,1)),1+(1-$AU7)) | BA7: =MIN(IF($AU7=100%,1,1+VLOOKUP(($AJ7-$AI7-$AH7-$AG7-$AF7-$AE7*(1+BA$3))/$AJ7,'Технический лист'!$A:$B,2,1)-VLOOKUP($AO7,'Технический лист'!$A:$B,2,1)),1+(1-$AU7)) | BB7: =MIN(IF($AU7=100%,1,1+VLOOKUP(($AJ7-$AI7-$AH7-$AG7-$AF7-$AE7*(1+BB$3))/$AJ7,'Технический лист'!$A:$B,2,1)-VLOOKUP($AO7,'Технический лист'!$A:$B,2,1)),1+(1-$AU7)) | BC7: =MIN(IF($AU7=100%,1,1+VLOOKUP(($AJ7-$AI7-$AH7-$AG7-$AF7-$AE7*(1+BC$3))/$AJ7,'Технический лист'!$A:$B,2,1)-VLOOKUP($AO7,'Технический лист'!$A:$B,2,1)),1+(1-$AU7)) | BD7: =MIN(IF($AU7=100%,1,1+VLOOKUP(($AJ7-$AI7-$AH7-$AG7-$AF7-$AE7*(1+BD$3))/$AJ7,'Технический лист'!$A:$B,2,1)-VLOOKUP($AO7,'Технический лист'!$A:$B,2,1)),1+(1-$AU7)) | BE7: =MIN(IF($AU7=100%,1,1+VLOOKUP(($AJ7-$AI7-$AH7-$AG7-$AF7-$AE7*(1+BE$3))/$AJ7,'Технический лист'!$A:$B,2,1)-VLOOKUP($AO7,'Технический лист'!$A:$B,2,1)),1+(1-$AU7)) | BF7: =MIN(IF($AU7=100%,1,1+VLOOKUP(($AJ7-$AI7-$AH7-$AG7-$AF7-$AE7*(1+BF$3))/$AJ7,'Технический лист'!$A:$B,2,1)-VLOOKUP($AO7,'Технический лист'!$A:$B,2,1)),1+(1-$AU7)) | BG7: =MIN(IF($AU7=100%,1,1+VLOOKUP(($AJ7-$AI7-$AH7-$AG7-$AF7-$AE7*(1+BG$3))/$AJ7,'Технический лист'!$A:$B,2,1)-VLOOKUP($AO7,'Технический лист'!$A:$B,2,1)),1+(1-$AU7)) | ... EU7: =MIN(IF($AU7=100%,1,1+VLOOKUP(($AJ7-$AI7-$AH7-$AG7-$AF7-$AE7*(1+EU$3))/$AJ7,'Технический лист'!$A:$B,2,1)-VLOOKUP($AO7,'Технический лист'!$A:$B,2,1)),1+(1-$AU7)) | EV7: 1 | EW7: =MIN(1,MAX(VLOOKUP(($AJ7-$AI7-$AH7-$AG7-$AF7-$AE7*(1+EW$3))/$AJ7,'Технический лист'!$A:$B,2,1),(EV7-0.05))) | EX7: =MIN(1,MAX(VLOOKUP(($AJ7-$AI7-$AH7-$AG7-$AF7-$AE7*(1+EX$3))/$AJ7,'Технический лист'!$A:$B,2,1),(EW7-0.05))) | EY7: =MIN(1,MAX(VLOOKUP(($AJ7-$AI7-$AH7-$AG7-$AF7-$AE7*(1+EY$3))/$AJ7,'Технический лист'!$A:$B,2,1),(EX7-0.05))) | EZ7: =MIN(1,MAX(VLOOKUP(($AJ7-$AI7-$AH7-$AG7-$AF7-$AE7*(1+EZ$3))/$AJ7,'Технический лист'!$A:$B,2,1),(EY7-0.05))) | FA7: =MIN(1,MAX(VLOOKUP(($AJ7-$AI7-$AH7-$AG7-$AF7-$AE7*(1+FA$3))/$AJ7,'Технический лист'!$A:$B,2,1),(EZ7-0.05))) | FB7: =MIN(1,MAX(VLOOKUP(($AJ7-$AI7-$AH7-$AG7-$AF7-$AE7*(1+FB$3))/$AJ7,'Технический лист'!$A:$B,2,1),(FA7-0.05))) | FC7: =MIN(1,MAX(VLOOKUP(($AJ7-$AI7-$AH7-$AG7-$AF7-$AE7*(1+FC$3))/$AJ7,'Технический лист'!$A:$B,2,1),(FB7-0.05))) | FD7: =MIN(1,MAX(VLOOKUP(($AJ7-$AI7-$AH7-$AG7-$AF7-$AE7*(1+FD$3))/$AJ7,'Технический лист'!$A:$B,2,1),(FC7-0.05))) | ... IR7: =MIN(1,MAX(VLOOKUP(($AJ7-$AI7-$AH7-$AG7-$AF7-$AE7*(1+IR$3))/$AJ7,'Технический лист'!$A:$B,2,1),(IQ7-0.05)))
A8: ЧМ (сырье) | B8: 2 | C8: Кокс каменноугольный | D8: 17108 | E8: Кокс литейный КЛ-3 | F8: КОКС КАМЕННОУГОЛЬНЫЙ | G8: СВР | H8: ЮУР | I8: СМЫЧКА | J8: КАРТ1-ЭК-РОС | K8: 715 | L8: Полувагоны | M8: Экспорт | N8: вагонная | O8: Южное | P8: '000080294056 | Q8: ООО "ЕвразХолдинг" | R8: ООО "ЕвразХолдинг" | S8: 15408 | T8: 11018927 | U8: 254 | V8: 0 | W8: 11679155 | X8: 56 | Y8: групповая | Z8: 5 | AA8: 3 | AB8: 4 | AC8: 889.96 | AD8: =AE8-AC8 | AE8: 1157.75 | AF8: =(Z8+AA8+AB8)*'Ставки аренды'!$B$3/X8 | AG8: 0 | AH8: 0 | AI8: =0.71*AVERAGE(AJ7,AJ8) | AJ8: =Цены!$C$8*'Курсы валют'!$B$2 | AK8: =AJ8/Цены!$B$1 | AL8: =AE8+AF8+AG8 | AM8: =AJ8-AL8 | AN8: =AI8+AH8+AG8+AF8+AE8 | AO8: =(AJ8-AN8)/AJ8 | AP8: =AL8/AJ8 | AQ8: =AE8/AJ8 | AR8: =AE8/AL8 | AS8: 1 | AT8: =S8*AS8 | AU8: 0.85 | AV8: =(AJ8-(AE8*(1+$IS$2)+AF8+AG8+AH8+AI8))/AJ8 | AW8: =(AE8*(1+$IS$2)+AF8+AG8)/AJ8 | AX8: =(AE8*(1+$IS$2))/AJ8 | AY8: =(AE8*(1+$IS$2))/(AE8*(1+$IS$2)+AF8+AG8) | AZ8: =MIN(IF($AU8=100%,1,1+VLOOKUP(($AJ8-$AI8-$AH8-$AG8-$AF8-$AE8*(1+AZ$3))/$AJ8,'Технический лист'!$A:$B,2,1)-VLOOKUP($AO8,'Технический лист'!$A:$B,2,1)),1+(1-$AU8)) | BA8: =MIN(IF($AU8=100%,1,1+VLOOKUP(($AJ8-$AI8-$AH8-$AG8-$AF8-$AE8*(1+BA$3))/$AJ8,'Технический лист'!$A:$B,2,1)-VLOOKUP($AO8,'Технический лист'!$A:$B,2,1)),1+(1-$AU8)) | BB8: =MIN(IF($AU8=100%,1,1+VLOOKUP(($AJ8-$AI8-$AH8-$AG8-$AF8-$AE8*(1+BB$3))/$AJ8,'Технический лист'!$A:$B,2,1)-VLOOKUP($AO8,'Технический лист'!$A:$B,2,1)),1+(1-$AU8)) | BC8: =MIN(IF($AU8=100%,1,1+VLOOKUP(($AJ8-$AI8-$AH8-$AG8-$AF8-$AE8*(1+BC$3))/$AJ8,'Технический лист'!$A:$B,2,1)-VLOOKUP($AO8,'Технический лист'!$A:$B,2,1)),1+(1-$AU8)) | BD8: =MIN(IF($AU8=100%,1,1+VLOOKUP(($AJ8-$AI8-$AH8-$AG8-$AF8-$AE8*(1+BD$3))/$AJ8,'Технический лист'!$A:$B,2,1)-VLOOKUP($AO8,'Технический лист'!$A:$B,2,1)),1+(1-$AU8)) | BE8: =MIN(IF($AU8=100%,1,1+VLOOKUP(($AJ8-$AI8-$AH8-$AG8-$AF8-$AE8*(1+BE$3))/$AJ8,'Технический лист'!$A:$B,2,1)-VLOOKUP($AO8,'Технический лист'!$A:$B,2,1)),1+(1-$AU8)) | BF8: =MIN(IF($AU8=100%,1,1+VLOOKUP(($AJ8-$AI8-$AH8-$AG8-$AF8-$AE8*(1+BF$3))/$AJ8,'Технический лист'!$A:$B,2,1)-VLOOKUP($AO8,'Технический лист'!$A:$B,2,1)),1+(1-$AU8)) | BG8: =MIN(IF($AU8=100%,1,1+VLOOKUP(($AJ8-$AI8-$AH8-$AG8-$AF8-$AE8*(1+BG$3))/$AJ8,'Технический лист'!$A:$B,2,1)-VLOOKUP($AO8,'Технический лист'!$A:$B,2,1)),1+(1-$AU8)) | ... EU8: =MIN(IF($AU8=100%,1,1+VLOOKUP(($AJ8-$AI8-$AH8-$AG8-$AF8-$AE8*(1+EU$3))/$AJ8,'Технический лист'!$A:$B,2,1)-VLOOKUP($AO8,'Технический лист'!$A:$B,2,1)),1+(1-$AU8)) | EV8: 1 | EW8: =MIN(1,MAX(VLOOKUP(($AJ8-$AI8-$AH8-$AG8-$AF8-$AE8*(1+EW$3))/$AJ8,'Технический лист'!$A:$B,2,1),(EV8-0.05))) | EX8: =MIN(1,MAX(VLOOKUP(($AJ8-$AI8-$AH8-$AG8-$AF8-$AE8*(1+EX$3))/$AJ8,'Технический лист'!$A:$B,2,1),(EW8-0.05))) | EY8: =MIN(1,MAX(VLOOKUP(($AJ8-$AI8-$AH8-$AG8-$AF8-$AE8*(1+EY$3))/$AJ8,'Технический лист'!$A:$B,2,1),(EX8-0.05))) | EZ8: =MIN(1,MAX(VLOOKUP(($AJ8-$AI8-$AH8-$AG8-$AF8-$AE8*(1+EZ$3))/$AJ8,'Технический лист'!$A:$B,2,1),(EY8-0.05))) | FA8: =MIN(1,MAX(VLOOKUP(($AJ8-$AI8-$AH8-$AG8-$AF8-$AE8*(1+FA$3))/$AJ8,'Технический лист'!$A:$B,2,1),(EZ8-0.05))) | FB8: =MIN(1,MAX(VLOOKUP(($AJ8-$AI8-$AH8-$AG8-$AF8-$AE8*(1+FB$3))/$AJ8,'Технический лист'!$A:$B,2,1),(FA8-0.05))) | FC8: =MIN(1,MAX(VLOOKUP(($AJ8-$AI8-$AH8-$AG8-$AF8-$AE8*(1+FC$3))/$AJ8,'Технический лист'!$A:$B,2,1),(FB8-0.05))) | FD8: =MIN(1,MAX(VLOOKUP(($AJ8-$AI8-$AH8-$AG8-$AF8-$AE8*(1+FD$3))/$AJ8,'Технический лист'!$A:$B,2,1),(FC8-0.05))) | ... IR8: =MIN(1,MAX(VLOOKUP(($AJ8-$AI8-$AH8-$AG8-$AF8-$AE8*(1+IR$3))/$AJ8,'Технический лист'!$A:$B,2,1),(IQ8-0.05)))
A9: ЧМ (сырье) | B9: 2 | C9: Кокс каменноугольный | D9: 17106 | E9: Кокс литейный КЛ-1 | F9: КОКС КАМЕННОУГОЛЬНЫЙ | G9: СВР | H9: ВСБ | I9: СМЫЧКА | J9: ГОНЧАРОВО | K9: 3548 | L9: Полувагоны | M9: Внутр. перевозки | N9: вагонная | O9: Восточное | P9: '000080294056 | Q9: ООО "ЕвразХолдинг" | R9: ООО "ЕвразХолдинг" | S9: 4069 | T9: 14438053 | U9: 70 | V9: 0 | W9: 8422842 | X9: 56 | Y9: групповая | Z9: 12 | AA9: 10 | AB9: 4 | AC9: 2331.39 | AD9: =AE9-AC9 | AE9: 3199.73 | AF9: =(Z9+AA9+AB9)*'Ставки аренды'!$B$3/X9 | AG9: 0 | AH9: 0 | AI9: =0.71*AVERAGE(AJ7,AJ8) | AJ9: =Цены!$D$9 | AK9: =AJ9/Цены!$B$1 | AL9: =AE9+AF9+AG9 | AM9: =AJ9-AL9 | AN9: =AI9+AH9+AG9+AF9+AE9 | AO9: =(AJ9-AN9)/AJ9 | AP9: =AL9/AJ9 | AQ9: =AE9/AJ9 | AR9: =AE9/AL9 | AS9: 1 | AT9: =S9*AS9 | AU9: 0.85 | AV9: =(AJ9-(AE9*(1+$IS$2)+AF9+AG9+AH9+AI9))/AJ9 | AW9: =(AE9*(1+$IS$2)+AF9+AG9)/AJ9 | AX9: =(AE9*(1+$IS$2))/AJ9 | AY9: =(AE9*(1+$IS$2))/(AE9*(1+$IS$2)+AF9+AG9) | AZ9: =MIN(IF($AU9=100%,1,1+VLOOKUP(($AJ9-$AI9-$AH9-$AG9-$AF9-$AE9*(1+AZ$3))/$AJ9,'Технический лист'!$A:$B,2,1)-VLOOKUP($AO9,'Технический лист'!$A:$B,2,1)),1+(1-$AU9)) | BA9: =MIN(IF($AU9=100%,1,1+VLOOKUP(($AJ9-$AI9-$AH9-$AG9-$AF9-$AE9*(1+BA$3))/$AJ9,'Технический лист'!$A:$B,2,1)-VLOOKUP($AO9,'Технический лист'!$A:$B,2,1)),1+(1-$AU9)) | BB9: =MIN(IF($AU9=100%,1,1+VLOOKUP(($AJ9-$AI9-$AH9-$AG9-$AF9-$AE9*(1+BB$3))/$AJ9,'Технический лист'!$A:$B,2,1)-VLOOKUP($AO9,'Технический лист'!$A:$B,2,1)),1+(1-$AU9)) | BC9: =MIN(IF($AU9=100%,1,1+VLOOKUP(($AJ9-$AI9-$AH9-$AG9-$AF9-$AE9*(1+BC$3))/$AJ9,'Технический лист'!$A:$B,2,1)-VLOOKUP($AO9,'Технический лист'!$A:$B,2,1)),1+(1-$AU9)) | BD9: =MIN(IF($AU9=100%,1,1+VLOOKUP(($AJ9-$AI9-$AH9-$AG9-$AF9-$AE9*(1+BD$3))/$AJ9,'Технический лист'!$A:$B,2,1)-VLOOKUP($AO9,'Технический лист'!$A:$B,2,1)),1+(1-$AU9)) | BE9: =MIN(IF($AU9=100%,1,1+VLOOKUP(($AJ9-$AI9-$AH9-$AG9-$AF9-$AE9*(1+BE$3))/$AJ9,'Технический лист'!$A:$B,2,1)-VLOOKUP($AO9,'Технический лист'!$A:$B,2,1)),1+(1-$AU9)) | BF9: =MIN(IF($AU9=100%,1,1+VLOOKUP(($AJ9-$AI9-$AH9-$AG9-$AF9-$AE9*(1+BF$3))/$AJ9,'Технический лист'!$A:$B,2,1)-VLOOKUP($AO9,'Технический лист'!$A:$B,2,1)),1+(1-$AU9)) | BG9: =MIN(IF($AU9=100%,1,1+VLOOKUP(($AJ9-$AI9-$AH9-$AG9-$AF9-$AE9*(1+BG$3))/$AJ9,'Технический лист'!$A:$B,2,1)-VLOOKUP($AO9,'Технический лист'!$A:$B,2,1)),1+(1-$AU9)) | ... EU9: =MIN(IF($AU9=100%,1,1+VLOOKUP(($AJ9-$AI9-$AH9-$AG9-$AF9-$AE9*(1+EU$3))/$AJ9,'Технический лист'!$A:$B,2,1)-VLOOKUP($AO9,'Технический лист'!$A:$B,2,1)),1+(1-$AU9)) | EV9: 1 | EW9: =MIN(1,MAX(VLOOKUP(($AJ9-$AI9-$AH9-$AG9-$AF9-$AE9*(1+EW$3))/$AJ9,'Технический лист'!$A:$B,2,1),(EV9-0.05))) | EX9: =MIN(1,MAX(VLOOKUP(($AJ9-$AI9-$AH9-$AG9-$AF9-$AE9*(1+EX$3))/$AJ9,'Технический лист'!$A:$B,2,1),(EW9-0.05))) | EY9: =MIN(1,MAX(VLOOKUP(($AJ9-$AI9-$AH9-$AG9-$AF9-$AE9*(1+EY$3))/$AJ9,'Технический лист'!$A:$B,2,1),(EX9-0.05))) | EZ9: =MIN(1,MAX(VLOOKUP(($AJ9-$AI9-$AH9-$AG9-$AF9-$AE9*(1+EZ$3))/$AJ9,'Технический лист'!$A:$B,2,1),(EY9-0.05))) | FA9: =MIN(1,MAX(VLOOKUP(($AJ9-$AI9-$AH9-$AG9-$AF9-$AE9*(1+FA$3))/$AJ9,'Технический лист'!$A:$B,2,1),(EZ9-0.05))) | FB9: =MIN(1,MAX(VLOOKUP(($AJ9-$AI9-$AH9-$AG9-$AF9-$AE9*(1+FB$3))/$AJ9,'Технический лист'!$A:$B,2,1),(FA9-0.05))) | FC9: =MIN(1,MAX(VLOOKUP(($AJ9-$AI9-$AH9-$AG9-$AF9-$AE9*(1+FC$3))/$AJ9,'Технический лист'!$A:$B,2,1),(FB9-0.05))) | FD9: =MIN(1,MAX(VLOOKUP(($AJ9-$AI9-$AH9-$AG9-$AF9-$AE9*(1+FD$3))/$AJ9,'Технический лист'!$A:$B,2,1),(FC9-0.05))) | ... IR9: =MIN(1,MAX(VLOOKUP(($AJ9-$AI9-$AH9-$AG9-$AF9-$AE9*(1+IR$3))/$AJ9,'Технический лист'!$A:$B,2,1),(IQ9-0.05)))
A10: ЧМ (сырье) | B10: 2 | C10: Кокс каменноугольный | D10: 17107 | E10: Кокс литейный КЛ-2 | F10: КОКС КАМЕННОУГОЛЬНЫЙ | G10: СВР | H10: СВР | I10: ТЮМЕНЬ-СЕВЕР | J10: УАЗ | K10: 297 | L10: Полувагоны | M10: Внутр. перевозки | N10: вагонная | O10: Южное | P10: '000027958866 | Q10: АО "Антипинский НПЗ" | R10: ООО "РИ-ИНВЕСТ" | S10: 2318 | T10: 688462 | U10: 36 | V10: 0 | W10: 941063 | X10: 64 | Y10: групповая | Z10: 4 | AA10: 4 | AB10: 4 | AC10: 447.67 | AD10: =AE10-AC10 | AE10: 553.14 | AF10: =(Z10+AA10+AB10)*'Ставки аренды'!$B$3/X10 | AG10: 0 | AH10: 0 | AI10: =0.95*AVERAGE(AJ10,AJ11) | AJ10: =Цены!$D$9 | AK10: =AJ10/Цены!$B$1 | AL10: =AE10+AF10+AG10 | AM10: =AJ10-AL10 | AN10: =AI10+AH10+AG10+AF10+AE10 | AO10: =(AJ10-AN10)/AJ10 | AP10: =AL10/AJ10 | AQ10: =AE10/AJ10 | AR10: =AE10/AL10 | AS10: 1 | AT10: =S10*AS10 | AU10: 0.95 | AV10: =(AJ10-(AE10*(1+$IS$2)+AF10+AG10+AH10+AI10))/AJ10 | AW10: =(AE10*(1+$IS$2)+AF10+AG10)/AJ10 | AX10: =(AE10*(1+$IS$2))/AJ10 | AY10: =(AE10*(1+$IS$2))/(AE10*(1+$IS$2)+AF10+AG10) | AZ10: =MIN(IF($AU10=100%,1,1+VLOOKUP(($AJ10-$AI10-$AH10-$AG10-$AF10-$AE10*(1+AZ$3))/$AJ10,'Технический лист'!$A:$B,2,1)-VLOOKUP($AO10,'Технический лист'!$A:$B,2,1)),1+(1-$AU10)) | BA10: =MIN(IF($AU10=100%,1,1+VLOOKUP(($AJ10-$AI10-$AH10-$AG10-$AF10-$AE10*(1+BA$3))/$AJ10,'Технический лист'!$A:$B,2,1)-VLOOKUP($AO10,'Технический лист'!$A:$B,2,1)),1+(1-$AU10)) | BB10: =MIN(IF($AU10=100%,1,1+VLOOKUP(($AJ10-$AI10-$AH10-$AG10-$AF10-$AE10*(1+BB$3))/$AJ10,'Технический лист'!$A:$B,2,1)-VLOOKUP($AO10,'Технический лист'!$A:$B,2,1)),1+(1-$AU10)) | BC10: =MIN(IF($AU10=100%,1,1+VLOOKUP(($AJ10-$AI10-$AH10-$AG10-$AF10-$AE10*(1+BC$3))/$AJ10,'Технический лист'!$A:$B,2,1)-VLOOKUP($AO10,'Технический лист'!$A:$B,2,1)),1+(1-$AU10)) | BD10: =MIN(IF($AU10=100%,1,1+VLOOKUP(($AJ10-$AI10-$AH10-$AG10-$AF10-$AE10*(1+BD$3))/$AJ10,'Технический лист'!$A:$B,2,1)-VLOOKUP($AO10,'Технический лист'!$A:$B,2,1)),1+(1-$AU10)) | BE10: =MIN(IF($AU10=100%,1,1+VLOOKUP(($AJ10-$AI10-$AH10-$AG10-$AF10-$AE10*(1+BE$3))/$AJ10,'Технический лист'!$A:$B,2,1)-VLOOKUP($AO10,'Технический лист'!$A:$B,2,1)),1+(1-$AU10)) | BF10: =MIN(IF($AU10=100%,1,1+VLOOKUP(($AJ10-$AI10-$AH10-$AG10-$AF10-$AE10*(1+BF$3))/$AJ10,'Технический лист'!$A:$B,2,1)-VLOOKUP($AO10,'Технический лист'!$A:$B,2,1)),1+(1-$AU10)) | BG10: =MIN(IF($AU10=100%,1,1+VLOOKUP(($AJ10-$AI10-$AH10-$AG10-$AF10-$AE10*(1+BG$3))/$AJ10,'Технический лист'!$A:$B,2,1)-VLOOKUP($AO10,'Технический лист'!$A:$B,2,1)),1+(1-$AU10)) | ... EU10: =MIN(IF($AU10=100%,1,1+VLOOKUP(($AJ10-$AI10-$AH10-$AG10-$AF10-$AE10*(1+EU$3))/$AJ10,'Технический лист'!$A:$B,2,1)-VLOOKUP($AO10,'Технический лист'!$A:$B,2,1)),1+(1-$AU10)) | EV10: 1 | EW10: =MIN(1,MAX(VLOOKUP(($AJ10-$AI10-$AH10-$AG10-$AF10-$AE10*(1+EW$3))/$AJ10,'Технический лист'!$A:$B,2,1),(EV10-0.05))) | EX10: =MIN(1,MAX(VLOOKUP(($AJ10-$AI10-$AH10-$AG10-$AF10-$AE10*(1+EX$3))/$AJ10,'Технический лист'!$A:$B,2,1),(EW10-0.05))) | EY10: =MIN(1,MAX(VLOOKUP(($AJ10-$AI10-$AH10-$AG10-$AF10-$AE10*(1+EY$3))/$AJ10,'Технический лист'!$A:$B,2,1),(EX10-0.05))) | EZ10: =MIN(1,MAX(VLOOKUP(($AJ10-$AI10-$AH10-$AG10-$AF10-$AE10*(1+EZ$3))/$AJ10,'Технический лист'!$A:$B,2,1),(EY10-0.05))) | FA10: =MIN(1,MAX(VLOOKUP(($AJ10-$AI10-$AH10-$AG10-$AF10-$AE10*(1+FA$3))/$AJ10,'Технический лист'!$A:$B,2,1),(EZ10-0.05))) | FB10: =MIN(1,MAX(VLOOKUP(($AJ10-$AI10-$AH10-$AG10-$AF10-$AE10*(1+FB$3))/$AJ10,'Технический лист'!$A:$B,2,1),(FA10-0.05))) | FC10: =MIN(1,MAX(VLOOKUP(($AJ10-$AI10-$AH10-$AG10-$AF10-$AE10*(1+FC$3))/$AJ10,'Технический лист'!$A:$B,2,1),(FB10-0.05))) | FD10: =MIN(1,MAX(VLOOKUP(($AJ10-$AI10-$AH10-$AG10-$AF10-$AE10*(1+FD$3))/$AJ10,'Технический лист'!$A:$B,2,1),(FC10-0.05))) | ... IR10: =MIN(1,MAX(VLOOKUP(($AJ10-$AI10-$AH10-$AG10-$AF10-$AE10*(1+IR$3))/$AJ10,'Технический лист'!$A:$B,2,1),(IQ10-0.05)))
A11: ЧМ (сырье) | B11: 2 | C11: Кокс каменноугольный | D11: 17107 | E11: Кокс литейный КЛ-2 | F11: КОКС КАМЕННОУГОЛЬНЫЙ | G11: СВР | H11: ЮУР | I11: ТЮМЕНЬ-СЕВЕР | J11: КАРТ1-ЭК-РОС | K11: 748 | L11: Полувагоны | M11: Экспорт | N11: вагонная | O11: Южное | P11: '000027958866 | Q11: АО "Антипинский НПЗ" | R11: ООО "РИ-ИНВЕСТ" | S11: 2167 | T11: 1621459 | U11: 34 | V11: 0 | W11: 1668248 | X11: 64 | Y11: групповая | Z11: 5 | AA11: 3 | AB11: 4 | AC11: 833.44 | AD11: =AE11-AC11 | AE11: 1080.53 | AF11: =(Z11+AA11+AB11)*'Ставки аренды'!$B$3/X11 | AG11: 0 | AH11: 0 | AI11: =0.95*AVERAGE(AJ10,AJ11) | AJ11: =Цены!$C$8*'Курсы валют'!$B$2 | AK11: =AJ11/Цены!$B$1 | AL11: =AE11+AF11+AG11 | AM11: =AJ11-AL11 | AN11: =AI11+AH11+AG11+AF11+AE11 | AO11: =(AJ11-AN11)/AJ11 | AP11: =AL11/AJ11 | AQ11: =AE11/AJ11 | AR11: =AE11/AL11 | AS11: 1 | AT11: =S11*AS11 | AU11: 0.95 | AV11: =(AJ11-(AE11*(1+$IS$2)+AF11+AG11+AH11+AI11))/AJ11 | AW11: =(AE11*(1+$IS$2)+AF11+AG11)/AJ11 | AX11: =(AE11*(1+$IS$2))/AJ11 | AY11: =(AE11*(1+$IS$2))/(AE11*(1+$IS$2)+AF11+AG11) | AZ11: =MIN(IF($AU11=100%,1,1+VLOOKUP(($AJ11-$AI11-$AH11-$AG11-$AF11-$AE11*(1+AZ$3))/$AJ11,'Технический лист'!$A:$B,2,1)-VLOOKUP($AO11,'Технический лист'!$A:$B,2,1)),1+(1-$AU11)) | BA11: =MIN(IF($AU11=100%,1,1+VLOOKUP(($AJ11-$AI11-$AH11-$AG11-$AF11-$AE11*(1+BA$3))/$AJ11,'Технический лист'!$A:$B,2,1)-VLOOKUP($AO11,'Технический лист'!$A:$B,2,1)),1+(1-$AU11)) | BB11: =MIN(IF($AU11=100%,1,1+VLOOKUP(($AJ11-$AI11-$AH11-$AG11-$AF11-$AE11*(1+BB$3))/$AJ11,'Технический лист'!$A:$B,2,1)-VLOOKUP($AO11,'Технический лист'!$A:$B,2,1)),1+(1-$AU11)) | BC11: =MIN(IF($AU11=100%,1,1+VLOOKUP(($AJ11-$AI11-$AH11-$AG11-$AF11-$AE11*(1+BC$3))/$AJ11,'Технический лист'!$A:$B,2,1)-VLOOKUP($AO11,'Технический лист'!$A:$B,2,1)),1+(1-$AU11)) | BD11: =MIN(IF($AU11=100%,1,1+VLOOKUP(($AJ11-$AI11-$AH11-$AG11-$AF11-$AE11*(1+BD$3))/$AJ11,'Технический лист'!$A:$B,2,1)-VLOOKUP($AO11,'Технический лист'!$A:$B,2,1)),1+(1-$AU11)) | BE11: =MIN(IF($AU11=100%,1,1+VLOOKUP(($AJ11-$AI11-$AH11-$AG11-$AF11-$AE11*(1+BE$3))/$AJ11,'Технический лист'!$A:$B,2,1)-VLOOKUP($AO11,'Технический лист'!$A:$B,2,1)),1+(1-$AU11)) | BF11: =MIN(IF($AU11=100%,1,1+VLOOKUP(($AJ11-$AI11-$AH11-$AG11-$AF11-$AE11*(1+BF$3))/$AJ11,'Технический лист'!$A:$B,2,1)-VLOOKUP($AO11,'Технический лист'!$A:$B,2,1)),1+(1-$AU11)) | BG11: =MIN(IF($AU11=100%,1,1+VLOOKUP(($AJ11-$AI11-$AH11-$AG11-$AF11-$AE11*(1+BG$3))/$AJ11,'Технический лист'!$A:$B,2,1)-VLOOKUP($AO11,'Технический лист'!$A:$B,2,1)),1+(1-$AU11)) | ... EU11: =MIN(IF($AU11=100%,1,1+VLOOKUP(($AJ11-$AI11-$AH11-$AG11-$AF11-$AE11*(1+EU$3))/$AJ11,'Технический лист'!$A:$B,2,1)-VLOOKUP($AO11,'Технический лист'!$A:$B,2,1)),1+(1-$AU11)) | EV11: 1 | EW11: =MIN(1,MAX(VLOOKUP(($AJ11-$AI11-$AH11-$AG11-$AF11-$AE11*(1+EW$3))/$AJ11,'Технический лист'!$A:$B,2,1),(EV11-0.05))) | EX11: =MIN(1,MAX(VLOOKUP(($AJ11-$AI11-$AH11-$AG11-$AF11-$AE11*(1+EX$3))/$AJ11,'Технический лист'!$A:$B,2,1),(EW11-0.05))) | EY11: =MIN(1,MAX(VLOOKUP(($AJ11-$AI11-$AH11-$AG11-$AF11-$AE11*(1+EY$3))/$AJ11,'Технический лист'!$A:$B,2,1),(EX11-0.05))) | EZ11: =MIN(1,MAX(VLOOKUP(($AJ11-$AI11-$AH11-$AG11-$AF11-$AE11*(1+EZ$3))/$AJ11,'Технический лист'!$A:$B,2,1),(EY11-0.05))) | FA11: =MIN(1,MAX(VLOOKUP(($AJ11-$AI11-$AH11-$AG11-$AF11-$AE11*(1+FA$3))/$AJ11,'Технический лист'!$A:$B,2,1),(EZ11-0.05))) | FB11: =MIN(1,MAX(VLOOKUP(($AJ11-$AI11-$AH11-$AG11-$AF11-$AE11*(1+FB$3))/$AJ11,'Технический лист'!$A:$B,2,1),(FA11-0.05))) | FC11: =MIN(1,MAX(VLOOKUP(($AJ11-$AI11-$AH11-$AG11-$AF11-$AE11*(1+FC$3))/$AJ11,'Технический лист'!$A:$B,2,1),(FB11-0.05))) | FD11: =MIN(1,MAX(VLOOKUP(($AJ11-$AI11-$AH11-$AG11-$AF11-$AE11*(1+FD$3))/$AJ11,'Технический лист'!$A:$B,2,1),(FC11-0.05))) | ... IR11: =MIN(1,MAX(VLOOKUP(($AJ11-$AI11-$AH11-$AG11-$AF11-$AE11*(1+IR$3))/$AJ11,'Технический лист'!$A:$B,2,1),(IQ11-0.05)))
A12: ЧМ (сырье) | B12: 2 | C12: Кокс каменноугольный | D12: 17107 | E12: Кокс литейный КЛ-2 | F12: КОКС КАМЕННОУГОЛЬНЫЙ | G12: СВР | H12: ВСБ | I12: ТЮМЕНЬ-СЕВЕР | J12: БАГУЛЬНАЯ | K12: 2676 | L12: Полувагоны | M12: Внутр. перевозки | N12: вагонная | O12: Восточное | P12: '000027958866 | Q12: АО "Антипинский НПЗ" | R12: ООО "РИ-ИНВЕСТ" | S12: 115217 | T12: 308286836 | U12: 1809 | V12: 0 | W12: 182973051 | X12: 64 | Y12: групповая | Z12: 11 | AA12: 8 | AB12: 4 | AC12: 1761.09 | AD12: =AE12-AC12 | AE12: 2415.2 | AF12: =(Z12+AA12+AB12)*'Ставки аренды'!$B$3/X12 | AG12: 0 | AH12: 0 | AI12: =0.95*AVERAGE(AJ10,AJ11) | AJ12: =Цены!$D$9 | AK12: =AJ12/Цены!$B$1 | AL12: =AE12+AF12+AG12 | AM12: =AJ12-AL12 | AN12: =AI12+AH12+AG12+AF12+AE12 | AO12: =(AJ12-AN12)/AJ12 | AP12: =AL12/AJ12 | AQ12: =AE12/AJ12 | AR12: =AE12/AL12 | AS12: 1 | AT12: =S12*AS12 | AU12: 0.95 | AV12: =(AJ12-(AE12*(1+$IS$2)+AF12+AG12+AH12+AI12))/AJ12 | AW12: =(AE12*(1+$IS$2)+AF12+AG12)/AJ12 | AX12: =(AE12*(1+$IS$2))/AJ12 | AY12: =(AE12*(1+$IS$2))/(AE12*(1+$IS$2)+AF12+AG12) | AZ12: =MIN(IF($AU12=100%,1,1+VLOOKUP(($AJ12-$AI12-$AH12-$AG12-$AF12-$AE12*(1+AZ$3))/$AJ12,'Технический лист'!$A:$B,2,1)-VLOOKUP($AO12,'Технический лист'!$A:$B,2,1)),1+(1-$AU12)) | BA12: =MIN(IF($AU12=100%,1,1+VLOOKUP(($AJ12-$AI12-$AH12-$AG12-$AF12-$AE12*(1+BA$3))/$AJ12,'Технический лист'!$A:$B,2,1)-VLOOKUP($AO12,'Технический лист'!$A:$B,2,1)),1+(1-$AU12)) | BB12: =MIN(IF($AU12=100%,1,1+VLOOKUP(($AJ12-$AI12-$AH12-$AG12-$AF12-$AE12*(1+BB$3))/$AJ12,'Технический лист'!$A:$B,2,1)-VLOOKUP($AO12,'Технический лист'!$A:$B,2,1)),1+(1-$AU12)) | BC12: =MIN(IF($AU12=100%,1,1+VLOOKUP(($AJ12-$AI12-$AH12-$AG12-$AF12-$AE12*(1+BC$3))/$AJ12,'Технический лист'!$A:$B,2,1)-VLOOKUP($AO12,'Технический лист'!$A:$B,2,1)),1+(1-$AU12)) | BD12: =MIN(IF($AU12=100%,1,1+VLOOKUP(($AJ12-$AI12-$AH12-$AG12-$AF12-$AE12*(1+BD$3))/$AJ12,'Технический лист'!$A:$B,2,1)-VLOOKUP($AO12,'Технический лист'!$A:$B,2,1)),1+(1-$AU12)) | BE12: =MIN(IF($AU12=100%,1,1+VLOOKUP(($AJ12-$AI12-$AH12-$AG12-$AF12-$AE12*(1+BE$3))/$AJ12,'Технический лист'!$A:$B,2,1)-VLOOKUP($AO12,'Технический лист'!$A:$B,2,1)),1+(1-$AU12)) | BF12: =MIN(IF($AU12=100%,1,1+VLOOKUP(($AJ12-$AI12-$AH12-$AG12-$AF12-$AE12*(1+BF$3))/$AJ12,'Технический лист'!$A:$B,2,1)-VLOOKUP($AO12,'Технический лист'!$A:$B,2,1)),1+(1-$AU12)) | BG12: =MIN(IF($AU12=100%,1,1+VLOOKUP(($AJ12-$AI12-$AH12-$AG12-$AF12-$AE12*(1+BG$3))/$AJ12,'Технический лист'!$A:$B,2,1)-VLOOKUP($AO12,'Технический лист'!$A:$B,2,1)),1+(1-$AU12)) | ... EU12: =MIN(IF($AU12=100%,1,1+VLOOKUP(($AJ12-$AI12-$AH12-$AG12-$AF12-$AE12*(1+EU$3))/$AJ12,'Технический лист'!$A:$B,2,1)-VLOOKUP($AO12,'Технический лист'!$A:$B,2,1)),1+(1-$AU12)) | EV12: 1 | EW12: =MIN(1,MAX(VLOOKUP(($AJ12-$AI12-$AH12-$AG12-$AF12-$AE12*(1+EW$3))/$AJ12,'Технический лист'!$A:$B,2,1),(EV12-0.05))) | EX12: =MIN(1,MAX(VLOOKUP(($AJ12-$AI12-$AH12-$AG12-$AF12-$AE12*(1+EX$3))/$AJ12,'Технический лист'!$A:$B,2,1),(EW12-0.05))) | EY12: =MIN(1,MAX(VLOOKUP(($AJ12-$AI12-$AH12-$AG12-$AF12-$AE12*(1+EY$3))/$AJ12,'Технический лист'!$A:$B,2,1),(EX12-0.05))) | EZ12: =MIN(1,MAX(VLOOKUP(($AJ12-$AI12-$AH12-$AG12-$AF12-$AE12*(1+EZ$3))/$AJ12,'Технический лист'!$A:$B,2,1),(EY12-0.05))) | FA12: =MIN(1,MAX(VLOOKUP(($AJ12-$AI12-$AH12-$AG12-$AF12-$AE12*(1+FA$3))/$AJ12,'Технический лист'!$A:$B,2,1),(EZ12-0.05))) | FB12: =MIN(1,MAX(VLOOKUP(($AJ12-$AI12-$AH12-$AG12-$AF12-$AE12*(1+FB$3))/$AJ12,'Технический лист'!$A:$B,2,1),(FA12-0.05))) | FC12: =MIN(1,MAX(VLOOKUP(($AJ12-$AI12-$AH12-$AG12-$AF12-$AE12*(1+FC$3))/$AJ12,'Технический лист'!$A:$B,2,1),(FB12-0.05))) | FD12: =MIN(1,MAX(VLOOKUP(($AJ12-$AI12-$AH12-$AG12-$AF12-$AE12*(1+FD$3))/$AJ12,'Технический лист'!$A:$B,2,1),(FC12-0.05))) | ... IR12: =MIN(1,MAX(VLOOKUP(($AJ12-$AI12-$AH12-$AG12-$AF12-$AE12*(1+IR$3))/$AJ12,'Технический лист'!$A:$B,2,1),(IQ12-0.05)))
A13: ЧМ (сырье) | B13: 2 | C13: Кокс каменноугольный | D13: 17111 | E13: Кокс электродный | F13: КОКС КАМЕННОУГОЛЬНЫЙ | G13: ЗСБ | H13: ЗСБ | I13: ПРЕДКОМБИНАТ | J13: КУЛУНДА-ЭК-Р | K13: 804 | L13: Полувагоны | M13: Экспорт | N13: вагонная | O13: Южное | P13: '000078553378 | Q13: ООО "УК"ПМХ" | R13: ООО "УК"ПМХ" | S13: 103613 | T13: 83305004 | U13: 2081 | V13: 0 | W13: 103864531 | X13: 50 | Y13: групповая | Z13: 6 | AA13: 3 | AB13: 4 | AC13: 1088.32 | AD13: =AE13-AC13 | AE13: 1424.38 | AF13: =(Z13+AA13+AB13)*'Ставки аренды'!$B$3/X13 | AG13: 0 | AH13: 0 | AI13: =0.9*AVERAGE(AJ13,AJ14) | AJ13: =Цены!$C$8*'Курсы валют'!$B$2 | AK13: =AJ13/Цены!$B$1 | AL13: =AE13+AF13+AG13 | AM13: =AJ13-AL13 | AN13: =AI13+AH13+AG13+AF13+AE13 | AO13: =(AJ13-AN13)/AJ13 | AP13: =AL13/AJ13 | AQ13: =AE13/AJ13 | AR13: =AE13/AL13 | AS13: 1 | AT13: =S13*AS13 | AU13: 0.9 | AV13: =(AJ13-(AE13*(1+$IS$2)+AF13+AG13+AH13+AI13))/AJ13 | AW13: =(AE13*(1+$IS$2)+AF13+AG13)/AJ13 | AX13: =(AE13*(1+$IS$2))/AJ13 | AY13: =(AE13*(1+$IS$2))/(AE13*(1+$IS$2)+AF13+AG13) | AZ13: =MIN(IF($AU13=100%,1,1+VLOOKUP(($AJ13-$AI13-$AH13-$AG13-$AF13-$AE13*(1+AZ$3))/$AJ13,'Технический лист'!$A:$B,2,1)-VLOOKUP($AO13,'Технический лист'!$A:$B,2,1)),1+(1-$AU13)) | BA13: =MIN(IF($AU13=100%,1,1+VLOOKUP(($AJ13-$AI13-$AH13-$AG13-$AF13-$AE13*(1+BA$3))/$AJ13,'Технический лист'!$A:$B,2,1)-VLOOKUP($AO13,'Технический лист'!$A:$B,2,1)),1+(1-$AU13)) | BB13: =MIN(IF($AU13=100%,1,1+VLOOKUP(($AJ13-$AI13-$AH13-$AG13-$AF13-$AE13*(1+BB$3))/$AJ13,'Технический лист'!$A:$B,2,1)-VLOOKUP($AO13,'Технический лист'!$A:$B,2,1)),1+(1-$AU13)) | BC13: =MIN(IF($AU13=100%,1,1+VLOOKUP(($AJ13-$AI13-$AH13-$AG13-$AF13-$AE13*(1+BC$3))/$AJ13,'Технический лист'!$A:$B,2,1)-VLOOKUP($AO13,'Технический лист'!$A:$B,2,1)),1+(1-$AU13)) | BD13: =MIN(IF($AU13=100%,1,1+VLOOKUP(($AJ13-$AI13-$AH13-$AG13-$AF13-$AE13*(1+BD$3))/$AJ13,'Технический лист'!$A:$B,2,1)-VLOOKUP($AO13,'Технический лист'!$A:$B,2,1)),1+(1-$AU13)) | BE13: =MIN(IF($AU13=100%,1,1+VLOOKUP(($AJ13-$AI13-$AH13-$AG13-$AF13-$AE13*(1+BE$3))/$AJ13,'Технический лист'!$A:$B,2,1)-VLOOKUP($AO13,'Технический лист'!$A:$B,2,1)),1+(1-$AU13)) | BF13: =MIN(IF($AU13=100%,1,1+VLOOKUP(($AJ13-$AI13-$AH13-$AG13-$AF13-$AE13*(1+BF$3))/$AJ13,'Технический лист'!$A:$B,2,1)-VLOOKUP($AO13,'Технический лист'!$A:$B,2,1)),1+(1-$AU13)) | BG13: =MIN(IF($AU13=100%,1,1+VLOOKUP(($AJ13-$AI13-$AH13-$AG13-$AF13-$AE13*(1+BG$3))/$AJ13,'Технический лист'!$A:$B,2,1)-VLOOKUP($AO13,'Технический лист'!$A:$B,2,1)),1+(1-$AU13)) | ... EU13: =MIN(IF($AU13=100%,1,1+VLOOKUP(($AJ13-$AI13-$AH13-$AG13-$AF13-$AE13*(1+EU$3))/$AJ13,'Технический лист'!$A:$B,2,1)-VLOOKUP($AO13,'Технический лист'!$A:$B,2,1)),1+(1-$AU13)) | EV13: 1 | EW13: =MIN(1,MAX(VLOOKUP(($AJ13-$AI13-$AH13-$AG13-$AF13-$AE13*(1+EW$3))/$AJ13,'Технический лист'!$A:$B,2,1),(EV13-0.05))) | EX13: =MIN(1,MAX(VLOOKUP(($AJ13-$AI13-$AH13-$AG13-$AF13-$AE13*(1+EX$3))/$AJ13,'Технический лист'!$A:$B,2,1),(EW13-0.05))) | EY13: =MIN(1,MAX(VLOOKUP(($AJ13-$AI13-$AH13-$AG13-$AF13-$AE13*(1+EY$3))/$AJ13,'Технический лист'!$A:$B,2,1),(EX13-0.05))) | EZ13: =MIN(1,MAX(VLOOKUP(($AJ13-$AI13-$AH13-$AG13-$AF13-$AE13*(1+EZ$3))/$AJ13,'Технический лист'!$A:$B,2,1),(EY13-0.05))) | FA13: =MIN(1,MAX(VLOOKUP(($AJ13-$AI13-$AH13-$AG13-$AF13-$AE13*(1+FA$3))/$AJ13,'Технический лист'!$A:$B,2,1),(EZ13-0.05))) | FB13: =MIN(1,MAX(VLOOKUP(($AJ13-$AI13-$AH13-$AG13-$AF13-$AE13*(1+FB$3))/$AJ13,'Технический лист'!$A:$B,2,1),(FA13-0.05))) | FC13: =MIN(1,MAX(VLOOKUP(($AJ13-$AI13-$AH13-$AG13-$AF13-$AE13*(1+FC$3))/$AJ13,'Технический лист'!$A:$B,2,1),(FB13-0.05))) | FD13: =MIN(1,MAX(VLOOKUP(($AJ13-$AI13-$AH13-$AG13-$AF13-$AE13*(1+FD$3))/$AJ13,'Технический лист'!$A:$B,2,1),(FC13-0.05))) | ... IR13: =MIN(1,MAX(VLOOKUP(($AJ13-$AI13-$AH13-$AG13-$AF13-$AE13*(1+IR$3))/$AJ13,'Технический лист'!$A:$B,2,1),(IQ13-0.05)))
A14: ЧМ (сырье) | B14: 2 | C14: Кокс каменноугольный | D14: 17103 | E14: Кокс доменный фракции свыше 25 мм | F14: КОКС КАМЕННОУГОЛЬНЫЙ | G14: ЗСБ | H14: СВР | I14: ПРЕДКОМБИНАТ | J14: СМЫЧКА | K14: 1982 | L14: Полувагоны | M14: Внутр. перевозки | N14: вагонная | O14: Южное | P14: '000000186683 | Q14: 'ПАО "Кокс" | R14: ООО "УК"ПМХ" | S14: 269089 | T14: 533360184 | U14: 5368 | V14: 0 | W14: 426612557 | X14: 50 | Y14: групповая | Z14: 9 | AA14: 8 | AB14: 4 | AC14: 1785.7 | AD14: =AE14-AC14 | AE14: 2528.84 | AF14: =(Z14+AA14+AB14)*'Ставки аренды'!$B$3/X14 | AG14: 0 | AH14: 0 | AI14: =0.9*AVERAGE(AJ13,AJ14) | AJ14: =Цены!$D$9 | AK14: =AJ14/Цены!$B$1 | AL14: =AE14+AF14+AG14 | AM14: =AJ14-AL14 | AN14: =AI14+AH14+AG14+AF14+AE14 | AO14: =(AJ14-AN14)/AJ14 | AP14: =AL14/AJ14 | AQ14: =AE14/AJ14 | AR14: =AE14/AL14 | AS14: 1 | AT14: =S14*AS14 | AU14: 0.9 | AV14: =(AJ14-(AE14*(1+$IS$2)+AF14+AG14+AH14+AI14))/AJ14 | AW14: =(AE14*(1+$IS$2)+AF14+AG14)/AJ14 | AX14: =(AE14*(1+$IS$2))/AJ14 | AY14: =(AE14*(1+$IS$2))/(AE14*(1+$IS$2)+AF14+AG14) | AZ14: =MIN(IF($AU14=100%,1,1+VLOOKUP(($AJ14-$AI14-$AH14-$AG14-$AF14-$AE14*(1+AZ$3))/$AJ14,'Технический лист'!$A:$B,2,1)-VLOOKUP($AO14,'Технический лист'!$A:$B,2,1)),1+(1-$AU14)) | BA14: =MIN(IF($AU14=100%,1,1+VLOOKUP(($AJ14-$AI14-$AH14-$AG14-$AF14-$AE14*(1+BA$3))/$AJ14,'Технический лист'!$A:$B,2,1)-VLOOKUP($AO14,'Технический лист'!$A:$B,2,1)),1+(1-$AU14)) | BB14: =MIN(IF($AU14=100%,1,1+VLOOKUP(($AJ14-$AI14-$AH14-$AG14-$AF14-$AE14*(1+BB$3))/$AJ14,'Технический лист'!$A:$B,2,1)-VLOOKUP($AO14,'Технический лист'!$A:$B,2,1)),1+(1-$AU14)) | BC14: =MIN(IF($AU14=100%,1,1+VLOOKUP(($AJ14-$AI14-$AH14-$AG14-$AF14-$AE14*(1+BC$3))/$AJ14,'Технический лист'!$A:$B,2,1)-VLOOKUP($AO14,'Технический лист'!$A:$B,2,1)),1+(1-$AU14)) | BD14: =MIN(IF($AU14=100%,1,1+VLOOKUP(($AJ14-$AI14-$AH14-$AG14-$AF14-$AE14*(1+BD$3))/$AJ14,'Технический лист'!$A:$B,2,1)-VLOOKUP($AO14,'Технический лист'!$A:$B,2,1)),1+(1-$AU14)) | BE14: =MIN(IF($AU14=100%,1,1+VLOOKUP(($AJ14-$AI14-$AH14-$AG14-$AF14-$AE14*(1+BE$3))/$AJ14,'Технический лист'!$A:$B,2,1)-VLOOKUP($AO14,'Технический лист'!$A:$B,2,1)),1+(1-$AU14)) | BF14: =MIN(IF($AU14=100%,1,1+VLOOKUP(($AJ14-$AI14-$AH14-$AG14-$AF14-$AE14*(1+BF$3))/$AJ14,'Технический лист'!$A:$B,2,1)-VLOOKUP($AO14,'Технический лист'!$A:$B,2,1)),1+(1-$AU14)) | BG14: =MIN(IF($AU14=100%,1,1+VLOOKUP(($AJ14-$AI14-$AH14-$AG14-$AF14-$AE14*(1+BG$3))/$AJ14,'Технический лист'!$A:$B,2,1)-VLOOKUP($AO14,'Технический лист'!$A:$B,2,1)),1+(1-$AU14)) | ... EU14: =MIN(IF($AU14=100%,1,1+VLOOKUP(($AJ14-$AI14-$AH14-$AG14-$AF14-$AE14*(1+EU$3))/$AJ14,'Технический лист'!$A:$B,2,1)-VLOOKUP($AO14,'Технический лист'!$A:$B,2,1)),1+(1-$AU14)) | EV14: 1 | EW14: =MIN(1,MAX(VLOOKUP(($AJ14-$AI14-$AH14-$AG14-$AF14-$AE14*(1+EW$3))/$AJ14,'Технический лист'!$A:$B,2,1),(EV14-0.05))) | EX14: =MIN(1,MAX(VLOOKUP(($AJ14-$AI14-$AH14-$AG14-$AF14-$AE14*(1+EX$3))/$AJ14,'Технический лист'!$A:$B,2,1),(EW14-0.05))) | EY14: =MIN(1,MAX(VLOOKUP(($AJ14-$AI14-$AH14-$AG14-$AF14-$AE14*(1+EY$3))/$AJ14,'Технический лист'!$A:$B,2,1),(EX14-0.05))) | EZ14: =MIN(1,MAX(VLOOKUP(($AJ14-$AI14-$AH14-$AG14-$AF14-$AE14*(1+EZ$3))/$AJ14,'Технический лист'!$A:$B,2,1),(EY14-0.05))) | FA14: =MIN(1,MAX(VLOOKUP(($AJ14-$AI14-$AH14-$AG14-$AF14-$AE14*(1+FA$3))/$AJ14,'Технический лист'!$A:$B,2,1),(EZ14-0.05))) | FB14: =MIN(1,MAX(VLOOKUP(($AJ14-$AI14-$AH14-$AG14-$AF14-$AE14*(1+FB$3))/$AJ14,'Технический лист'!$A:$B,2,1),(FA14-0.05))) | FC14: =MIN(1,MAX(VLOOKUP(($AJ14-$AI14-$AH14-$AG14-$AF14-$AE14*(1+FC$3))/$AJ14,'Технический лист'!$A:$B,2,1),(FB14-0.05))) | FD14: =MIN(1,MAX(VLOOKUP(($AJ14-$AI14-$AH14-$AG14-$AF14-$AE14*(1+FD$3))/$AJ14,'Технический лист'!$A:$B,2,1),(FC14-0.05))) | ... IR14: =MIN(1,MAX(VLOOKUP(($AJ14-$AI14-$AH14-$AG14-$AF14-$AE14*(1+IR$3))/$AJ14,'Технический лист'!$A:$B,2,1),(IQ14-0.05)))
A15: ЧМ (сырье) | B15: 2 | C15: Кокс каменноугольный | D15: 17110 | E15: Кокс, не поименованный в алфавите | F15: КОКС КАМЕННОУГОЛЬНЫЙ | G15: МСК | H15: ПРВ | I15: ПРИСАДЫ | J15: ОЗИНКИ-Э-РОС | K15: 1221 | L15: Полувагоны | M15: Экспорт | N15: вагонная | O15: Южное | P15: '000000186281 | Q15: 'ПАО "Тулачермет" | R15: ООО "УК"ПМХ" | S15: 90345 | T15: 110291447 | U15: 1566 | V15: 0 | W15: 102631838 | X15: 58 | Y15: групповая | Z15: 7 | AA15: 4 | AB15: 4 | AC15: 1249.38 | AD15: =AE15-AC15 | AE15: 1667.24 | AF15: =(Z15+AA15+AB15)*'Ставки аренды'!$B$3/X15 | AG15: 0 | AH15: 0 | AI15: =0.9*AVERAGE(AJ13,AJ14) | AJ15: =Цены!$C$8*'Курсы валют'!$B$2 | AK15: =AJ15/Цены!$B$1 | AL15: =AE15+AF15+AG15 | AM15: =AJ15-AL15 | AN15: =AI15+AH15+AG15+AF15+AE15 | AO15: =(AJ15-AN15)/AJ15 | AP15: =AL15/AJ15 | AQ15: =AE15/AJ15 | AR15: =AE15/AL15 | AS15: 1 | AT15: =S15*AS15 | AU15: 0.9 | AV15: =(AJ15-(AE15*(1+$IS$2)+AF15+AG15+AH15+AI15))/AJ15 | AW15: =(AE15*(1+$IS$2)+AF15+AG15)/AJ15 | AX15: =(AE15*(1+$IS$2))/AJ15 | AY15: =(AE15*(1+$IS$2))/(AE15*(1+$IS$2)+AF15+AG15) | AZ15: =MIN(IF($AU15=100%,1,1+VLOOKUP(($AJ15-$AI15-$AH15-$AG15-$AF15-$AE15*(1+AZ$3))/$AJ15,'Технический лист'!$A:$B,2,1)-VLOOKUP($AO15,'Технический лист'!$A:$B,2,1)),1+(1-$AU15)) | BA15: =MIN(IF($AU15=100%,1,1+VLOOKUP(($AJ15-$AI15-$AH15-$AG15-$AF15-$AE15*(1+BA$3))/$AJ15,'Технический лист'!$A:$B,2,1)-VLOOKUP($AO15,'Технический лист'!$A:$B,2,1)),1+(1-$AU15)) | BB15: =MIN(IF($AU15=100%,1,1+VLOOKUP(($AJ15-$AI15-$AH15-$AG15-$AF15-$AE15*(1+BB$3))/$AJ15,'Технический лист'!$A:$B,2,1)-VLOOKUP($AO15,'Технический лист'!$A:$B,2,1)),1+(1-$AU15)) | BC15: =MIN(IF($AU15=100%,1,1+VLOOKUP(($AJ15-$AI15-$AH15-$AG15-$AF15-$AE15*(1+BC$3))/$AJ15,'Технический лист'!$A:$B,2,1)-VLOOKUP($AO15,'Технический лист'!$A:$B,2,1)),1+(1-$AU15)) | BD15: =MIN(IF($AU15=100%,1,1+VLOOKUP(($AJ15-$AI15-$AH15-$AG15-$AF15-$AE15*(1+BD$3))/$AJ15,'Технический лист'!$A:$B,2,1)-VLOOKUP($AO15,'Технический лист'!$A:$B,2,1)),1+(1-$AU15)) | BE15: =MIN(IF($AU15=100%,1,1+VLOOKUP(($AJ15-$AI15-$AH15-$AG15-$AF15-$AE15*(1+BE$3))/$AJ15,'Технический лист'!$A:$B,2,1)-VLOOKUP($AO15,'Технический лист'!$A:$B,2,1)),1+(1-$AU15)) | BF15: =MIN(IF($AU15=100%,1,1+VLOOKUP(($AJ15-$AI15-$AH15-$AG15-$AF15-$AE15*(1+BF$3))/$AJ15,'Технический лист'!$A:$B,2,1)-VLOOKUP($AO15,'Технический лист'!$A:$B,2,1)),1+(1-$AU15)) | BG15: =MIN(IF($AU15=100%,1,1+VLOOKUP(($AJ15-$AI15-$AH15-$AG15-$AF15-$AE15*(1+BG$3))/$AJ15,'Технический лист'!$A:$B,2,1)-VLOOKUP($AO15,'Технический лист'!$A:$B,2,1)),1+(1-$AU15)) | ... EU15: =MIN(IF($AU15=100%,1,1+VLOOKUP(($AJ15-$AI15-$AH15-$AG15-$AF15-$AE15*(1+EU$3))/$AJ15,'Технический лист'!$A:$B,2,1)-VLOOKUP($AO15,'Технический лист'!$A:$B,2,1)),1+(1-$AU15)) | EV15: 1 | EW15: =MIN(1,MAX(VLOOKUP(($AJ15-$AI15-$AH15-$AG15-$AF15-$AE15*(1+EW$3))/$AJ15,'Технический лист'!$A:$B,2,1),(EV15-0.05))) | EX15: =MIN(1,MAX(VLOOKUP(($AJ15-$AI15-$AH15-$AG15-$AF15-$AE15*(1+EX$3))/$AJ15,'Технический лист'!$A:$B,2,1),(EW15-0.05))) | EY15: =MIN(1,MAX(VLOOKUP(($AJ15-$AI15-$AH15-$AG15-$AF15-$AE15*(1+EY$3))/$AJ15,'Технический лист'!$A:$B,2,1),(EX15-0.05))) | EZ15: =MIN(1,MAX(VLOOKUP(($AJ15-$AI15-$AH15-$AG15-$AF15-$AE15*(1+EZ$3))/$AJ15,'Технический лист'!$A:$B,2,1),(EY15-0.05))) | FA15: =MIN(1,MAX(VLOOKUP(($AJ15-$AI15-$AH15-$AG15-$AF15-$AE15*(1+FA$3))/$AJ15,'Технический лист'!$A:$B,2,1),(EZ15-0.05))) | FB15: =MIN(1,MAX(VLOOKUP(($AJ15-$AI15-$AH15-$AG15-$AF15-$AE15*(1+FB$3))/$AJ15,'Технический лист'!$A:$B,2,1),(FA15-0.05))) | FC15: =MIN(1,MAX(VLOOKUP(($AJ15-$AI15-$AH15-$AG15-$AF15-$AE15*(1+FC$3))/$AJ15,'Технический лист'!$A:$B,2,1),(FB15-0.05))) | FD15: =MIN(1,MAX(VLOOKUP(($AJ15-$AI15-$AH15-$AG15-$AF15-$AE15*(1+FD$3))/$AJ15,'Технический лист'!$A:$B,2,1),(FC15-0.05))) | ... IR15: =MIN(1,MAX(VLOOKUP(($AJ15-$AI15-$AH15-$AG15-$AF15-$AE15*(1+IR$3))/$AJ15,'Технический лист'!$A:$B,2,1),(IQ15-0.05)))
A16: ЧМ (сырье) | B16: 2 | C16: Кокс каменноугольный | D16: 17111 | E16: Кокс электродный | F16: КОКС КАМЕННОУГОЛЬНЫЙ | G16: ЗСБ | H16: КРС | I16: ПРЕДКОМБИНАТ | J16: ЛЕСОСИБ-ПЕР | K16: 697 | L16: Полувагоны | M16: Внутр. перевозки | N16: вагонная | O16: Восточное | P16: '000000186683 | Q16: 'ПАО "Кокс" | R16: ООО "УК"ПМХ" | S16: 21520 | T16: 14999320 | U16: 432 | V16: 0 | W16: 17973782 | X16: 50 | Y16: групповая | Z16: 6 | AA16: 6 | AB16: 4 | AC16: 903.98 | AD16: =AE16-AC16 | AE16: 1203.9 | AF16: =(Z16+AA16+AB16)*'Ставки аренды'!$B$3/X16 | AG16: 0 | AH16: 0 | AI16: =0.9*AVERAGE(AJ13,AJ14) | AJ16: =Цены!$D$9 | AK16: =AJ16/Цены!$B$1 | AL16: =AE16+AF16+AG16 | AM16: =AJ16-AL16 | AN16: =AI16+AH16+AG16+AF16+AE16 | AO16: =(AJ16-AN16)/AJ16 | AP16: =AL16/AJ16 | AQ16: =AE16/AJ16 | AR16: =AE16/AL16 | AS16: 1 | AT16: =S16*AS16 | AU16: 0.9 | AV16: =(AJ16-(AE16*(1+$IS$2)+AF16+AG16+AH16+AI16))/AJ16 | AW16: =(AE16*(1+$IS$2)+AF16+AG16)/AJ16 | AX16: =(AE16*(1+$IS$2))/AJ16 | AY16: =(AE16*(1+$IS$2))/(AE16*(1+$IS$2)+AF16+AG16) | AZ16: =MIN(IF($AU16=100%,1,1+VLOOKUP(($AJ16-$AI16-$AH16-$AG16-$AF16-$AE16*(1+AZ$3))/$AJ16,'Технический лист'!$A:$B,2,1)-VLOOKUP($AO16,'Технический лист'!$A:$B,2,1)),1+(1-$AU16)) | BA16: =MIN(IF($AU16=100%,1,1+VLOOKUP(($AJ16-$AI16-$AH16-$AG16-$AF16-$AE16*(1+BA$3))/$AJ16,'Технический лист'!$A:$B,2,1)-VLOOKUP($AO16,'Технический лист'!$A:$B,2,1)),1+(1-$AU16)) | BB16: =MIN(IF($AU16=100%,1,1+VLOOKUP(($AJ16-$AI16-$AH16-$AG16-$AF16-$AE16*(1+BB$3))/$AJ16,'Технический лист'!$A:$B,2,1)-VLOOKUP($AO16,'Технический лист'!$A:$B,2,1)),1+(1-$AU16)) | BC16: =MIN(IF($AU16=100%,1,1+VLOOKUP(($AJ16-$AI16-$AH16-$AG16-$AF16-$AE16*(1+BC$3))/$AJ16,'Технический лист'!$A:$B,2,1)-VLOOKUP($AO16,'Технический лист'!$A:$B,2,1)),1+(1-$AU16)) | BD16: =MIN(IF($AU16=100%,1,1+VLOOKUP(($AJ16-$AI16-$AH16-$AG16-$AF16-$AE16*(1+BD$3))/$AJ16,'Технический лист'!$A:$B,2,1)-VLOOKUP($AO16,'Технический лист'!$A:$B,2,1)),1+(1-$AU16)) | BE16: =MIN(IF($AU16=100%,1,1+VLOOKUP(($AJ16-$AI16-$AH16-$AG16-$AF16-$AE16*(1+BE$3))/$AJ16,'Технический лист'!$A:$B,2,1)-VLOOKUP($AO16,'Технический лист'!$A:$B,2,1)),1+(1-$AU16)) | BF16: =MIN(IF($AU16=100%,1,1+VLOOKUP(($AJ16-$AI16-$AH16-$AG16-$AF16-$AE16*(1+BF$3))/$AJ16,'Технический лист'!$A:$B,2,1)-VLOOKUP($AO16,'Технический лист'!$A:$B,2,1)),1+(1-$AU16)) | BG16: =MIN(IF($AU16=100%,1,1+VLOOKUP(($AJ16-$AI16-$AH16-$AG16-$AF16-$AE16*(1+BG$3))/$AJ16,'Технический лист'!$A:$B,2,1)-VLOOKUP($AO16,'Технический лист'!$A:$B,2,1)),1+(1-$AU16)) | ... EU16: =MIN(IF($AU16=100%,1,1+VLOOKUP(($AJ16-$AI16-$AH16-$AG16-$AF16-$AE16*(1+EU$3))/$AJ16,'Технический лист'!$A:$B,2,1)-VLOOKUP($AO16,'Технический лист'!$A:$B,2,1)),1+(1-$AU16)) | EV16: 1 | EW16: =MIN(1,MAX(VLOOKUP(($AJ16-$AI16-$AH16-$AG16-$AF16-$AE16*(1+EW$3))/$AJ16,'Технический лист'!$A:$B,2,1),(EV16-0.05))) | EX16: =MIN(1,MAX(VLOOKUP(($AJ16-$AI16-$AH16-$AG16-$AF16-$AE16*(1+EX$3))/$AJ16,'Технический лист'!$A:$B,2,1),(EW16-0.05))) | EY16: =MIN(1,MAX(VLOOKUP(($AJ16-$AI16-$AH16-$AG16-$AF16-$AE16*(1+EY$3))/$AJ16,'Технический лист'!$A:$B,2,1),(EX16-0.05))) | EZ16: =MIN(1,MAX(VLOOKUP(($AJ16-$AI16-$AH16-$AG16-$AF16-$AE16*(1+EZ$3))/$AJ16,'Технический лист'!$A:$B,2,1),(EY16-0.05))) | FA16: =MIN(1,MAX(VLOOKUP(($AJ16-$AI16-$AH16-$AG16-$AF16-$AE16*(1+FA$3))/$AJ16,'Технический лист'!$A:$B,2,1),(EZ16-0.05))) | FB16: =MIN(1,MAX(VLOOKUP(($AJ16-$AI16-$AH16-$AG16-$AF16-$AE16*(1+FB$3))/$AJ16,'Технический лист'!$A:$B,2,1),(FA16-0.05))) | FC16: =MIN(1,MAX(VLOOKUP(($AJ16-$AI16-$AH16-$AG16-$AF16-$AE16*(1+FC$3))/$AJ16,'Технический лист'!$A:$B,2,1),(FB16-0.05))) | FD16: =MIN(1,MAX(VLOOKUP(($AJ16-$AI16-$AH16-$AG16-$AF16-$AE16*(1+FD$3))/$AJ16,'Технический лист'!$A:$B,2,1),(FC16-0.05))) | ... IR16: =MIN(1,MAX(VLOOKUP(($AJ16-$AI16-$AH16-$AG16-$AF16-$AE16*(1+IR$3))/$AJ16,'Технический лист'!$A:$B,2,1),(IQ16-0.05)))
A17: ЧМ (сырье) | B17: 2 | C17: Кокс каменноугольный | D17: 17110 | E17: Кокс, не поименованный в алфавите | F17: КОКС КАМЕННОУГОЛЬНЫЙ | G17: ЗСБ | H17: ДВС | I17: ПРЕДКОМБИНАТ | J17: ГРОДЕК/КИТАЙ | K17: 5788 | L17: Полувагоны | M17: Экспорт | N17: вагонная | O17: Восточное | P17: '000000186683 | Q17: 'ПАО "Кокс" | R17: ООО "УК"ПМХ" | S17: 10601 | T17: 61359168 | U17: 178 | V17: 0 | W17: 31981756 | X17: 60 | Y17: повагонная | Z17: 17 | AA17: 14 | AB17: 4 | AC17: 333.78 | AD17: =AE17-AC17 | AE17: 4793.08 | AF17: =(Z17+AA17+AB17)*'Ставки аренды'!$B$3/X17 | AG17: 0 | AH17: 0 | AI17: =0.9*AVERAGE(AJ13,AJ14) | AJ17: =Цены!$C$8*'Курсы валют'!$B$2 | AK17: =AJ17/Цены!$B$1 | AL17: =AE17+AF17+AG17 | AM17: =AJ17-AL17 | AN17: =AI17+AH17+AG17+AF17+AE17 | AO17: =(AJ17-AN17)/AJ17 | AP17: =AL17/AJ17 | AQ17: =AE17/AJ17 | AR17: =AE17/AL17 | AS17: 1 | AT17: =S17*AS17 | AU17: 0.9 | AV17: =(AJ17-(AE17*(1+$IS$2)+AF17+AG17+AH17+AI17))/AJ17 | AW17: =(AE17*(1+$IS$2)+AF17+AG17)/AJ17 | AX17: =(AE17*(1+$IS$2))/AJ17 | AY17: =(AE17*(1+$IS$2))/(AE17*(1+$IS$2)+AF17+AG17) | AZ17: =MIN(IF($AU17=100%,1,1+VLOOKUP(($AJ17-$AI17-$AH17-$AG17-$AF17-$AE17*(1+AZ$3))/$AJ17,'Технический лист'!$A:$B,2,1)-VLOOKUP($AO17,'Технический лист'!$A:$B,2,1)),1+(1-$AU17)) | BA17: =MIN(IF($AU17=100%,1,1+VLOOKUP(($AJ17-$AI17-$AH17-$AG17-$AF17-$AE17*(1+BA$3))/$AJ17,'Технический лист'!$A:$B,2,1)-VLOOKUP($AO17,'Технический лист'!$A:$B,2,1)),1+(1-$AU17)) | BB17: =MIN(IF($AU17=100%,1,1+VLOOKUP(($AJ17-$AI17-$AH17-$AG17-$AF17-$AE17*(1+BB$3))/$AJ17,'Технический лист'!$A:$B,2,1)-VLOOKUP($AO17,'Технический лист'!$A:$B,2,1)),1+(1-$AU17)) | BC17: =MIN(IF($AU17=100%,1,1+VLOOKUP(($AJ17-$AI17-$AH17-$AG17-$AF17-$AE17*(1+BC$3))/$AJ17,'Технический лист'!$A:$B,2,1)-VLOOKUP($AO17,'Технический лист'!$A:$B,2,1)),1+(1-$AU17)) | BD17: =MIN(IF($AU17=100%,1,1+VLOOKUP(($AJ17-$AI17-$AH17-$AG17-$AF17-$AE17*(1+BD$3))/$AJ17,'Технический лист'!$A:$B,2,1)-VLOOKUP($AO17,'Технический лист'!$A:$B,2,1)),1+(1-$AU17)) | BE17: =MIN(IF($AU17=100%,1,1+VLOOKUP(($AJ17-$AI17-$AH17-$AG17-$AF17-$AE17*(1+BE$3))/$AJ17,'Технический лист'!$A:$B,2,1)-VLOOKUP($AO17,'Технический лист'!$A:$B,2,1)),1+(1-$AU17)) | BF17: =MIN(IF($AU17=100%,1,1+VLOOKUP(($AJ17-$AI17-$AH17-$AG17-$AF17-$AE17*(1+BF$3))/$AJ17,'Технический лист'!$A:$B,2,1)-VLOOKUP($AO17,'Технический лист'!$A:$B,2,1)),1+(1-$AU17)) | BG17: =MIN(IF($AU17=100%,1,1+VLOOKUP(($AJ17-$AI17-$AH17-$AG17-$AF17-$AE17*(1+BG$3))/$AJ17,'Технический лист'!$A:$B,2,1)-VLOOKUP($AO17,'Технический лист'!$A:$B,2,1)),1+(1-$AU17)) | ... EU17: =MIN(IF($AU17=100%,1,1+VLOOKUP(($AJ17-$AI17-$AH17-$AG17-$AF17-$AE17*(1+EU$3))/$AJ17,'Технический лист'!$A:$B,2,1)-VLOOKUP($AO17,'Технический лист'!$A:$B,2,1)),1+(1-$AU17)) | EV17: 1 | EW17: =MIN(1,MAX(VLOOKUP(($AJ17-$AI17-$AH17-$AG17-$AF17-$AE17*(1+EW$3))/$AJ17,'Технический лист'!$A:$B,2,1),(EV17-0.05))) | EX17: =MIN(1,MAX(VLOOKUP(($AJ17-$AI17-$AH17-$AG17-$AF17-$AE17*(1+EX$3))/$AJ17,'Технический лист'!$A:$B,2,1),(EW17-0.05))) | EY17: =MIN(1,MAX(VLOOKUP(($AJ17-$AI17-$AH17-$AG17-$AF17-$AE17*(1+EY$3))/$AJ17,'Технический лист'!$A:$B,2,1),(EX17-0.05))) | EZ17: =MIN(1,MAX(VLOOKUP(($AJ17-$AI17-$AH17-$AG17-$AF17-$AE17*(1+EZ$3))/$AJ17,'Технический лист'!$A:$B,2,1),(EY17-0.05))) | FA17: =MIN(1,MAX(VLOOKUP(($AJ17-$AI17-$AH17-$AG17-$AF17-$AE17*(1+FA$3))/$AJ17,'Технический лист'!$A:$B,2,1),(EZ17-0.05))) | FB17: =MIN(1,MAX(VLOOKUP(($AJ17-$AI17-$AH17-$AG17-$AF17-$AE17*(1+FB$3))/$AJ17,'Технический лист'!$A:$B,2,1),(FA17-0.05))) | FC17: =MIN(1,MAX(VLOOKUP(($AJ17-$AI17-$AH17-$AG17-$AF17-$AE17*(1+FC$3))/$AJ17,'Технический лист'!$A:$B,2,1),(FB17-0.05))) | FD17: =MIN(1,MAX(VLOOKUP(($AJ17-$AI17-$AH17-$AG17-$AF17-$AE17*(1+FD$3))/$AJ17,'Технический лист'!$A:$B,2,1),(FC17-0.05))) | ... IR17: =MIN(1,MAX(VLOOKUP(($AJ17-$AI17-$AH17-$AG17-$AF17-$AE17*(1+IR$3))/$AJ17,'Технический лист'!$A:$B,2,1),(IQ17-0.05)))
