Workbook
Name ccc: #REF!
Name ccc: #REF!
Name cmndBase: #REF!
Name cmndBase: #REF!
Name cmndDayMonthTo: #REF!
Name cmndDayMonthTo: #REF!
Name cmndDays: #REF!
Name cmndDays: #REF!
Name cmndDocNum: #REF!
Name cmndDocNum: #REF!
Name cmndDocSer: #REF!
Name cmndDocSer: #REF!
Name cmndFIO: #REF!
Name cmndFIO: #REF!
Name cmndOrdDay: #REF!
Name cmndOrdDay: #REF!
Name cmndOrdMonth: #REF!
Name cmndOrdMonth: #REF!
Name cmndOrdNum: #REF!
Name cmndOrdNum: #REF!
Name cmndOrdYear: #REF!
Name cmndOrdYear: #REF!
Name cmndPoint: #REF!
Name cmndPoint: #REF!
Name cmndPoint1: #REF!
Name cmndPoint1: #REF!
Name cmndPos: #REF!
Name cmndPos: #REF!
Name cmndYearTo: #REF!
Name cmndYearTo: #REF!
Name cntAddition: #REF!
Name cntAddition: #REF!
Name cntDay: #REF!
Name cntDay: #REF!
Name cntMonth: #REF!
Name cntMonth: #REF!
Name cntName: #REF!
Name cntName: #REF!
Name cntNumber: #REF!
Name cntNumber: #REF!
Name cntPayer: #REF!
Name cntPayer: #REF!
Name cntPayer1: #REF!
Name cntPayer1: #REF!
Name cntPayerAddr1: #REF!
Name cntPayerAddr1: #REF!
Name cntPayerAddr2: #REF!
Name cntPayerAddr2: #REF!
Name cntPayerBank1: #REF!
Name cntPayerBank1: #REF!
Name cntPayerBank2: #REF!
Name cntPayerBank2: #REF!
Name cntPayerBank3: #REF!
Name cntPayerBank3: #REF!
Name cntPayerCount: #REF!
Name cntPayerCount: #REF!
Name cntPayerCountCor: #REF!
Name cntPayerCountCor: #REF!
Name cntPriceC: #REF!
Name cntPriceC: #REF!

Sheet Выпадение всего
A2: УГОЛЬ экспорт | G2: Справочно коэфф по направлениям:
C3: Значения | H3: Значения
A4: Вид груза | B4: Направление | C4: Сумма по полю Объем перевозок (тн) | D4: Сумма по полю объем* коэфф | E4: Сумма по полю Средний коэфф сохранения базы | G4: Названия строк | H4: Сумма по полю Объем перевозок (тн) | I4: Сумма по полю объем* коэфф | J4: Сумма по полю Средний коэфф сохранения базы
A5: антрацит (энергетический уголь) | B5: Восточное | C5: 2022773 | D5: 2022773 | E5: 1 | G5: Восточное | H5: 16935950 | I5: 16884958 | J5: 0.9969891
A6: антрацит (энергетический уголь) Итог | C6: 2022773 | D6: 2022773 | E6: 1 | G6: Северо-Западное | H6: 10287319 | I6: 10061954 | J6: 0.97809295
A7: уголь для коксования | B7: Восточное | C7: 1434447 | D7: 1434447 | E7: 1 | G7: Южное | H7: 3748943 | I7: 3727812.4 | J7: 0.99436358
B8: Северо-Западное | C8: 51530 | D8: 51530 | E8: 1 | G8: Общий итог | H8: 30972212 | I8: 30674724 | J8: 0.99039501
B9: Южное | C9: 595825 | D9: 595825 | E9: 1
A10: уголь для коксования Итог | C10: 2081802 | D10: 2081802 | E10: 1 | G10: ПАРАМЕТРЫ ИЗМЕНЕНИЯ ТАРИФА
A11: уголь энергетический (кроме антрацита) | B11: Восточное | C11: 13478730 | D11: 13427738 | E11: 0.99621682 | G11: TRUE | H11: TRUE | J11: FALSE
B12: Северо-Западное | C12: 10235789 | D12: 10010424 | E12: 0.97798266 | G12: до 50% | I12: до -50%
B13: Южное | C13: 3153118 | D13: 3131987.4 | E13: 0.9932985 | G13: ИНДЕКСАЦИЯ
A14: уголь энергетический (кроме антрацита) Итог | C14: 26867637 | D14: 26570149 | E14: 0.98892765 | I14: 45 | J14: 0.1
A15: Общий итог | C15: 30972212 | D15: 30674724 | E15: 0.99039501
G16: СКИДКА
I17: 0 | J17: =-(I17/1000) -> 0
A24: млн.тонн | B24: 2025 | D24: 2026 | H24: 2027 | L24: 2028 | P24: 2029 | T24: 2030
B25: Факт ИХ перевезено | C25: Факт (по плану погрузки) | D25: План | E25: с учетом чувствительности | F25: +/- | G25: +/- % | H25: План | I25: с учетом чувствительности | J25: +/- | K25: +/- % | L25: План | M25: с учетом чувствительности | N25: +/- | O25: +/- % | P25: План | Q25: с учетом чувствительности | R25: +/- | S25: +/- % | T25: План | U25: с учетом чувствительности | V25: +/- | W25: +/- %
A26: Всего погрузка: | B26: =B27+B28 -> 327.53617 | C26: =C27+C28 -> 324.46634 | D26: =D27+D28 -> 328.24059 | E26: =E27+E28 -> 327.05762 | F26: =E26-D26 -> -1.1829684 | G26: =F26/D26 -> -0.0036039674 | H26: =H27+H28 -> 326.22648 | I26: =I27+I28 -> 325.04866 | J26: =I26-H26 -> -1.1778266 | K26: =J26/H26 -> -0.0036104568 | L26: =L27+L28 -> 326.725 | M26: =M27+M28 -> 325.5405 | N26: =M26-L26 -> -1.184503 | O26: =N26/L26 -> -0.0036253823 | P26: =P27+P28 -> 327.511 | Q26: =Q27+Q28 -> 326.29489 | R26: =Q26-P26 -> -1.21611 | S26: =R26/P26 -> -0.0037131884 | T26: =T27+T28 -> 328.9 | U26: =U27+U28 -> 327.64686 | V26: =U26-T26 -> -1.2531352 | W26: =V26/T26 -> -0.0038100798
A27: Внутренние | B27: 148.39864 | C27: ='План погрузки'!G20 -> 147.43839 | D27: ='План погрузки'!H20 -> 143.42277 | E27: =D27 -> 143.42277 | H27: ='План погрузки'!I20 -> 143.539 | I27: =H27 -> 143.539 | L27: ='План погрузки'!J20 -> 143.525 | M27: =L27 -> 143.525 | P27: ='План погрузки'!K20 -> 143.811 | Q27: =P27 -> 143.811 | T27: ='План погрузки'!L20 -> 144.4 | U27: =T27 -> 144.4
A28: Экспорт | B28: =B33+B37+B41 -> 179.13752 | C28: =SUM(C29:C31) -> 177.02795 | D28: =SUM(D29:D31) -> 184.81782 | E28: =E33+E37+E41 -> 183.63485 | F28: =E28-D28 -> -1.1829684 | G28: =F28/D28 -> -0.0064007268 | H28: =SUM(H29:H31) -> 182.68748 | I28: =I33+I37+I41 -> 181.50966 | J28: =I28-H28 -> -1.1778266 | K28: =J28/H28 -> -0.0064472212 | L28: =SUM(L29:L31) -> 183.2 | M28: =M33+M37+M41 -> 182.0155 | N28: =M28-L28 -> -1.184503 | O28: =N28/L28 -> -0.0064656279 | P28: =SUM(P29:P31) -> 183.7 | Q28: =Q33+Q37+Q41 -> 182.48389 | R28: =Q28-P28 -> -1.21611 | S28: =R28/P28 -> -0.0066200873 | T28: =SUM(T29:T31) -> 184.5 | U28: =U33+U37+U41 -> 183.24686 | V28: =U28-T28 -> -1.2531352 | W28: =V28/T28 -> -0.006792061
A29: Восточное | B29: =B34+B38+B42 -> 118.71894 | C29: ='План погрузки'!G72 -> 118.19677 | D29: ='План погрузки'!H72 -> 119.96579 | E29: =E34+E38+E42 -> 119.65578 | F29: =E29-D29 -> -0.31001173 | G29: =F29/D29 -> -0.0025841678 | H29: ='План погрузки'!I72 -> 117.707 | I29: =I34+I38+I42 -> 117.40283 | J29: =I29-H29 -> -0.30417464 | K29: =J29/H29 -> -0.0025841678 | L29: ='План погрузки'!J72 -> 117.707 | M29: =M34+M38+M42 -> 117.40283 | N29: =M29-L29 -> -0.30417464 | O29: =N29/L29 -> -0.0025841678 | P29: ='План погрузки'!K72 -> 116.197 | Q29: =Q34+Q38+Q42 -> 115.89673 | R29: =Q29-P29 -> -0.30027255 | S29: =R29/P29 -> -0.0025841678 | T29: ='План погрузки'!L72 -> 114.707 | U29: =U34+U38+U42 -> 114.41058 | V29: =U29-T29 -> -0.29642214 | W29: =V29/T29 -> -0.0025841678
A30: Северо-Западное | B30: =B35+B39+B43 -> 39.259007 | C30: ='План погрузки'!G46 -> 38.307818 | D30: ='План погрузки'!H46 -> 37.677301 | E30: =E35+E39+E43 -> 36.951446 | F30: =E30-D30 -> -0.72585494 | G30: =F30/D30 -> -0.019265046 | H30: ='План погрузки'!I46 -> 37.677301 | I30: =I35+I39+I43 -> 36.951446 | J30: =I30-H30 -> -0.72585494 | K30: =J30/H30 -> -0.019265046 | L30: ='План погрузки'!J46 -> 37.959 | M30: =M35+M39+M43 -> 37.227718 | N30: =M30-L30 -> -0.73128188 | O30: =N30/L30 -> -0.019265046 | P30: ='План погрузки'!K46 -> 39.737 | Q30: =Q35+Q39+Q43 -> 38.971465 | R30: =Q30-P30 -> -0.76553514 | S30: =R30/P30 -> -0.019265046 | T30: ='План погрузки'!L46 -> 41.793 | U30: =U35+U39+U43 -> 40.987856 | V30: =U30-T30 -> -0.80514407 | W30: =V30/T30 -> -0.019265046
A31: Южное | B31: =B36+B40+B44 -> 21.159581 | C31: ='План погрузки'!G59 -> 20.523359 | D31: ='План погрузки'!H59 -> 27.174729 | E31: =E36+E40+E44 -> 27.027627 | F31: =E31-D31 -> -0.1471017 | G31: =F31/D31 -> -0.00541318 | H31: ='План погрузки'!I59 -> 27.303182 | I31: =I36+I40+I44 -> 27.155385 | J31: =I31-H31 -> -0.14779704 | K31: =J31/H31 -> -0.00541318 | L31: ='План погрузки'!J59 -> 27.534 | M31: =M36+M40+M44 -> 27.384954 | N31: =M31-L31 -> -0.1490465 | O31: =N31/L31 -> -0.00541318 | P31: ='План погрузки'!K59 -> 27.766 | Q31: =Q36+Q40+Q44 -> 27.615698 | R31: =Q31-P31 -> -0.15030236 | S31: =R31/P31 -> -0.00541318 | T31: ='План погрузки'!L59 -> 28 | U31: =U36+U40+U44 -> 27.848431 | V31: =U31-T31 -> -0.15156904 | W31: =V31/T31 -> -0.00541318
A32: в т.ч. Экспорт:
A33: уголь энергетический (кроме антрацита) | B33: =B34+B35+B36 -> 132.53632 | D33: =SUM(D34:D36) -> 136.86279 | E33: =SUM(E34:E36) -> 135.67982 | F33: =E33-D33 -> -1.1829684 | G33: =F33/D33 -> -0.0086434623 | H33: =SUM(H34:H36) -> 135.42364 | I33: =SUM(I34:I36) -> 134.24582 | J33: =I33-H33 -> -1.1778266 | K33: =J33/H33 -> -0.0086973485 | L33: =SUM(L34:L36) -> 135.85657 | M33: =SUM(M34:M36) -> 134.67207 | N33: =M33-L33 -> -1.184503 | O33: =N33/L33 -> -0.008718776 | P33: =SUM(P34:P36) -> 136.56828 | Q33: =SUM(Q34:Q36) -> 135.35217 | R33: =Q33-P33 -> -1.21611 | S33: =R33/P33 -> -0.0089047768 | T33: =SUM(T34:T36) -> 137.53851 | U33: =SUM(U34:U36) -> 136.28538 | V33: =U33-T33 -> -1.2531352 | W33: =V33/T33 -> -0.009111159
A34: Восточное | B34: 81.09312 | D34: =$D$29*$B$34/$B$29 -> 81.944806 | E34: =$E$11*D34 -> 81.634794 | F34: =E34-D34 -> -0.31001173 | G34: =F34/D34 -> -0.0037831773 | H34: =$H$29*$B$34/$B$29 -> 80.401899 | I34: =$E$11*H34 -> 80.097725 | J34: =I34-H34 -> -0.30417464 | K34: =J34/H34 -> -0.0037831773 | L34: =$L$29*$B$34/$B$29 -> 80.401899 | M34: =$E$11*L34 -> 80.097725 | N34: =M34-L34 -> -0.30417464 | O34: =N34/L34 -> -0.0037831773 | P34: =$P$29*$B$34/$B$29 -> 79.370467 | Q34: =$E$11*P34 -> 79.070194 | R34: =Q34-P34 -> -0.30027255 | S34: =R34/P34 -> -0.0037831773 | T34: =$T$29*$B$34/$B$29 -> 78.352695 | U34: =$E$11*T34 -> 78.056273 | V34: =U34-T34 -> -0.29642214 | W34: =V34/T34 -> -0.0037831773
A35: Северо-Западное | B35: 34.351411 | D35: =$D$30*$B$35/$B$30 -> 32.967427 | E35: =$E$12*D35 -> 32.241572 | F35: =E35-D35 -> -0.72585494 | G35: =F35/D35 -> -0.022017337 | H35: =$H$30*$B$35/$B$30 -> 32.967427 | I35: =$E$12*H35 -> 32.241572 | J35: =I35-H35 -> -0.72585494 | K35: =J35/H35 -> -0.022017337 | L35: =$L$30*$B$35/$B$30 -> 33.213912 | M35: =$E$12*L35 -> 32.48263 | N35: =M35-L35 -> -0.73128188 | O35: =N35/L35 -> -0.022017337 | P35: =$P$30*$B$35/$B$30 -> 34.769652 | Q35: =$E$12*P35 -> 34.004117 | R35: =Q35-P35 -> -0.76553514 | S35: =R35/P35 -> -0.022017337 | T35: =$T$30*$B$35/$B$30 -> 36.568641 | U35: =$E$12*T35 -> 35.763497 | V35: =U35-T35 -> -0.80514407 | W35: =V35/T35 -> -0.022017337
A36: Южное | B36: 17.091784 | D36: =$D$31*$B$36/$B$31 -> 21.950557 | E36: =$E$13*D36 -> 21.803456 | F36: =E36-D36 -> -0.1471017 | G36: =F36/D36 -> -0.0067015018 | H36: =$H$31*$B$36/$B$31 -> 22.054316 | I36: =$E$13*H36 -> 21.906519 | J36: =I36-H36 -> -0.14779704 | K36: =J36/H36 -> -0.0067015018 | L36: =$L$31*$B$36/$B$31 -> 22.240761 | M36: =$E$13*L36 -> 22.091714 | N36: =M36-L36 -> -0.1490465 | O36: =N36/L36 -> -0.0067015018 | P36: =$P$31*$B$36/$B$31 -> 22.42816 | Q36: =$E$13*P36 -> 22.277858 | R36: =Q36-P36 -> -0.15030236 | S36: =R36/P36 -> -0.0067015018 | T36: =$T$31*$B$36/$B$31 -> 22.617175 | U36: =$E$13*T36 -> 22.465606 | V36: =U36-T36 -> -0.15156904 | W36: =V36/T36 -> -0.0067015018
A37: уголь для коксования | B37: =B38+B39+B40 -> 32.077955 | D37: =SUM(D38:D40) -> 32.896365 | E37: =SUM(E38:E40) -> 32.896365 | F37: =E37-D37 -> 0 | G37: =F37/D37 -> 0 | H37: =SUM(H38:H40) -> 32.385708 | I37: =SUM(I38:I40) -> 32.385708 | J37: =I37-H37 -> 0 | K37: =J37/H37 -> 0 | L37: =SUM(L38:L40) -> 32.426464 | M37: =SUM(M38:M40) -> 32.426464 | N37: =M37-L37 -> 0 | O37: =N37/L37 -> 0 | P37: =SUM(P38:P40) -> 32.206433 | Q37: =SUM(Q38:Q40) -> 32.206433 | R37: =Q37-P37 -> 0 | S37: =R37/P37 -> 0 | T37: =SUM(T38:T40) -> 32.007851 | U37: =SUM(U38:U40) -> 32.007851 | V37: =U37-T37 -> 0 | W37: =V37/T37 -> 0
A38: Восточное | B38: 27.539394 | D38: =$D$29*$B$38/$B$29 -> 27.828628 | E38: =$E$7*D38 -> 27.828628 | F38: =E38-D38 -> 0 | G38: =F38/D38 -> 0 | H38: =$H$29*$B$38/$B$29 -> 27.304654 | I38: =$E$7*H38 -> 27.304654 | J38: =I38-H38 -> 0 | K38: =J38/H38 -> 0 | L38: =$L$29*$B$38/$B$29 -> 27.304654 | M38: =$E$7*L38 -> 27.304654 | N38: =M38-L38 -> 0 | O38: =N38/L38 -> 0 | P38: =$P$29*$B$38/$B$29 -> 26.954377 | Q38: =$E$7*P38 -> 26.954377 | R38: =Q38-P38 -> 0 | S38: =R38/P38 -> 0 | T38: =$T$29*$B$38/$B$29 -> 26.60874 | U38: =$E$7*T38 -> 26.60874 | V38: =U38-T38 -> 0 | W38: =V38/T38 -> 0
A39: Северо-Западное | B39: 2.34476 | D39: =$D$30*$B$39/$B$30 -> 2.250292 | E39: =$E$8*D39 -> 2.250292 | F39: =E39-D39 -> 0 | G39: =F39/D39 -> 0 | H39: =$H$30*$B$39/$B$30 -> 2.250292 | I39: =$E$8*H39 -> 2.250292 | J39: =I39-H39 -> 0 | K39: =J39/H39 -> 0 | L39: =$L$30*$B$39/$B$30 -> 2.2671166 | M39: =$E$8*L39 -> 2.2671166 | N39: =M39-L39 -> 0 | O39: =N39/L39 -> 0 | P39: =$P$30*$B$39/$B$30 -> 2.3733083 | Q39: =$E$8*P39 -> 2.3733083 | R39: =Q39-P39 -> 0 | S39: =R39/P39 -> 0 | T39: =$T$30*$B$39/$B$30 -> 2.4961038 | U39: =$E$8*T39 -> 2.4961038 | V39: =U39-T39 -> 0 | W39: =V39/T39 -> 0
A40: Южное | B40: 2.193801 | D40: =$D$31*$B$40/$B$31 -> 2.8174446 | E40: =$E$9*D40 -> 2.8174446 | F40: =E40-D40 -> 0 | G40: =F40/D40 -> 0 | H40: =$H$31*$B$40/$B$31 -> 2.8307625 | I40: =$E$9*H40 -> 2.8307625 | J40: =I40-H40 -> 0 | K40: =J40/H40 -> 0 | L40: =$L$31*$B$40/$B$31 -> 2.8546934 | M40: =$E$9*L40 -> 2.8546934 | N40: =M40-L40 -> 0 | O40: =N40/L40 -> 0 | P40: =$P$31*$B$40/$B$31 -> 2.8787469 | Q40: =$E$9*P40 -> 2.8787469 | R40: =Q40-P40 -> 0 | S40: =R40/P40 -> 0 | T40: =$T$31*$B$40/$B$31 -> 2.9030078 | U40: =$E$9*T40 -> 2.9030078 | V40: =U40-T40 -> 0 | W40: =V40/T40 -> 0
A41: антрацит (энергетический уголь) | B41: =B42+B43+B44 -> 14.523253 | D41: =SUM(D42:D44) -> 15.058663 | E41: =SUM(E42:E44) -> 15.058663 | F41: =E41-D41 -> 0 | G41: =F41/D41 -> 0 | H41: =SUM(H42:H44) -> 14.878132 | I41: =SUM(I42:I44) -> 14.878132 | J41: =I41-H41 -> 0 | K41: =J41/H41 -> 0 | L41: =SUM(L42:L44) -> 14.916963 | M41: =SUM(M42:M44) -> 14.916963 | N41: =M41-L41 -> 0 | O41: =N41/L41 -> 0 | P41: =SUM(P42:P44) -> 14.925288 | Q41: =SUM(Q42:Q44) -> 14.925288 | R41: =Q41-P41 -> 0 | S41: =R41/P41 -> 0 | T41: =SUM(T42:T44) -> 14.953638 | U41: =SUM(U42:U44) -> 14.953638 | V41: =U41-T41 -> 0 | W41: =V41/T41 -> 0
A42: Восточное | B42: 10.086421 | D42: =$D$29*$B$42/$B$29 -> 10.192354 | E42: =$E$5*D42 -> 10.192354 | F42: =E42-D42 -> 0 | G42: =F42/D42 -> 0 | H42: =$H$29*$B$42/$B$29 -> 10.000446 | I42: =$E$5*H42 -> 10.000446 | J42: =I42-H42 -> 0 | K42: =J42/H42 -> 0 | L42: =$L$29*$B$42/$B$29 -> 10.000446 | M42: =$E$5*L42 -> 10.000446 | N42: =M42-L42 -> 0 | O42: =N42/L42 -> 0 | P42: =$P$29*$B$42/$B$29 -> 9.8721561 | Q42: =$E$5*P42 -> 9.8721561 | R42: =Q42-P42 -> 0 | S42: =R42/P42 -> 0 | T42: =$T$29*$B$42/$B$29 -> 9.745565 | U42: =$E$5*T42 -> 9.745565 | V42: =U42-T42 -> 0 | W42: =V42/T42 -> 0
A43: Северо-Западное | B43: 2.562836 | D43: =$D$30*$B$43/$B$30 -> 2.4595819 | E43: =$E$5*D43 -> 2.4595819 | F43: =E43-D43 -> 0 | G43: =F43/D43 -> 0 | H43: =$H$30*$B$43/$B$30 -> 2.4595819 | I43: =$E$5*H43 -> 2.4595819 | J43: =I43-H43 -> 0 | K43: =J43/H43 -> 0 | L43: =$L$30*$B$43/$B$30 -> 2.4779713 | M43: =$E$5*L43 -> 2.4779713 | N43: =M43-L43 -> 0 | O43: =N43/L43 -> 0 | P43: =$P$30*$B$43/$B$30 -> 2.5940395 | Q43: =$E$5*P43 -> 2.5940395 | R43: =Q43-P43 -> 0 | S43: =R43/P43 -> 0 | T43: =$T$30*$B$43/$B$30 -> 2.7282556 | U43: =$E$5*T43 -> 2.7282556 | V43: =U43-T43 -> 0 | W43: =V43/T43 -> 0
A44: Южное | B44: 1.873996 | D44: =$D$31*$B$44/$B$31 -> 2.4067269 | E44: =$E$5*D44 -> 2.4067269 | F44: =E44-D44 -> 0 | G44: =F44/D44 -> 0 | H44: =$H$31*$B$44/$B$31 -> 2.4181033 | I44: =$E$5*H44 -> 2.4181033 | J44: =I44-H44 -> 0 | K44: =J44/H44 -> 0 | L44: =$L$31*$B$44/$B$31 -> 2.4385457 | M44: =$E$5*L44 -> 2.4385457 | N44: =M44-L44 -> 0 | O44: =N44/L44 -> 0 | P44: =$P$31*$B$44/$B$31 -> 2.4590928 | Q44: =$E$5*P44 -> 2.4590928 | R44: =Q44-P44 -> 0 | S44: =R44/P44 -> 0 | T44: =$T$31*$B$44/$B$31 -> 2.479817 | U44: =$E$5*T44 -> 2.479817 | V44: =U44-T44 -> 0 | W44: =V44/T44 -> 0

Sheet Уголь_эластика_экспорт
IS1: индексация жд тарифа | IU1: индексация заданная | IV1: =1+(IX1/1000) -> 1 | IW1: корректировка | IX1: 0
B2: параметры перевозок | X2: параметры расчета тарифа | AC2: экономика перевозок в текущих условиях | AT2: для усреднения | AU2: Коэффициент загрузки предприятия | AV2: трнаспортная с индексацией | AZ2: Изменение тарифа ОАО "РЖД" | IS2: =ROUND(IU2,2) -> 0.1 | IT2: =IF(IS2<0,"скидка","индексация") -> индексация | IU2: =IF(AND('Выпадение всего'!G11=TRUE,'Выпадение всего'!J11=FALSE),'Выпадение всего'!J14,IF(AND('Выпадение всего'!G11=FALSE,'Выпадение всего'!J11=TRUE),'Выпадение всего'!J17)) -> 0.1 | IV2: 1 | IW2: при корректировке коэфф НЕ может принимать значения >1, если у ИПЕМ он <=1, т.е. груз нечувствителен
A3: сцеп цены | B3: Код группы груза | C3: Группа груза | D3: Код груза | E3: Наим груза | F3: Вид груза | G3: Дор отпр | H3: Дор наз | I3: Станц отпр РФ | J3: Станц назн РФ | K3: Средняя дальность(км) | L3: Род вагона | M3: Вид перевозки | N3: Признак контейнерной отправки | O3: Направление | P3: ОКПО компании | Q3: Компания отправителя | R3: Холдинг отправителя | S3: Объем перевозок (тн) | T3: Грузооборот, ткм | U3: Кол-во вагонов | V3: Кол-во контейнеров | W3: Провозная плата, руб | X3: Загрузка вагона | Y3: Категория отправки | Z3: Груженый рейс, дней | AA3: Порожний рейс, дней | AB3: Погрузка-разгрузка, дней | AC3: Расходы по оплате услуг ОАО 'РЖД', руб. за тонну гружёный рейс | AD3: Расходы по оплате услуг ОАО 'РЖД', руб. за тонну порожний рейс | AE3: Расходы по оплате услуг ОАО 'РЖД', руб. за тонну общая стоимость (тарифные условия 2026 года) | AF3: Расходы по оплате услуг операторов, руб. за тонну | AG3: Расходы на перевалку, руб. за тонну | AH3: Акциз/пошлина | AI3: Себестоимость добычи/производства, руб. т. | AJ3: Стоимость 1 тонны на рынке, руб./т. | AK3: Стоимость 1 тонны на рынке, $/т. | AL3: Общие транспортные расходы, руб. за тонну | AM3: Нетбэк, руб. за тонну | AN3: Общие расходы, руб. за тонну | AO3: Маржинальность в текущих условиях | AP3: Транспортная составляющая в цене % | AQ3: Инфраструктурная составляющая в цене % | AR3: Инфраструктурная составляющая в транспортных затратах | AS3: Коэффициент сохранения базы В РАСЧЕТ | AT3: объем* коэфф | AV3: Маржинальность с индексацией | AW3: Транспортная составляющая в цене % | AX3: Инфраструктурная составляющая в цене % | AY3: Инфраструктурная составляющая в транспортных затратах | AZ3: =ROUND(BA3-0.5%,3) -> -0.5 | BA3: =ROUND(BB3-0.5%,3) -> -0.495 | BB3: =ROUND(BC3-0.5%,3) -> -0.49 | BC3: =ROUND(BD3-0.5%,3) -> -0.485 | BD3: =ROUND(BE3-0.5%,3) -> -0.48 | BE3: =ROUND(BF3-0.5%,3) -> -0.475 | BF3: =ROUND(BG3-0.5%,3) -> -0.47 | BG3: =ROUND(BH3-0.5%,3) -> -0.465 | ... CW3: =ROUND(CX3-0.5%,3) -> -0.255 | CX3: -0.25 | CY3: -0.245 | CZ3: -0.24 | DA3: -0.235 | DB3: -0.23 | DC3: -0.225 | DD3: -0.22 | DE3: -0.215 | DF3: -0.21 | DG3: -0.205 | DH3: -0.2 | DI3: -0.195 | DJ3: -0.19 | DK3: -0.185 | DL3: -0.18 | DM3: -0.175 | DN3: -0.17 | DO3: -0.165 | DP3: -0.16 | DQ3: -0.155 | DR3: -0.15 | DS3: -0.145 | DT3: -0.14 | DU3: -0.135 | DV3: -0.13 | DW3: -0.125 | DX3: -0.12 | DY3: -0.115 | DZ3: -0.11 | EA3: -0.105 | EB3: -0.1 | EC3: -0.095 | ED3: -0.09 | EE3: -0.085 | EF3: -0.08 | EG3: -0.075 | EH3: -0.07 | EI3: -0.065 | EJ3: -0.06 | EK3: -0.055 | EL3: -0.05 | EM3: -0.045 | EN3: -0.04 | EO3: -0.035 | EP3: -0.03 | EQ3: -0.025 | ER3: -0.02 | ES3: -0.015 | ET3: -0.01 | EU3: -0.005 | EV3: 0 | EW3: 0.005 | EX3: 0.01 | EY3: 0.015 | EZ3: 0.02 | FA3: 0.025 | FB3: 0.03 | FC3: 0.035 | FD3: 0.04 | FE3: 0.045 | FF3: 0.05 | FG3: 0.055 | FH3: 0.06 | FI3: 0.065 | FJ3: 0.07 | FK3: 0.075 | FL3: 0.08 | FM3: 0.085 | FN3: 0.09 | FO3: 0.095 | FP3: 0.1 | FQ3: 0.105 | FR3: 0.11 | FS3: 0.115 | FT3: 0.12 | FU3: 0.125 | FV3: 0.13 | FW3: 0.135 | FX3: 0.14 | FY3: 0.145 | FZ3: 0.15 | GA3: 0.155 | GB3: 0.16 | GC3: 0.165 | GD3: 0.17 | GE3: 0.175 | GF3: 0.18 | GG3: 0.185 | GH3: 0.19 | GI3: 0.195 | GJ3: 0.2 | GK3: 0.205 | GL3: 0.21 | GM3: 0.215 | GN3: 0.22 | GO3: 0.225 | GP3: 0.23 | GQ3: 0.235 | GR3: 0.24 | GS3: 0.245 | GT3: 0.25 | GU3: 0.255 | GV3: 0.26 | GW3: 0.265 | GX3: 0.27 | GY3: 0.275 | GZ3: 0.28 | HA3: 0.285 | HB3: 0.29 | HC3: 0.295 | HD3: 0.3 | HE3: 0.305 | HF3: 0.31 | HG3: 0.315 | HH3: 0.32 | HI3: 0.325 | HJ3: 0.33 | HK3: 0.335 | HL3: 0.34 | HM3: 0.345 | HN3: 0.35 | HO3: 0.355 | HP3: 0.36 | HQ3: 0.365 | HR3: 0.37 | HS3: 0.375 | HT3: 0.38 | HU3: 0.385 | HV3: 0.39 | HW3: 0.395 | HX3: 0.4 | HY3: 0.405 | HZ3: 0.41 | IA3: 0.415 | IB3: 0.42 | IC3: 0.425 | ID3: 0.43 | IE3: 0.435 | IF3: 0.44 | IG3: 0.445 | IH3: 0.45 | II3: 0.455 | IJ3: 0.46 | IK3: 0.465 | IL3: 0.47 | IM3: 0.475 | IN3: 0.48 | IO3: 0.485 | IP3: 0.49 | IQ3: 0.495 | IR3: 0.5 | IS3: Коэффициент сохранения базы ИПЕМ | IT3: Коэффициент сохранения базы с корректировкой | IW3: при корректировке коэфф МОЖЕТ принимать значения >1, если у ИПЕМ он <=1, т.е. груз нечувствителен
A4: уголь энергетический (кроме антрацита)ЭкспортВосточное | B4: 1 | C4: Уголь каменный | D4: 16111 | E4: УГОЛЬ Г | F4: уголь энергетический (кроме антрацита) | G4: ДВС | H4: ДВС | I4: ЧЕГДОМЫН | J4: ВАНИНО-ЭКСП | K4: 971 | L4: полувагон | M4: Экспорт | N4: неконтейнерная | O4: Восточное | P4: 54657469 | Q4: ООО "КАРБОНПРО" | R4: АО "СУЭК" | S4: 4534534 | T4: 4403034520 | U4: 60744 | W4: 3250215610 | X4: 75 | Y4: группа вагонов | Z4: 7 | AA4: 7 | AB4: 4 | AC4: 808.81 | AD4: 406.26 | AE4: =AC4+AD4 -> 1215.07 | AF4: ='Цены,перевалка,аренда'!$C$26*SUM(Уголь_эластика_экспорт!Z4+Уголь_эластика_экспорт!AA4+Уголь_эластика_экспорт!AB4)/Уголь_эластика_экспорт!X4 -> 240 | AG4: =SUMIF('Цены,перевалка,аренда'!$A$20:$A$22,Уголь_эластика_экспорт!$O4,'Цены,перевалка,аренда'!$D$20:$D$22) -> 763.055 | AI4: 5018 | AJ4: =SUMIF('Цены,перевалка,аренда'!$A$5:$A$17,Уголь_эластика_экспорт!A4,'Цены,перевалка,аренда'!$D$5:$D$17) -> 8546.216 | AK4: =AJ4/'Цены,перевалка,аренда'!$C$1 -> 112 | AL4: =AE4+AF4+AG4 -> 2218.125 | AM4: =AJ4-AL4 -> 6328.091 | AN4: =AI4+AH4+AG4+AF4+AE4 -> 7236.125 | AO4: =(AJ4-AN4)/AJ4 -> 0.15329486 | AP4: =AL4/AJ4 -> 0.25954469 | AQ4: =AE4/AJ4 -> 0.14217637 | AR4: =AE4/AL4 -> 0.54779149 | AS4: =IT4 -> 1 | AT4: =S4*AS4 -> 4534534 | AU4: 1 | AV4: =(AJ4-(AE4*(1+$IS$2)+AF4+AG4+AH4+AI4))/AJ4 -> 0.13907722 | AW4: =(AE4*(1+$IS$2)+AF4+AG4)/AJ4 -> 0.27376233 | AX4: =(AE4*(1+$IS$2))/AJ4 -> 0.15639401 | AY4: =(AE4*(1+$IS$2))/(AE4*(1+$IS$2)+AF4+AG4) -> 0.57127659 | AZ4: =MIN(IF($AU4=100%,1,1+VLOOKUP(($AJ4-$AI4-$AH4-$AG4-$AF4-$AE4*(1+AZ$3))/$AJ4,Уголь_коэфф!$A:$B,2,1)-VLOOKUP($AO4,Уголь_коэфф!$A:$B,2,1)),1+(1-$AU4)) -> 1 | BA4: =MIN(IF($AU4=100%,1,1+VLOOKUP(($AJ4-$AI4-$AH4-$AG4-$AF4-$AE4*(1+BA$3))/$AJ4,Уголь_коэфф!$A:$B,2,1)-VLOOKUP($AO4,Уголь_коэфф!$A:$B,2,1)),1+(1-$AU4)) -> 1 | BB4: =MIN(IF($AU4=100%,1,1+VLOOKUP(($AJ4-$AI4-$AH4-$AG4-$AF4-$AE4*(1+BB$3))/$AJ4,Уголь_коэфф!$A:$B,2,1)-VLOOKUP($AO4,Уголь_коэфф!$A:$B,2,1)),1+(1-$AU4)) -> 1 | BC4: =MIN(IF($AU4=100%,1,1+VLOOKUP(($AJ4-$AI4-$AH4-$AG4-$AF4-$AE4*(1+BC$3))/$AJ4,Уголь_коэфф!$A:$B,2,1)-VLOOKUP($AO4,Уголь_коэфф!$A:$B,2,1)),1+(1-$AU4)) -> 1 | BD4: =MIN(IF($AU4=100%,1,1+VLOOKUP(($AJ4-$AI4-$AH4-$AG4-$AF4-$AE4*(1+BD$3))/$AJ4,Уголь_коэфф!$A:$B,2,1)-VLOOKUP($AO4,Уголь_коэфф!$A:$B,2,1)),1+(1-$AU4)) -> 1 | BE4: =MIN(IF($AU4=100%,1,1+VLOOKUP(($AJ4-$AI4-$AH4-$AG4-$AF4-$AE4*(1+BE$3))/$AJ4,Уголь_коэфф!$A:$B,2,1)-VLOOKUP($AO4,Уголь_коэфф!$A:$B,2,1)),1+(1-$AU4)) -> 1 | BF4: =MIN(IF($AU4=100%,1,1+VLOOKUP(($AJ4-$AI4-$AH4-$AG4-$AF4-$AE4*(1+BF$3))/$AJ4,Уголь_коэфф!$A:$B,2,1)-VLOOKUP($AO4,Уголь_коэфф!$A:$B,2,1)),1+(1-$AU4)) -> 1 | BG4: =MIN(IF($AU4=100%,1,1+VLOOKUP(($AJ4-$AI4-$AH4-$AG4-$AF4-$AE4*(1+BG$3))/$AJ4,Уголь_коэфф!$A:$B,2,1)-VLOOKUP($AO4,Уголь_коэфф!$A:$B,2,1)),1+(1-$AU4)) -> 1 | ... EU4: =MIN(IF($AU4=100%,1,1+VLOOKUP(($AJ4-$AI4-$AH4-$AG4-$AF4-$AE4*(1+EU$3))/$AJ4,Уголь_коэфф!$A:$B,2,1)-VLOOKUP($AO4,Уголь_коэфф!$A:$B,2,1)),1+(1-$AU4)) -> 1 | EV4: 1 | EW4: =MIN(1,MAX(VLOOKUP(($AJ4-$AI4-$AH4-$AG4-$AF4-$AE4*(1+EW$3))/$AJ4,Уголь_коэфф!$A:$B,2,1),(EV4-0.05))) -> 1 | EX4: =MIN(1,MAX(VLOOKUP(($AJ4-$AI4-$AH4-$AG4-$AF4-$AE4*(1+EX$3))/$AJ4,Уголь_коэфф!$A:$B,2,1),(EW4-0.05))) -> 1 | EY4: =MIN(1,MAX(VLOOKUP(($AJ4-$AI4-$AH4-$AG4-$AF4-$AE4*(1+EY$3))/$AJ4,Уголь_коэфф!$A:$B,2,1),(EX4-0.05))) -> 1 | EZ4: =MIN(1,MAX(VLOOKUP(($AJ4-$AI4-$AH4-$AG4-$AF4-$AE4*(1+EZ$3))/$AJ4,Уголь_коэфф!$A:$B,2,1),(EY4-0.05))) -> 1 | FA4: =MIN(1,MAX(VLOOKUP(($AJ4-$AI4-$AH4-$AG4-$AF4-$AE4*(1+FA$3))/$AJ4,Уголь_коэфф!$A:$B,2,1),(EZ4-0.05))) -> 1 | FB4: =MIN(1,MAX(VLOOKUP(($AJ4-$AI4-$AH4-$AG4-$AF4-$AE4*(1+FB$3))/$AJ4,Уголь_коэфф!$A:$B,2,1),(FA4-0.05))) -> 1 | FC4: =MIN(1,MAX(VLOOKUP(($AJ4-$AI4-$AH4-$AG4-$AF4-$AE4*(1+FC$3))/$AJ4,Уголь_коэфф!$A:$B,2,1),(FB4-0.05))) -> 1 | FD4: =MIN(1,MAX(VLOOKUP(($AJ4-$AI4-$AH4-$AG4-$AF4-$AE4*(1+FD$3))/$AJ4,Уголь_коэфф!$A:$B,2,1),(FC4-0.05))) -> 1 | ... IR4: =MIN(1,MAX(VLOOKUP(($AJ4-$AI4-$AH4-$AG4-$AF4-$AE4*(1+IR$3))/$AJ4,Уголь_коэфф!$A:$B,2,1),(IQ4-0.05))) -> 1 | IS4: =HLOOKUP($IS$2,$AZ$3:$IR$27,ROW(IR4)-2,FALSE) -> 1 | IT4: =IF($IV$2=1,IF(AND($IT$2="индексация",IS4<1,IS4*$IV$1>1),1,IF(AND($IT$2="индексация",IS4=1),1,IF(AND($IT$2="скидка",IS4=1),1,IS4*$IV$1))),IS4*$IV$1) -> 1
A5: уголь энергетический (кроме антрацита)ЭкспортСеверо-Западное | B5: 1 | C5: Уголь каменный | D5: 16112 | E5: УГОЛЬ Д | F5: уголь энергетический (кроме антрацита) | G5: КРС | H5: ОКТ | I5: ЧЕРНОГ.КОПИ | J5: МУРМАНСК-ЭКС | K5: 5356 | L5: полувагон | M5: Экспорт | N5: неконтейнерная | O5: Северо-Западное | P5: 54657469 | Q5: ООО "КАРБОНПРО" | R5: АО "СУЭК" | S5: 2180783 | T5: 11680408007 | U5: 29661 | W5: 4360383957 | X5: 75 | Y5: маршрутная | Z5: 12 | AA5: 12 | AB5: 4 | AC5: 2152.64 | AD5: 1013.71 | AE5: =AC5+AD5 -> 3166.35 | AF5: ='Цены,перевалка,аренда'!$C$26*SUM(Уголь_эластика_экспорт!Z5+Уголь_эластика_экспорт!AA5+Уголь_эластика_экспорт!AB5)/Уголь_эластика_экспорт!X5 -> 373.33333 | AG5: =SUMIF('Цены,перевалка,аренда'!$A$20:$A$22,Уголь_эластика_экспорт!$O5,'Цены,перевалка,аренда'!$D$20:$D$22) -> 610.444 | AI5: 2020 | AJ5: =SUMIF('Цены,перевалка,аренда'!$A$5:$A$17,Уголь_эластика_экспорт!A5,'Цены,перевалка,аренда'!$D$5:$D$17) -> 6485.9675 | AK5: =AJ5/'Цены,перевалка,аренда'!$C$1 -> 85 | AL5: =AE5+AF5+AG5 -> 4150.1273 | AM5: =AJ5-AL5 -> 2335.8402 | AN5: =AI5+AH5+AG5+AF5+AE5 -> 6170.1273 | AO5: =(AJ5-AN5)/AJ5 -> 0.048695922 | AP5: =AL5/AJ5 -> 0.63986249 | AQ5: =AE5/AJ5 -> 0.48818468 | AR5: =AE5/AL5 -> 0.76295249 | AS5: =IT5 -> 1 | AT5: =S5*AS5 -> 2180783 | AU5: 1 | AV5: =(AJ5-(AE5*(1+$IS$2)+AF5+AG5+AH5+AI5))/AJ5 -> -0.00012254661 | AW5: =(AE5*(1+$IS$2)+AF5+AG5)/AJ5 -> 0.68868096 | AX5: =(AE5*(1+$IS$2))/AJ5 -> 0.53700315 | AY5: =(AE5*(1+$IS$2))/(AE5*(1+$IS$2)+AF5+AG5) -> 0.77975606 | AZ5: =MIN(IF($AU5=100%,1,1+VLOOKUP(($AJ5-$AI5-$AH5-$AG5-$AF5-$AE5*(1+AZ$3))/$AJ5,Уголь_коэфф!$A:$B,2,1)-VLOOKUP($AO5,Уголь_коэфф!$A:$B,2,1)),1+(1-$AU5)) -> 1 | BA5: =MIN(IF($AU5=100%,1,1+VLOOKUP(($AJ5-$AI5-$AH5-$AG5-$AF5-$AE5*(1+BA$3))/$AJ5,Уголь_коэфф!$A:$B,2,1)-VLOOKUP($AO5,Уголь_коэфф!$A:$B,2,1)),1+(1-$AU5)) -> 1 | BB5: =MIN(IF($AU5=100%,1,1+VLOOKUP(($AJ5-$AI5-$AH5-$AG5-$AF5-$AE5*(1+BB$3))/$AJ5,Уголь_коэфф!$A:$B,2,1)-VLOOKUP($AO5,Уголь_коэфф!$A:$B,2,1)),1+(1-$AU5)) -> 1 | BC5: =MIN(IF($AU5=100%,1,1+VLOOKUP(($AJ5-$AI5-$AH5-$AG5-$AF5-$AE5*(1+BC$3))/$AJ5,Уголь_коэфф!$A:$B,2,1)-VLOOKUP($AO5,Уголь_коэфф!$A:$B,2,1)),1+(1-$AU5)) -> 1 | BD5: =MIN(IF($AU5=100%,1,1+VLOOKUP(($AJ5-$AI5-$AH5-$AG5-$AF5-$AE5*(1+BD$3))/$AJ5,Уголь_коэфф!$A:$B,2,1)-VLOOKUP($AO5,Уголь_коэфф!$A:$B,2,1)),1+(1-$AU5)) -> 1 | BE5: =MIN(IF($AU5=100%,1,1+VLOOKUP(($AJ5-$AI5-$AH5-$AG5-$AF5-$AE5*(1+BE$3))/$AJ5,Уголь_коэфф!$A:$B,2,1)-VLOOKUP($AO5,Уголь_коэфф!$A:$B,2,1)),1+(1-$AU5)) -> 1 | BF5: =MIN(IF($AU5=100%,1,1+VLOOKUP(($AJ5-$AI5-$AH5-$AG5-$AF5-$AE5*(1+BF$3))/$AJ5,Уголь_коэфф!$A:$B,2,1)-VLOOKUP($AO5,Уголь_коэфф!$A:$B,2,1)),1+(1-$AU5)) -> 1 | BG5: =MIN(IF($AU5=100%,1,1+VLOOKUP(($AJ5-$AI5-$AH5-$AG5-$AF5-$AE5*(1+BG$3))/$AJ5,Уголь_коэфф!$A:$B,2,1)-VLOOKUP($AO5,Уголь_коэфф!$A:$B,2,1)),1+(1-$AU5)) -> 1 | ... EU5: =MIN(IF($AU5=100%,1,1+VLOOKUP(($AJ5-$AI5-$AH5-$AG5-$AF5-$AE5*(1+EU$3))/$AJ5,Уголь_коэфф!$A:$B,2,1)-VLOOKUP($AO5,Уголь_коэфф!$A:$B,2,1)),1+(1-$AU5)) -> 1 | EV5: 1 | EW5: =MIN(1,MAX(VLOOKUP(($AJ5-$AI5-$AH5-$AG5-$AF5-$AE5*(1+EW$3))/$AJ5,Уголь_коэфф!$A:$B,2,1),(EV5-0.05))) -> 1 | EX5: =MIN(1,MAX(VLOOKUP(($AJ5-$AI5-$AH5-$AG5-$AF5-$AE5*(1+EX$3))/$AJ5,Уголь_коэфф!$A:$B,2,1),(EW5-0.05))) -> 1 | EY5: =MIN(1,MAX(VLOOKUP(($AJ5-$AI5-$AH5-$AG5-$AF5-$AE5*(1+EY$3))/$AJ5,Уголь_коэфф!$A:$B,2,1),(EX5-0.05))) -> 1 | EZ5: =MIN(1,MAX(VLOOKUP(($AJ5-$AI5-$AH5-$AG5-$AF5-$AE5*(1+EZ$3))/$AJ5,Уголь_коэфф!$A:$B,2,1),(EY5-0.05))) -> 1 | FA5: =MIN(1,MAX(VLOOKUP(($AJ5-$AI5-$AH5-$AG5-$AF5-$AE5*(1+FA$3))/$AJ5,Уголь_коэфф!$A:$B,2,1),(EZ5-0.05))) -> 1 | FB5: =MIN(1,MAX(VLOOKUP(($AJ5-$AI5-$AH5-$AG5-$AF5-$AE5*(1+FB$3))/$AJ5,Уголь_коэфф!$A:$B,2,1),(FA5-0.05))) -> 1 | FC5: =MIN(1,MAX(VLOOKUP(($AJ5-$AI5-$AH5-$AG5-$AF5-$AE5*(1+FC$3))/$AJ5,Уголь_коэфф!$A:$B,2,1),(FB5-0.05))) -> 1 | FD5: =MIN(1,MAX(VLOOKUP(($AJ5-$AI5-$AH5-$AG5-$AF5-$AE5*(1+FD$3))/$AJ5,Уголь_коэфф!$A:$B,2,1),(FC5-0.05))) -> 1 | ... IR5: =MIN(1,MAX(VLOOKUP(($AJ5-$AI5-$AH5-$AG5-$AF5-$AE5*(1+IR$3))/$AJ5,Уголь_коэфф!$A:$B,2,1),(IQ5-0.05))) -> 0.908 | IS5: =HLOOKUP($IS$2,$AZ$3:$IR$27,ROW(IR5)-2,FALSE) -> 1 | IT5: =IF($IV$2=1,IF(AND($IT$2="индексация",IS5<1,IS5*$IV$1>1),1,IF(AND($IT$2="индексация",IS5=1),1,IF(AND($IT$2="скидка",IS5=1),1,IS5*$IV$1))),IS5*$IV$1) -> 1
A6: уголь энергетический (кроме антрацита)ЭкспортЮжное | B6: 1 | C6: Уголь каменный | D6: 16112 | E6: УГОЛЬ Д | F6: уголь энергетический (кроме антрацита) | G6: КРС | H6: СКВ | I6: ЧЕРНОГ.КОПИ | J6: АЗОВ-ЭКСПОРТ | K6: 4832 | L6: полувагон | M6: Экспорт | N6: неконтейнерная | O6: Южное | P6: 54657469 | Q6: ООО "КАРБОНПРО" | R6: АО "СУЭК" | S6: 399916 | T6: 1932276609 | U6: 5484 | W6: 750324310 | X6: 75 | Y6: маршрутная | Z6: 11 | AA6: 11 | AB6: 4 | AC6: 1990.61 | AD6: 928.22 | AE6: =AC6+AD6 -> 2918.83 | AF6: ='Цены,перевалка,аренда'!$C$26*SUM(Уголь_эластика_экспорт!Z6+Уголь_эластика_экспорт!AA6+Уголь_эластика_экспорт!AB6)/Уголь_эластика_экспорт!X6 -> 346.66667 | AG6: =SUMIF('Цены,перевалка,аренда'!$A$20:$A$22,Уголь_эластика_экспорт!$O6,'Цены,перевалка,аренда'!$D$20:$D$22) -> 991.9715 | AI6: 2020 | AJ6: =SUMIF('Цены,перевалка,аренда'!$A$5:$A$17,Уголь_эластика_экспорт!A6,'Цены,перевалка,аренда'!$D$5:$D$17) -> 7249.0225 | AK6: =AJ6/'Цены,перевалка,аренда'!$C$1 -> 95 | AL6: =AE6+AF6+AG6 -> 4257.4682 | AM6: =AJ6-AL6 -> 2991.5543 | AN6: =AI6+AH6+AG6+AF6+AE6 -> 6277.4682 | AO6: =(AJ6-AN6)/AJ6 -> 0.13402556 | AP6: =AL6/AJ6 -> 0.58731617 | AQ6: =AE6/AJ6 -> 0.40265153 | AR6: =AE6/AL6 -> 0.68557882 | AS6: =IT6 -> 1 | AT6: =S6*AS6 -> 399916 | AU6: 1 | AV6: =(AJ6-(AE6*(1+$IS$2)+AF6+AG6+AH6+AI6))/AJ6 -> 0.093760412 | AW6: =(AE6*(1+$IS$2)+AF6+AG6)/AJ6 -> 0.62758133 | AX6: =(AE6*(1+$IS$2))/AJ6 -> 0.44291668 | AY6: =(AE6*(1+$IS$2))/(AE6*(1+$IS$2)+AF6+AG6) -> 0.70575185 | AZ6: =MIN(IF($AU6=100%,1,1+VLOOKUP(($AJ6-$AI6-$AH6-$AG6-$AF6-$AE6*(1+AZ$3))/$AJ6,Уголь_коэфф!$A:$B,2,1)-VLOOKUP($AO6,Уголь_коэфф!$A:$B,2,1)),1+(1-$AU6)) -> 1 | BA6: =MIN(IF($AU6=100%,1,1+VLOOKUP(($AJ6-$AI6-$AH6-$AG6-$AF6-$AE6*(1+BA$3))/$AJ6,Уголь_коэфф!$A:$B,2,1)-VLOOKUP($AO6,Уголь_коэфф!$A:$B,2,1)),1+(1-$AU6)) -> 1 | BB6: =MIN(IF($AU6=100%,1,1+VLOOKUP(($AJ6-$AI6-$AH6-$AG6-$AF6-$AE6*(1+BB$3))/$AJ6,Уголь_коэфф!$A:$B,2,1)-VLOOKUP($AO6,Уголь_коэфф!$A:$B,2,1)),1+(1-$AU6)) -> 1 | BC6: =MIN(IF($AU6=100%,1,1+VLOOKUP(($AJ6-$AI6-$AH6-$AG6-$AF6-$AE6*(1+BC$3))/$AJ6,Уголь_коэфф!$A:$B,2,1)-VLOOKUP($AO6,Уголь_коэфф!$A:$B,2,1)),1+(1-$AU6)) -> 1 | BD6: =MIN(IF($AU6=100%,1,1+VLOOKUP(($AJ6-$AI6-$AH6-$AG6-$AF6-$AE6*(1+BD$3))/$AJ6,Уголь_коэфф!$A:$B,2,1)-VLOOKUP($AO6,Уголь_коэфф!$A:$B,2,1)),1+(1-$AU6)) -> 1 | BE6: =MIN(IF($AU6=100%,1,1+VLOOKUP(($AJ6-$AI6-$AH6-$AG6-$AF6-$AE6*(1+BE$3))/$AJ6,Уголь_коэфф!$A:$B,2,1)-VLOOKUP($AO6,Уголь_коэфф!$A:$B,2,1)),1+(1-$AU6)) -> 1 | BF6: =MIN(IF($AU6=100%,1,1+VLOOKUP(($AJ6-$AI6-$AH6-$AG6-$AF6-$AE6*(1+BF$3))/$AJ6,Уголь_коэфф!$A:$B,2,1)-VLOOKUP($AO6,Уголь_коэфф!$A:$B,2,1)),1+(1-$AU6)) -> 1 | BG6: =MIN(IF($AU6=100%,1,1+VLOOKUP(($AJ6-$AI6-$AH6-$AG6-$AF6-$AE6*(1+BG$3))/$AJ6,Уголь_коэфф!$A:$B,2,1)-VLOOKUP($AO6,Уголь_коэфф!$A:$B,2,1)),1+(1-$AU6)) -> 1 | ... EU6: =MIN(IF($AU6=100%,1,1+VLOOKUP(($AJ6-$AI6-$AH6-$AG6-$AF6-$AE6*(1+EU$3))/$AJ6,Уголь_коэфф!$A:$B,2,1)-VLOOKUP($AO6,Уголь_коэфф!$A:$B,2,1)),1+(1-$AU6)) -> 1 | EV6: 1 | EW6: =MIN(1,MAX(VLOOKUP(($AJ6-$AI6-$AH6-$AG6-$AF6-$AE6*(1+EW$3))/$AJ6,Уголь_коэфф!$A:$B,2,1),(EV6-0.05))) -> 1 | EX6: =MIN(1,MAX(VLOOKUP(($AJ6-$AI6-$AH6-$AG6-$AF6-$AE6*(1+EX$3))/$AJ6,Уголь_коэфф!$A:$B,2,1),(EW6-0.05))) -> 1 | EY6: =MIN(1,MAX(VLOOKUP(($AJ6-$AI6-$AH6-$AG6-$AF6-$AE6*(1+EY$3))/$AJ6,Уголь_коэфф!$A:$B,2,1),(EX6-0.05))) -> 1 | EZ6: =MIN(1,MAX(VLOOKUP(($AJ6-$AI6-$AH6-$AG6-$AF6-$AE6*(1+EZ$3))/$AJ6,Уголь_коэфф!$A:$B,2,1),(EY6-0.05))) -> 1 | FA6: =MIN(1,MAX(VLOOKUP(($AJ6-$AI6-$AH6-$AG6-$AF6-$AE6*(1+FA$3))/$AJ6,Уголь_коэфф!$A:$B,2,1),(EZ6-0.05))) -> 1 | FB6: =MIN(1,MAX(VLOOKUP(($AJ6-$AI6-$AH6-$AG6-$AF6-$AE6*(1+FB$3))/$AJ6,Уголь_коэфф!$A:$B,2,1),(FA6-0.05))) -> 1 | FC6: =MIN(1,MAX(VLOOKUP(($AJ6-$AI6-$AH6-$AG6-$AF6-$AE6*(1+FC$3))/$AJ6,Уголь_коэфф!$A:$B,2,1),(FB6-0.05))) -> 1 | FD6: =MIN(1,MAX(VLOOKUP(($AJ6-$AI6-$AH6-$AG6-$AF6-$AE6*(1+FD$3))/$AJ6,Уголь_коэфф!$A:$B,2,1),(FC6-0.05))) -> 1 | ... IR6: =MIN(1,MAX(VLOOKUP(($AJ6-$AI6-$AH6-$AG6-$AF6-$AE6*(1+IR$3))/$AJ6,Уголь_коэфф!$A:$B,2,1),(IQ6-0.05))) -> 0.975 | IS6: =HLOOKUP($IS$2,$AZ$3:$IR$27,ROW(IR6)-2,FALSE) -> 1 | IT6: =IF($IV$2=1,IF(AND($IT$2="индексация",IS6<1,IS6*$IV$1>1),1,IF(AND($IT$2="индексация",IS6=1),1,IF(AND($IT$2="скидка",IS6=1),1,IS6*$IV$1))),IS6*$IV$1) -> 1
A7: уголь энергетический (кроме антрацита)ЭкспортВосточное | B7: 1 | C7: Уголь каменный | D7: 16112 | E7: УГОЛЬ Д | F7: уголь энергетический (кроме антрацита) | G7: КРС | H7: ИФР | I7: КАМЫШТА | J7: МИХ-СЕМ-Э | K7: 4678 | L7: полувагон | M7: Экспорт | N7: неконтейнерная | O7: Восточное | P7: 1869326 | Q7: ООО "УГОЛЬ ПЛЮС" | R7: АО "Русский уголь" | S7: 200545 | T7: 938250119 | U7: 2877 | W7: 485116824 | X7: 69 | Y7: маршрутная | Z7: 14 | AA7: 14 | AB7: 4 | AC7: 2198.94 | AD7: 1008.93 | AE7: =AC7+AD7 -> 3207.87 | AF7: ='Цены,перевалка,аренда'!$C$27*SUM(Уголь_эластика_экспорт!Z7+Уголь_эластика_экспорт!AA7+Уголь_эластика_экспорт!AB7)/Уголь_эластика_экспорт!X7 -> 324.63768 | AI7: 586 | AJ7: =SUMIF('Цены,перевалка,аренда'!$A$5:$A$17,Уголь_эластика_экспорт!A7,'Цены,перевалка,аренда'!$D$5:$D$17) -> 8546.216 | AK7: =AJ7/'Цены,перевалка,аренда'!$C$1 -> 112 | AL7: =AE7+AF7+AG7 -> 3532.5077 | AM7: =AJ7-AL7 -> 5013.7083 | AN7: =AI7+AH7+AG7+AF7+AE7 -> 4118.5077 | AO7: =(AJ7-AN7)/AJ7 -> 0.51808991 | AP7: =AL7/AJ7 -> 0.41334173 | AQ7: =AE7/AJ7 -> 0.3753556 | AR7: =AE7/AL7 -> 0.90809994 | AS7: =IT7 -> 1 | AT7: =S7*AS7 -> 200545 | AU7: 1 | AV7: =(AJ7-(AE7*(1+$IS$2)+AF7+AG7+AH7+AI7))/AJ7 -> 0.48055436 | AW7: =(AE7*(1+$IS$2)+AF7+AG7)/AJ7 -> 0.45087729 | AX7: =(AE7*(1+$IS$2))/AJ7 -> 0.41289116 | AY7: =(AE7*(1+$IS$2))/(AE7*(1+$IS$2)+AF7+AG7) -> 0.91575062 | AZ7: =MIN(IF($AU7=100%,1,1+VLOOKUP(($AJ7-$AI7-$AH7-$AG7-$AF7-$AE7*(1+AZ$3))/$AJ7,Уголь_коэфф!$A:$B,2,1)-VLOOKUP($AO7,Уголь_коэфф!$A:$B,2,1)),1+(1-$AU7)) -> 1 | BA7: =MIN(IF($AU7=100%,1,1+VLOOKUP(($AJ7-$AI7-$AH7-$AG7-$AF7-$AE7*(1+BA$3))/$AJ7,Уголь_коэфф!$A:$B,2,1)-VLOOKUP($AO7,Уголь_коэфф!$A:$B,2,1)),1+(1-$AU7)) -> 1 | BB7: =MIN(IF($AU7=100%,1,1+VLOOKUP(($AJ7-$AI7-$AH7-$AG7-$AF7-$AE7*(1+BB$3))/$AJ7,Уголь_коэфф!$A:$B,2,1)-VLOOKUP($AO7,Уголь_коэфф!$A:$B,2,1)),1+(1-$AU7)) -> 1 | BC7: =MIN(IF($AU7=100%,1,1+VLOOKUP(($AJ7-$AI7-$AH7-$AG7-$AF7-$AE7*(1+BC$3))/$AJ7,Уголь_коэфф!$A:$B,2,1)-VLOOKUP($AO7,Уголь_коэфф!$A:$B,2,1)),1+(1-$AU7)) -> 1 | BD7: =MIN(IF($AU7=100%,1,1+VLOOKUP(($AJ7-$AI7-$AH7-$AG7-$AF7-$AE7*(1+BD$3))/$AJ7,Уголь_коэфф!$A:$B,2,1)-VLOOKUP($AO7,Уголь_коэфф!$A:$B,2,1)),1+(1-$AU7)) -> 1 | BE7: =MIN(IF($AU7=100%,1,1+VLOOKUP(($AJ7-$AI7-$AH7-$AG7-$AF7-$AE7*(1+BE$3))/$AJ7,Уголь_коэфф!$A:$B,2,1)-VLOOKUP($AO7,Уголь_коэфф!$A:$B,2,1)),1+(1-$AU7)) -> 1 | BF7: =MIN(IF($AU7=100%,1,1+VLOOKUP(($AJ7-$AI7-$AH7-$AG7-$AF7-$AE7*(1+BF$3))/$AJ7,Уголь_коэфф!$A:$B,2,1)-VLOOKUP($AO7,Уголь_коэфф!$A:$B,2,1)),1+(1-$AU7)) -> 1 | BG7: =MIN(IF($AU7=100%,1,1+VLOOKUP(($AJ7-$AI7-$AH7-$AG7-$AF7-$AE7*(1+BG$3))/$AJ7,Уголь_коэфф!$A:$B,2,1)-VLOOKUP($AO7,Уголь_коэфф!$A:$B,2,1)),1+(1-$AU7)) -> 1 | ... EU7: =MIN(IF($AU7=100%,1,1+VLOOKUP(($AJ7-$AI7-$AH7-$AG7-$AF7-$AE7*(1+EU$3))/$AJ7,Уголь_коэфф!$A:$B,2,1)-VLOOKUP($AO7,Уголь_коэфф!$A:$B,2,1)),1+(1-$AU7)) -> 1 | EV7: 1 | EW7: =MIN(1,MAX(VLOOKUP(($AJ7-$AI7-$AH7-$AG7-$AF7-$AE7*(1+EW$3))/$AJ7,Уголь_коэфф!$A:$B,2,1),(EV7-0.05))) -> 1 | EX7: =MIN(1,MAX(VLOOKUP(($AJ7-$AI7-$AH7-$AG7-$AF7-$AE7*(1+EX$3))/$AJ7,Уголь_коэфф!$A:$B,2,1),(EW7-0.05))) -> 1 | EY7: =MIN(1,MAX(VLOOKUP(($AJ7-$AI7-$AH7-$AG7-$AF7-$AE7*(1+EY$3))/$AJ7,Уголь_коэфф!$A:$B,2,1),(EX7-0.05))) -> 1 | EZ7: =MIN(1,MAX(VLOOKUP(($AJ7-$AI7-$AH7-$AG7-$AF7-$AE7*(1+EZ$3))/$AJ7,Уголь_коэфф!$A:$B,2,1),(EY7-0.05))) -> 1 | FA7: =MIN(1,MAX(VLOOKUP(($AJ7-$AI7-$AH7-$AG7-$AF7-$AE7*(1+FA$3))/$AJ7,Уголь_коэфф!$A:$B,2,1),(EZ7-0.05))) -> 1 | FB7: =MIN(1,MAX(VLOOKUP(($AJ7-$AI7-$AH7-$AG7-$AF7-$AE7*(1+FB$3))/$AJ7,Уголь_коэфф!$A:$B,2,1),(FA7-0.05))) -> 1 | FC7: =MIN(1,MAX(VLOOKUP(($AJ7-$AI7-$AH7-$AG7-$AF7-$AE7*(1+FC$3))/$AJ7,Уголь_коэфф!$A:$B,2,1),(FB7-0.05))) -> 1 | FD7: =MIN(1,MAX(VLOOKUP(($AJ7-$AI7-$AH7-$AG7-$AF7-$AE7*(1+FD$3))/$AJ7,Уголь_коэфф!$A:$B,2,1),(FC7-0.05))) -> 1 | ... IR7: =MIN(1,MAX(VLOOKUP(($AJ7-$AI7-$AH7-$AG7-$AF7-$AE7*(1+IR$3))/$AJ7,Уголь_коэфф!$A:$B,2,1),(IQ7-0.05))) -> 1 | IS7: =HLOOKUP($IS$2,$AZ$3:$IR$27,ROW(IR7)-2,FALSE) -> 1 | IT7: =IF($IV$2=1,IF(AND($IT$2="индексация",IS7<1,IS7*$IV$1>1),1,IF(AND($IT$2="индексация",IS7=1),1,IF(AND($IT$2="скидка",IS7=1),1,IS7*$IV$1))),IS7*$IV$1) -> 1
A8: уголь энергетический (кроме антрацита)ЭкспортСеверо-Западное | B8: 1 | C8: Уголь каменный | D8: 16111 | E8: УГОЛЬ Г | F8: уголь энергетический (кроме антрацита) | G8: КРС | H8: ОКТ | I8: КРАВЧЕНКО | J8: ЛУЖСКАЯ-ЭКСП | K8: 4972 | L8: полувагон | M8: Экспорт | N8: неконтейнерная | O8: Северо-Западное | P8: 78465421 | Q8: АО "РУССКИЙ УГОЛЬ" | R8: АО "Русский уголь" | S8: 55119 | T8: 274033646 | U8: 786 | W8: 109968398 | X8: 69 | Y8: маршрутная | Z8: 12 | AA8: 12 | AB8: 4 | AC8: 2243.1 | AD8: 1024.44 | AE8: =AC8+AD8 -> 3267.54 | AF8: ='Цены,перевалка,аренда'!$C$27*SUM(Уголь_эластика_экспорт!Z8+Уголь_эластика_экспорт!AA8+Уголь_эластика_экспорт!AB8)/Уголь_эластика_экспорт!X8 -> 284.05797 | AG8: =SUMIF('Цены,перевалка,аренда'!$A$20:$A$22,Уголь_эластика_экспорт!$O8,'Цены,перевалка,аренда'!$D$20:$D$22) -> 610.444 | AI8: 586 | AJ8: =SUMIF('Цены,перевалка,аренда'!$A$5:$A$17,Уголь_эластика_экспорт!A8,'Цены,перевалка,аренда'!$D$5:$D$17) -> 6485.9675 | AK8: =AJ8/'Цены,перевалка,аренда'!$C$1 -> 85 | AL8: =AE8+AF8+AG8 -> 4162.042 | AM8: =AJ8-AL8 -> 2323.9255 | AN8: =AI8+AH8+AG8+AF8+AE8 -> 4748.042 | AO8: =(AJ8-AN8)/AJ8 -> 0.26795162 | AP8: =AL8/AJ8 -> 0.64169948 | AQ8: =AE8/AJ8 -> 0.50378606 | AR8: =AE8/AL8 -> 0.78508098 | AS8: =IT8 -> 1 | AT8: =S8*AS8 -> 55119 | AU8: 1 | AV8: =(AJ8-(AE8*(1+$IS$2)+AF8+AG8+AH8+AI8))/AJ8 -> 0.21757302 | AW8: =(AE8*(1+$IS$2)+AF8+AG8)/AJ8 -> 0.69207809 | AX8: =(AE8*(1+$IS$2))/AJ8 -> 0.55416466 | AY8: =(AE8*(1+$IS$2))/(AE8*(1+$IS$2)+AF8+AG8) -> 0.80072563 | AZ8: =MIN(IF($AU8=100%,1,1+VLOOKUP(($AJ8-$AI8-$AH8-$AG8-$AF8-$AE8*(1+AZ$3))/$AJ8,Уголь_коэфф!$A:$B,2,1)-VLOOKUP($AO8,Уголь_коэфф!$A:$B,2,1)),1+(1-$AU8)) -> 1 | BA8: =MIN(IF($AU8=100%,1,1+VLOOKUP(($AJ8-$AI8-$AH8-$AG8-$AF8-$AE8*(1+BA$3))/$AJ8,Уголь_коэфф!$A:$B,2,1)-VLOOKUP($AO8,Уголь_коэфф!$A:$B,2,1)),1+(1-$AU8)) -> 1 | BB8: =MIN(IF($AU8=100%,1,1+VLOOKUP(($AJ8-$AI8-$AH8-$AG8-$AF8-$AE8*(1+BB$3))/$AJ8,Уголь_коэфф!$A:$B,2,1)-VLOOKUP($AO8,Уголь_коэфф!$A:$B,2,1)),1+(1-$AU8)) -> 1 | BC8: =MIN(IF($AU8=100%,1,1+VLOOKUP(($AJ8-$AI8-$AH8-$AG8-$AF8-$AE8*(1+BC$3))/$AJ8,Уголь_коэфф!$A:$B,2,1)-VLOOKUP($AO8,Уголь_коэфф!$A:$B,2,1)),1+(1-$AU8)) -> 1 | BD8: =MIN(IF($AU8=100%,1,1+VLOOKUP(($AJ8-$AI8-$AH8-$AG8-$AF8-$AE8*(1+BD$3))/$AJ8,Уголь_коэфф!$A:$B,2,1)-VLOOKUP($AO8,Уголь_коэфф!$A:$B,2,1)),1+(1-$AU8)) -> 1 | BE8: =MIN(IF($AU8=100%,1,1+VLOOKUP(($AJ8-$AI8-$AH8-$AG8-$AF8-$AE8*(1+BE$3))/$AJ8,Уголь_коэфф!$A:$B,2,1)-VLOOKUP($AO8,Уголь_коэфф!$A:$B,2,1)),1+(1-$AU8)) -> 1 | BF8: =MIN(IF($AU8=100%,1,1+VLOOKUP(($AJ8-$AI8-$AH8-$AG8-$AF8-$AE8*(1+BF$3))/$AJ8,Уголь_коэфф!$A:$B,2,1)-VLOOKUP($AO8,Уголь_коэфф!$A:$B,2,1)),1+(1-$AU8)) -> 1 | BG8: =MIN(IF($AU8=100%,1,1+VLOOKUP(($AJ8-$AI8-$AH8-$AG8-$AF8-$AE8*(1+BG$3))/$AJ8,Уголь_коэфф!$A:$B,2,1)-VLOOKUP($AO8,Уголь_коэфф!$A:$B,2,1)),1+(1-$AU8)) -> 1 | ... EU8: =MIN(IF($AU8=100%,1,1+VLOOKUP(($AJ8-$AI8-$AH8-$AG8-$AF8-$AE8*(1+EU$3))/$AJ8,Уголь_коэфф!$A:$B,2,1)-VLOOKUP($AO8,Уголь_коэфф!$A:$B,2,1)),1+(1-$AU8)) -> 1 | EV8: 1 | EW8: =MIN(1,MAX(VLOOKUP(($AJ8-$AI8-$AH8-$AG8-$AF8-$AE8*(1+EW$3))/$AJ8,Уголь_коэфф!$A:$B,2,1),(EV8-0.05))) -> 1 | EX8: =MIN(1,MAX(VLOOKUP(($AJ8-$AI8-$AH8-$AG8-$AF8-$AE8*(1+EX$3))/$AJ8,Уголь_коэфф!$A:$B,2,1),(EW8-0.05))) -> 1 | EY8: =MIN(1,MAX(VLOOKUP(($AJ8-$AI8-$AH8-$AG8-$AF8-$AE8*(1+EY$3))/$AJ8,Уголь_коэфф!$A:$B,2,1),(EX8-0.05))) -> 1 | EZ8: =MIN(1,MAX(VLOOKUP(($AJ8-$AI8-$AH8-$AG8-$AF8-$AE8*(1+EZ$3))/$AJ8,Уголь_коэфф!$A:$B,2,1),(EY8-0.05))) -> 1 | FA8: =MIN(1,MAX(VLOOKUP(($AJ8-$AI8-$AH8-$AG8-$AF8-$AE8*(1+FA$3))/$AJ8,Уголь_коэфф!$A:$B,2,1),(EZ8-0.05))) -> 1 | FB8: =MIN(1,MAX(VLOOKUP(($AJ8-$AI8-$AH8-$AG8-$AF8-$AE8*(1+FB$3))/$AJ8,Уголь_коэфф!$A:$B,2,1),(FA8-0.05))) -> 1 | FC8: =MIN(1,MAX(VLOOKUP(($AJ8-$AI8-$AH8-$AG8-$AF8-$AE8*(1+FC$3))/$AJ8,Уголь_коэфф!$A:$B,2,1),(FB8-0.05))) -> 1 | FD8: =MIN(1,MAX(VLOOKUP(($AJ8-$AI8-$AH8-$AG8-$AF8-$AE8*(1+FD$3))/$AJ8,Уголь_коэфф!$A:$B,2,1),(FC8-0.05))) -> 1 | ... IR8: =MIN(1,MAX(VLOOKUP(($AJ8-$AI8-$AH8-$AG8-$AF8-$AE8*(1+IR$3))/$AJ8,Уголь_коэфф!$A:$B,2,1),(IQ8-0.05))) -> 1 | IS8: =HLOOKUP($IS$2,$AZ$3:$IR$27,ROW(IR8)-2,FALSE) -> 1 | IT8: =IF($IV$2=1,IF(AND($IT$2="индексация",IS8<1,IS8*$IV$1>1),1,IF(AND($IT$2="индексация",IS8=1),1,IF(AND($IT$2="скидка",IS8=1),1,IS8*$IV$1))),IS8*$IV$1) -> 1
A9: уголь энергетический (кроме антрацита)ЭкспортЮжное | B9: 1 | C9: Уголь каменный | D9: 16111 | E9: УГОЛЬ Г | F9: уголь энергетический (кроме антрацита) | G9: КРС | H9: СКВ | I9: КРАВЧЕНКО | J9: ВЫШСТБЛ-ЭКС | K9: 5362 | L9: полувагон | M9: Экспорт | N9: неконтейнерная | O9: Южное | P9: 78465421 | Q9: АО "РУССКИЙ УГОЛЬ" | R9: АО "Русский уголь" | S9: 744502 | T9: 3991785157 | U9: 10404 | W9: 1516719886 | X9: 69 | Y9: маршрутная | Z9: 12 | AA9: 12 | AB9: 4 | AC9: 2334.86 | AD9: 1086.34 | AE9: =AC9+AD9 -> 3421.2 | AF9: ='Цены,перевалка,аренда'!$C$27*SUM(Уголь_эластика_экспорт!Z9+Уголь_эластика_экспорт!AA9+Уголь_эластика_экспорт!AB9)/Уголь_эластика_экспорт!X9 -> 284.05797 | AG9: =SUMIF('Цены,перевалка,аренда'!$A$20:$A$22,Уголь_эластика_экспорт!$O9,'Цены,перевалка,аренда'!$D$20:$D$22) -> 991.9715 | AI9: 586 | AJ9: =SUMIF('Цены,перевалка,аренда'!$A$5:$A$17,Уголь_эластика_экспорт!A9,'Цены,перевалка,аренда'!$D$5:$D$17) -> 7249.0225 | AK9: =AJ9/'Цены,перевалка,аренда'!$C$1 -> 95 | AL9: =AE9+AF9+AG9 -> 4697.2295 | AM9: =AJ9-AL9 -> 2551.793 | AN9: =AI9+AH9+AG9+AF9+AE9 -> 5283.2295 | AO9: =(AJ9-AN9)/AJ9 -> 0.27118043 | AP9: =AL9/AJ9 -> 0.64798109 | AQ9: =AE9/AJ9 -> 0.47195329 | AR9: =AE9/AL9 -> 0.72834423 | AS9: =IT9 -> 1 | AT9: =S9*AS9 -> 744502 | AU9: 1 | AV9: =(AJ9-(AE9*(1+$IS$2)+AF9+AG9+AH9+AI9))/AJ9 -> 0.2239851 | AW9: =(AE9*(1+$IS$2)+AF9+AG9)/AJ9 -> 0.69517641 | AX9: =(AE9*(1+$IS$2))/AJ9 -> 0.51914862 | AY9: =(AE9*(1+$IS$2))/(AE9*(1+$IS$2)+AF9+AG9) -> 0.74678687 | AZ9: =MIN(IF($AU9=100%,1,1+VLOOKUP(($AJ9-$AI9-$AH9-$AG9-$AF9-$AE9*(1+AZ$3))/$AJ9,Уголь_коэфф!$A:$B,2,1)-VLOOKUP($AO9,Уголь_коэфф!$A:$B,2,1)),1+(1-$AU9)) -> 1 | BA9: =MIN(IF($AU9=100%,1,1+VLOOKUP(($AJ9-$AI9-$AH9-$AG9-$AF9-$AE9*(1+BA$3))/$AJ9,Уголь_коэфф!$A:$B,2,1)-VLOOKUP($AO9,Уголь_коэфф!$A:$B,2,1)),1+(1-$AU9)) -> 1 | BB9: =MIN(IF($AU9=100%,1,1+VLOOKUP(($AJ9-$AI9-$AH9-$AG9-$AF9-$AE9*(1+BB$3))/$AJ9,Уголь_коэфф!$A:$B,2,1)-VLOOKUP($AO9,Уголь_коэфф!$A:$B,2,1)),1+(1-$AU9)) -> 1 | BC9: =MIN(IF($AU9=100%,1,1+VLOOKUP(($AJ9-$AI9-$AH9-$AG9-$AF9-$AE9*(1+BC$3))/$AJ9,Уголь_коэфф!$A:$B,2,1)-VLOOKUP($AO9,Уголь_коэфф!$A:$B,2,1)),1+(1-$AU9)) -> 1 | BD9: =MIN(IF($AU9=100%,1,1+VLOOKUP(($AJ9-$AI9-$AH9-$AG9-$AF9-$AE9*(1+BD$3))/$AJ9,Уголь_коэфф!$A:$B,2,1)-VLOOKUP($AO9,Уголь_коэфф!$A:$B,2,1)),1+(1-$AU9)) -> 1 | BE9: =MIN(IF($AU9=100%,1,1+VLOOKUP(($AJ9-$AI9-$AH9-$AG9-$AF9-$AE9*(1+BE$3))/$AJ9,Уголь_коэфф!$A:$B,2,1)-VLOOKUP($AO9,Уголь_коэфф!$A:$B,2,1)),1+(1-$AU9)) -> 1 | BF9: =MIN(IF($AU9=100%,1,1+VLOOKUP(($AJ9-$AI9-$AH9-$AG9-$AF9-$AE9*(1+BF$3))/$AJ9,Уголь_коэфф!$A:$B,2,1)-VLOOKUP($AO9,Уголь_коэфф!$A:$B,2,1)),1+(1-$AU9)) -> 1 | BG9: =MIN(IF($AU9=100%,1,1+VLOOKUP(($AJ9-$AI9-$AH9-$AG9-$AF9-$AE9*(1+BG$3))/$AJ9,Уголь_коэфф!$A:$B,2,1)-VLOOKUP($AO9,Уголь_коэфф!$A:$B,2,1)),1+(1-$AU9)) -> 1 | ... EU9: =MIN(IF($AU9=100%,1,1+VLOOKUP(($AJ9-$AI9-$AH9-$AG9-$AF9-$AE9*(1+EU$3))/$AJ9,Уголь_коэфф!$A:$B,2,1)-VLOOKUP($AO9,Уголь_коэфф!$A:$B,2,1)),1+(1-$AU9)) -> 1 | EV9: 1 | EW9: =MIN(1,MAX(VLOOKUP(($AJ9-$AI9-$AH9-$AG9-$AF9-$AE9*(1+EW$3))/$AJ9,Уголь_коэфф!$A:$B,2,1),(EV9-0.05))) -> 1 | EX9: =MIN(1,MAX(VLOOKUP(($AJ9-$AI9-$AH9-$AG9-$AF9-$AE9*(1+EX$3))/$AJ9,Уголь_коэфф!$A:$B,2,1),(EW9-0.05))) -> 1 | EY9: =MIN(1,MAX(VLOOKUP(($AJ9-$AI9-$AH9-$AG9-$AF9-$AE9*(1+EY$3))/$AJ9,Уголь_коэфф!$A:$B,2,1),(EX9-0.05))) -> 1 | EZ9: =MIN(1,MAX(VLOOKUP(($AJ9-$AI9-$AH9-$AG9-$AF9-$AE9*(1+EZ$3))/$AJ9,Уголь_коэфф!$A:$B,2,1),(EY9-0.05))) -> 1 | FA9: =MIN(1,MAX(VLOOKUP(($AJ9-$AI9-$AH9-$AG9-$AF9-$AE9*(1+FA$3))/$AJ9,Уголь_коэфф!$A:$B,2,1),(EZ9-0.05))) -> 1 | FB9: =MIN(1,MAX(VLOOKUP(($AJ9-$AI9-$AH9-$AG9-$AF9-$AE9*(1+FB$3))/$AJ9,Уголь_коэфф!$A:$B,2,1),(FA9-0.05))) -> 1 | FC9: =MIN(1,MAX(VLOOKUP(($AJ9-$AI9-$AH9-$AG9-$AF9-$AE9*(1+FC$3))/$AJ9,Уголь_коэфф!$A:$B,2,1),(FB9-0.05))) -> 1 | FD9: =MIN(1,MAX(VLOOKUP(($AJ9-$AI9-$AH9-$AG9-$AF9-$AE9*(1+FD$3))/$AJ9,Уголь_коэфф!$A:$B,2,1),(FC9-0.05))) -> 1 | ... IR9: =MIN(1,MAX(VLOOKUP(($AJ9-$AI9-$AH9-$AG9-$AF9-$AE9*(1+IR$3))/$AJ9,Уголь_коэфф!$A:$B,2,1),(IQ9-0.05))) -> 1 | IS9: =HLOOKUP($IS$2,$AZ$3:$IR$27,ROW(IR9)-2,FALSE) -> 1 | IT9: =IF($IV$2=1,IF(AND($IT$2="индексация",IS9<1,IS9*$IV$1>1),1,IF(AND($IT$2="индексация",IS9=1),1,IF(AND($IT$2="скидка",IS9=1),1,IS9*$IV$1))),IS9*$IV$1) -> 1
A10: уголь энергетический (кроме антрацита)ЭкспортВосточное | B10: 1 | C10: Уголь каменный | D10: 16118 | E10: УГОЛЬ Т | F10: уголь энергетический (кроме антрацита) | G10: ЗСБ | H10: ДВС | I10: САРБАЛА | J10: НАХОДКА-В-ЭК | K10: 5976 | L10: полувагон | M10: Экспорт | N10: неконтейнерная | O10: Восточное | P10: 82365518 | Q10: АО "АТРИУМ" | R10: ООО "УГМК-Холдинг" | S10: 1782028 | T10: 10648684516 | U10: 23883 | W10: 3937998980 | X10: 75 | Y10: маршрутная | Z10: 13 | AA10: 14 | AB10: 4 | AC10: 2442.47 | AD10: 1120.57 | AE10: =AC10+AD10 -> 3563.04 | AF10: ='Цены,перевалка,аренда'!$C$26*SUM(Уголь_эластика_экспорт!Z10+Уголь_эластика_экспорт!AA10+Уголь_эластика_экспорт!AB10)/Уголь_эластика_экспорт!X10 -> 413.33333 | AG10: =SUMIF('Цены,перевалка,аренда'!$A$20:$A$22,Уголь_эластика_экспорт!$O10,'Цены,перевалка,аренда'!$D$20:$D$22) -> 763.055 | AI10: 2736 | AJ10: =SUMIF('Цены,перевалка,аренда'!$A$5:$A$17,Уголь_эластика_экспорт!A10,'Цены,перевалка,аренда'!$D$5:$D$17) -> 8546.216 | AK10: =AJ10/'Цены,перевалка,аренда'!$C$1 -> 112 | AL10: =AE10+AF10+AG10 -> 4739.4283 | AM10: =AJ10-AL10 -> 3806.7877 | AN10: =AI10+AH10+AG10+AF10+AE10 -> 7475.4283 | AO10: =(AJ10-AN10)/AJ10 -> 0.12529378 | AP10: =AL10/AJ10 -> 0.55456454 | AQ10: =AE10/AJ10 -> 0.41691434 | AR10: =AE10/AL10 -> 0.75178687 | AS10: =IT10 -> 1 | AT10: =S10*AS10 -> 1782028 | AU10: 0.9 | AV10: =(AJ10-(AE10*(1+$IS$2)+AF10+AG10+AH10+AI10))/AJ10 -> 0.083602341 | AW10: =(AE10*(1+$IS$2)+AF10+AG10)/AJ10 -> 0.59625597 | AX10: =(AE10*(1+$IS$2))/AJ10 -> 0.45860577 | AY10: =(AE10*(1+$IS$2))/(AE10*(1+$IS$2)+AF10+AG10) -> 0.76914244 | AZ10: =MIN(IF($AU10=100%,1,1+VLOOKUP(($AJ10-$AI10-$AH10-$AG10-$AF10-$AE10*(1+AZ$3))/$AJ10,Уголь_коэфф!$A:$B,2,1)-VLOOKUP($AO10,Уголь_коэфф!$A:$B,2,1)),1+(1-$AU10)) -> 1.1 | BA10: =MIN(IF($AU10=100%,1,1+VLOOKUP(($AJ10-$AI10-$AH10-$AG10-$AF10-$AE10*(1+BA$3))/$AJ10,Уголь_коэфф!$A:$B,2,1)-VLOOKUP($AO10,Уголь_коэфф!$A:$B,2,1)),1+(1-$AU10)) -> 1.1 | BB10: =MIN(IF($AU10=100%,1,1+VLOOKUP(($AJ10-$AI10-$AH10-$AG10-$AF10-$AE10*(1+BB$3))/$AJ10,Уголь_коэфф!$A:$B,2,1)-VLOOKUP($AO10,Уголь_коэфф!$A:$B,2,1)),1+(1-$AU10)) -> 1.1 | BC10: =MIN(IF($AU10=100%,1,1+VLOOKUP(($AJ10-$AI10-$AH10-$AG10-$AF10-$AE10*(1+BC$3))/$AJ10,Уголь_коэфф!$A:$B,2,1)-VLOOKUP($AO10,Уголь_коэфф!$A:$B,2,1)),1+(1-$AU10)) -> 1.1 | BD10: =MIN(IF($AU10=100%,1,1+VLOOKUP(($AJ10-$AI10-$AH10-$AG10-$AF10-$AE10*(1+BD$3))/$AJ10,Уголь_коэфф!$A:$B,2,1)-VLOOKUP($AO10,Уголь_коэфф!$A:$B,2,1)),1+(1-$AU10)) -> 1.1 | BE10: =MIN(IF($AU10=100%,1,1+VLOOKUP(($AJ10-$AI10-$AH10-$AG10-$AF10-$AE10*(1+BE$3))/$AJ10,Уголь_коэфф!$A:$B,2,1)-VLOOKUP($AO10,Уголь_коэфф!$A:$B,2,1)),1+(1-$AU10)) -> 1.1 | BF10: =MIN(IF($AU10=100%,1,1+VLOOKUP(($AJ10-$AI10-$AH10-$AG10-$AF10-$AE10*(1+BF$3))/$AJ10,Уголь_коэфф!$A:$B,2,1)-VLOOKUP($AO10,Уголь_коэфф!$A:$B,2,1)),1+(1-$AU10)) -> 1.1 | BG10: =MIN(IF($AU10=100%,1,1+VLOOKUP(($AJ10-$AI10-$AH10-$AG10-$AF10-$AE10*(1+BG$3))/$AJ10,Уголь_коэфф!$A:$B,2,1)-VLOOKUP($AO10,Уголь_коэфф!$A:$B,2,1)),1+(1-$AU10)) -> 1.1 | ... EU10: =MIN(IF($AU10=100%,1,1+VLOOKUP(($AJ10-$AI10-$AH10-$AG10-$AF10-$AE10*(1+EU$3))/$AJ10,Уголь_коэфф!$A:$B,2,1)-VLOOKUP($AO10,Уголь_коэфф!$A:$B,2,1)),1+(1-$AU10)) -> 1 | EV10: 1 | EW10: =MIN(1,MAX(VLOOKUP(($AJ10-$AI10-$AH10-$AG10-$AF10-$AE10*(1+EW$3))/$AJ10,Уголь_коэфф!$A:$B,2,1),(EV10-0.05))) -> 1 | EX10: =MIN(1,MAX(VLOOKUP(($AJ10-$AI10-$AH10-$AG10-$AF10-$AE10*(1+EX$3))/$AJ10,Уголь_коэфф!$A:$B,2,1),(EW10-0.05))) -> 1 | EY10: =MIN(1,MAX(VLOOKUP(($AJ10-$AI10-$AH10-$AG10-$AF10-$AE10*(1+EY$3))/$AJ10,Уголь_коэфф!$A:$B,2,1),(EX10-0.05))) -> 1 | EZ10: =MIN(1,MAX(VLOOKUP(($AJ10-$AI10-$AH10-$AG10-$AF10-$AE10*(1+EZ$3))/$AJ10,Уголь_коэфф!$A:$B,2,1),(EY10-0.05))) -> 1 | FA10: =MIN(1,MAX(VLOOKUP(($AJ10-$AI10-$AH10-$AG10-$AF10-$AE10*(1+FA$3))/$AJ10,Уголь_коэфф!$A:$B,2,1),(EZ10-0.05))) -> 1 | FB10: =MIN(1,MAX(VLOOKUP(($AJ10-$AI10-$AH10-$AG10-$AF10-$AE10*(1+FB$3))/$AJ10,Уголь_коэфф!$A:$B,2,1),(FA10-0.05))) -> 1 | FC10: =MIN(1,MAX(VLOOKUP(($AJ10-$AI10-$AH10-$AG10-$AF10-$AE10*(1+FC$3))/$AJ10,Уголь_коэфф!$A:$B,2,1),(FB10-0.05))) -> 1 | FD10: =MIN(1,MAX(VLOOKUP(($AJ10-$AI10-$AH10-$AG10-$AF10-$AE10*(1+FD$3))/$AJ10,Уголь_коэфф!$A:$B,2,1),(FC10-0.05))) -> 1 | ... IR10: =MIN(1,MAX(VLOOKUP(($AJ10-$AI10-$AH10-$AG10-$AF10-$AE10*(1+IR$3))/$AJ10,Уголь_коэфф!$A:$B,2,1),(IQ10-0.05))) -> 0.965 | IS10: =HLOOKUP($IS$2,$AZ$3:$IR$27,ROW(IR10)-2,FALSE) -> 1 | IT10: =IF($IV$2=1,IF(AND($IT$2="индексация",IS10<1,IS10*$IV$1>1),1,IF(AND($IT$2="индексация",IS10=1),1,IF(AND($IT$2="скидка",IS10=1),1,IS10*$IV$1))),IS10*$IV$1) -> 1
A11: уголь энергетический (кроме антрацита)ЭкспортСеверо-Западное | B11: 1 | C11: Уголь каменный | D11: 16117 | E11: УГОЛЬ СС | F11: уголь энергетический (кроме антрацита) | G11: ЗСБ | H11: ОКТ | I11: БОЧАТЫ | J11: ЛУЖСКАЯ-ЭКСП | K11: 4156 | L11: полувагон | M11: Экспорт | N11: неконтейнерная | O11: Северо-Западное | P11: 82365518 | Q11: АО "АТРИУМ" | R11: ООО "УГМК-Холдинг" | S11: 1822456 | T11: 7574874184 | U11: 25338 | W11: 3281208376 | X11: 69 | Y11: маршрутная | Z11: 11 | AA11: 12 | AB11: 4 | AC11: 2082.23 | AD11: 928.76 | AE11: =AC11+AD11 -> 3010.99 | AF11: ='Цены,перевалка,аренда'!$C$27*SUM(Уголь_эластика_экспорт!Z11+Уголь_эластика_экспорт!AA11+Уголь_эластика_экспорт!AB11)/Уголь_эластика_экспорт!X11 -> 273.91304 | AG11: =SUMIF('Цены,перевалка,аренда'!$A$20:$A$22,Уголь_эластика_экспорт!$O11,'Цены,перевалка,аренда'!$D$20:$D$22) -> 610.444 | AI11: 2736 | AJ11: =SUMIF('Цены,перевалка,аренда'!$A$5:$A$17,Уголь_эластика_экспорт!A11,'Цены,перевалка,аренда'!$D$5:$D$17) -> 6485.9675 | AK11: =AJ11/'Цены,перевалка,аренда'!$C$1 -> 85 | AL11: =AE11+AF11+AG11 -> 3895.347 | AM11: =AJ11-AL11 -> 2590.6205 | AN11: =AI11+AH11+AG11+AF11+AE11 -> 6631.347 | AO11: =(AJ11-AN11)/AJ11 -> -0.022414473 | AP11: =AL11/AJ11 -> 0.60058072 | AQ11: =AE11/AJ11 -> 0.46423144 | AR11: =AE11/AL11 -> 0.77297092 | AS11: =IT11 -> 0.975 | AT11: =S11*AS11 -> 1776894.6 | AU11: 0.9 | AV11: =(AJ11-(AE11*(1+$IS$2)+AF11+AG11+AH11+AI11))/AJ11 -> -0.068837617 | AW11: =(AE11*(1+$IS$2)+AF11+AG11)/AJ11 -> 0.64700387 | AX11: =(AE11*(1+$IS$2))/AJ11 -> 0.51065458 | AY11: =(AE11*(1+$IS$2))/(AE11*(1+$IS$2)+AF11+AG11) -> 0.78926048 | AZ11: =MIN(IF($AU11=100%,1,1+VLOOKUP(($AJ11-$AI11-$AH11-$AG11-$AF11-$AE11*(1+AZ$3))/$AJ11,Уголь_коэфф!$A:$B,2,1)-VLOOKUP($AO11,Уголь_коэфф!$A:$B,2,1)),1+(1-$AU11)) -> 1.097 | BA11: =MIN(IF($AU11=100%,1,1+VLOOKUP(($AJ11-$AI11-$AH11-$AG11-$AF11-$AE11*(1+BA$3))/$AJ11,Уголь_коэфф!$A:$B,2,1)-VLOOKUP($AO11,Уголь_коэфф!$A:$B,2,1)),1+(1-$AU11)) -> 1.097 | BB11: =MIN(IF($AU11=100%,1,1+VLOOKUP(($AJ11-$AI11-$AH11-$AG11-$AF11-$AE11*(1+BB$3))/$AJ11,Уголь_коэфф!$A:$B,2,1)-VLOOKUP($AO11,Уголь_коэфф!$A:$B,2,1)),1+(1-$AU11)) -> 1.097 | BC11: =MIN(IF($AU11=100%,1,1+VLOOKUP(($AJ11-$AI11-$AH11-$AG11-$AF11-$AE11*(1+BC$3))/$AJ11,Уголь_коэфф!$A:$B,2,1)-VLOOKUP($AO11,Уголь_коэфф!$A:$B,2,1)),1+(1-$AU11)) -> 1.097 | BD11: =MIN(IF($AU11=100%,1,1+VLOOKUP(($AJ11-$AI11-$AH11-$AG11-$AF11-$AE11*(1+BD$3))/$AJ11,Уголь_коэфф!$A:$B,2,1)-VLOOKUP($AO11,Уголь_коэфф!$A:$B,2,1)),1+(1-$AU11)) -> 1.097 | BE11: =MIN(IF($AU11=100%,1,1+VLOOKUP(($AJ11-$AI11-$AH11-$AG11-$AF11-$AE11*(1+BE$3))/$AJ11,Уголь_коэфф!$A:$B,2,1)-VLOOKUP($AO11,Уголь_коэфф!$A:$B,2,1)),1+(1-$AU11)) -> 1.091 | BF11: =MIN(IF($AU11=100%,1,1+VLOOKUP(($AJ11-$AI11-$AH11-$AG11-$AF11-$AE11*(1+BF$3))/$AJ11,Уголь_коэфф!$A:$B,2,1)-VLOOKUP($AO11,Уголь_коэфф!$A:$B,2,1)),1+(1-$AU11)) -> 1.091 | BG11: =MIN(IF($AU11=100%,1,1+VLOOKUP(($AJ11-$AI11-$AH11-$AG11-$AF11-$AE11*(1+BG$3))/$AJ11,Уголь_коэфф!$A:$B,2,1)-VLOOKUP($AO11,Уголь_коэфф!$A:$B,2,1)),1+(1-$AU11)) -> 1.091 | ... EU11: =MIN(IF($AU11=100%,1,1+VLOOKUP(($AJ11-$AI11-$AH11-$AG11-$AF11-$AE11*(1+EU$3))/$AJ11,Уголь_коэфф!$A:$B,2,1)-VLOOKUP($AO11,Уголь_коэфф!$A:$B,2,1)),1+(1-$AU11)) -> 1 | EV11: 1 | EW11: =MIN(1,MAX(VLOOKUP(($AJ11-$AI11-$AH11-$AG11-$AF11-$AE11*(1+EW$3))/$AJ11,Уголь_коэфф!$A:$B,2,1),(EV11-0.05))) -> 0.995 | EX11: =MIN(1,MAX(VLOOKUP(($AJ11-$AI11-$AH11-$AG11-$AF11-$AE11*(1+EX$3))/$AJ11,Уголь_коэфф!$A:$B,2,1),(EW11-0.05))) -> 0.995 | EY11: =MIN(1,MAX(VLOOKUP(($AJ11-$AI11-$AH11-$AG11-$AF11-$AE11*(1+EY$3))/$AJ11,Уголь_коэфф!$A:$B,2,1),(EX11-0.05))) -> 0.995 | EZ11: =MIN(1,MAX(VLOOKUP(($AJ11-$AI11-$AH11-$AG11-$AF11-$AE11*(1+EZ$3))/$AJ11,Уголь_коэфф!$A:$B,2,1),(EY11-0.05))) -> 0.99 | FA11: =MIN(1,MAX(VLOOKUP(($AJ11-$AI11-$AH11-$AG11-$AF11-$AE11*(1+FA$3))/$AJ11,Уголь_коэфф!$A:$B,2,1),(EZ11-0.05))) -> 0.99 | FB11: =MIN(1,MAX(VLOOKUP(($AJ11-$AI11-$AH11-$AG11-$AF11-$AE11*(1+FB$3))/$AJ11,Уголь_коэфф!$A:$B,2,1),(FA11-0.05))) -> 0.99 | FC11: =MIN(1,MAX(VLOOKUP(($AJ11-$AI11-$AH11-$AG11-$AF11-$AE11*(1+FC$3))/$AJ11,Уголь_коэфф!$A:$B,2,1),(FB11-0.05))) -> 0.99 | FD11: =MIN(1,MAX(VLOOKUP(($AJ11-$AI11-$AH11-$AG11-$AF11-$AE11*(1+FD$3))/$AJ11,Уголь_коэфф!$A:$B,2,1),(FC11-0.05))) -> 0.985 | ... IR11: =MIN(1,MAX(VLOOKUP(($AJ11-$AI11-$AH11-$AG11-$AF11-$AE11*(1+IR$3))/$AJ11,Уголь_коэфф!$A:$B,2,1),(IQ11-0.05))) -> 0.872 | IS11: =HLOOKUP($IS$2,$AZ$3:$IR$27,ROW(IR11)-2,FALSE) -> 0.975 | IT11: =IF($IV$2=1,IF(AND($IT$2="индексация",IS11<1,IS11*$IV$1>1),1,IF(AND($IT$2="индексация",IS11=1),1,IF(AND($IT$2="скидка",IS11=1),1,IS11*$IV$1))),IS11*$IV$1) -> 0.975
A12: уголь энергетический (кроме антрацита)ЭкспортЮжное | B12: 1 | C12: Уголь каменный | D12: 16112 | E12: УГОЛЬ Д | F12: уголь энергетический (кроме антрацита) | G12: ЗСБ | H12: СКВ | I12: ЕРУНАКОВО | J12: ТУАПСЕ-СОР-Э | K12: 4637 | L12: полувагон | M12: Экспорт | N12: неконтейнерная | O12: Южное | P12: 82365518 | Q12: АО "АТРИУМ" | R12: ООО "УГМК-Холдинг" | S12: 1389317 | T12: 6442749019 | U12: 19610 | W12: 2689139106 | X12: 69 | Y12: маршрутная | Z12: 11 | AA12: 12 | AB12: 4 | AC12: 2198.94 | AD12: 1008.93 | AE12: =AC12+AD12 -> 3207.87 | AF12: ='Цены,перевалка,аренда'!$C$27*SUM(Уголь_эластика_экспорт!Z12+Уголь_эластика_экспорт!AA12+Уголь_эластика_экспорт!AB12)/Уголь_эластика_экспорт!X12 -> 273.91304 | AG12: =SUMIF('Цены,перевалка,аренда'!$A$20:$A$22,Уголь_эластика_экспорт!$O12,'Цены,перевалка,аренда'!$D$20:$D$22) -> 991.9715 | AI12: 2736 | AJ12: =SUMIF('Цены,перевалка,аренда'!$A$5:$A$17,Уголь_эластика_экспорт!A12,'Цены,перевалка,аренда'!$D$5:$D$17) -> 7249.0225 | AK12: =AJ12/'Цены,перевалка,аренда'!$C$1 -> 95 | AL12: =AE12+AF12+AG12 -> 4473.7545 | AM12: =AJ12-AL12 -> 2775.268 | AN12: =AI12+AH12+AG12+AF12+AE12 -> 7209.7545 | AO12: =(AJ12-AN12)/AJ12 -> 0.0054170002 | AP12: =AL12/AJ12 -> 0.6171528 | AQ12: =AE12/AJ12 -> 0.44252449 | AR12: =AE12/AL12 -> 0.71704202 | AS12: =IT12 -> 0.99 | AT12: =S12*AS12 -> 1375423.8 | AU12: 0.9 | AV12: =(AJ12-(AE12*(1+$IS$2)+AF12+AG12+AH12+AI12))/AJ12 -> -0.038835449 | AW12: =(AE12*(1+$IS$2)+AF12+AG12)/AJ12 -> 0.66140525 | AX12: =(AE12*(1+$IS$2))/AJ12 -> 0.48677694 | AY12: =(AE12*(1+$IS$2))/(AE12*(1+$IS$2)+AF12+AG12) -> 0.73597381 | AZ12: =MIN(IF($AU12=100%,1,1+VLOOKUP(($AJ12-$AI12-$AH12-$AG12-$AF12-$AE12*(1+AZ$3))/$AJ12,Уголь_коэфф!$A:$B,2,1)-VLOOKUP($AO12,Уголь_коэфф!$A:$B,2,1)),1+(1-$AU12)) -> 1.1 | BA12: =MIN(IF($AU12=100%,1,1+VLOOKUP(($AJ12-$AI12-$AH12-$AG12-$AF12-$AE12*(1+BA$3))/$AJ12,Уголь_коэфф!$A:$B,2,1)-VLOOKUP($AO12,Уголь_коэфф!$A:$B,2,1)),1+(1-$AU12)) -> 1.1 | BB12: =MIN(IF($AU12=100%,1,1+VLOOKUP(($AJ12-$AI12-$AH12-$AG12-$AF12-$AE12*(1+BB$3))/$AJ12,Уголь_коэфф!$A:$B,2,1)-VLOOKUP($AO12,Уголь_коэфф!$A:$B,2,1)),1+(1-$AU12)) -> 1.1 | BC12: =MIN(IF($AU12=100%,1,1+VLOOKUP(($AJ12-$AI12-$AH12-$AG12-$AF12-$AE12*(1+BC$3))/$AJ12,Уголь_коэфф!$A:$B,2,1)-VLOOKUP($AO12,Уголь_коэфф!$A:$B,2,1)),1+(1-$AU12)) -> 1.1 | BD12: =MIN(IF($AU12=100%,1,1+VLOOKUP(($AJ12-$AI12-$AH12-$AG12-$AF12-$AE12*(1+BD$3))/$AJ12,Уголь_коэфф!$A:$B,2,1)-VLOOKUP($AO12,Уголь_коэфф!$A:$B,2,1)),1+(1-$AU12)) -> 1.098 | BE12: =MIN(IF($AU12=100%,1,1+VLOOKUP(($AJ12-$AI12-$AH12-$AG12-$AF12-$AE12*(1+BE$3))/$AJ12,Уголь_коэфф!$A:$B,2,1)-VLOOKUP($AO12,Уголь_коэфф!$A:$B,2,1)),1+(1-$AU12)) -> 1.098 | BF12: =MIN(IF($AU12=100%,1,1+VLOOKUP(($AJ12-$AI12-$AH12-$AG12-$AF12-$AE12*(1+BF$3))/$AJ12,Уголь_коэфф!$A:$B,2,1)-VLOOKUP($AO12,Уголь_коэфф!$A:$B,2,1)),1+(1-$AU12)) -> 1.098 | BG12: =MIN(IF($AU12=100%,1,1+VLOOKUP(($AJ12-$AI12-$AH12-$AG12-$AF12-$AE12*(1+BG$3))/$AJ12,Уголь_коэфф!$A:$B,2,1)-VLOOKUP($AO12,Уголь_коэфф!$A:$B,2,1)),1+(1-$AU12)) -> 1.098 | ... EU12: =MIN(IF($AU12=100%,1,1+VLOOKUP(($AJ12-$AI12-$AH12-$AG12-$AF12-$AE12*(1+EU$3))/$AJ12,Уголь_коэфф!$A:$B,2,1)-VLOOKUP($AO12,Уголь_коэфф!$A:$B,2,1)),1+(1-$AU12)) -> 1 | EV12: 1 | EW12: =MIN(1,MAX(VLOOKUP(($AJ12-$AI12-$AH12-$AG12-$AF12-$AE12*(1+EW$3))/$AJ12,Уголь_коэфф!$A:$B,2,1),(EV12-0.05))) -> 1 | EX12: =MIN(1,MAX(VLOOKUP(($AJ12-$AI12-$AH12-$AG12-$AF12-$AE12*(1+EX$3))/$AJ12,Уголь_коэфф!$A:$B,2,1),(EW12-0.05))) -> 1 | EY12: =MIN(1,MAX(VLOOKUP(($AJ12-$AI12-$AH12-$AG12-$AF12-$AE12*(1+EY$3))/$AJ12,Уголь_коэфф!$A:$B,2,1),(EX12-0.05))) -> 1 | EZ12: =MIN(1,MAX(VLOOKUP(($AJ12-$AI12-$AH12-$AG12-$AF12-$AE12*(1+EZ$3))/$AJ12,Уголь_коэфф!$A:$B,2,1),(EY12-0.05))) -> 1 | FA12: =MIN(1,MAX(VLOOKUP(($AJ12-$AI12-$AH12-$AG12-$AF12-$AE12*(1+FA$3))/$AJ12,Уголь_коэфф!$A:$B,2,1),(EZ12-0.05))) -> 1 | FB12: =MIN(1,MAX(VLOOKUP(($AJ12-$AI12-$AH12-$AG12-$AF12-$AE12*(1+FB$3))/$AJ12,Уголь_коэфф!$A:$B,2,1),(FA12-0.05))) -> 1 | FC12: =MIN(1,MAX(VLOOKUP(($AJ12-$AI12-$AH12-$AG12-$AF12-$AE12*(1+FC$3))/$AJ12,Уголь_коэфф!$A:$B,2,1),(FB12-0.05))) -> 1 | FD12: =MIN(1,MAX(VLOOKUP(($AJ12-$AI12-$AH12-$AG12-$AF12-$AE12*(1+FD$3))/$AJ12,Уголь_коэфф!$A:$B,2,1),(FC12-0.05))) -> 1 | ... IR12: =MIN(1,MAX(VLOOKUP(($AJ12-$AI12-$AH12-$AG12-$AF12-$AE12*(1+IR$3))/$AJ12,Уголь_коэфф!$A:$B,2,1),(IQ12-0.05))) -> 0.896 | IS12: =HLOOKUP($IS$2,$AZ$3:$IR$27,ROW(IR12)-2,FALSE) -> 0.99 | IT12: =IF($IV$2=1,IF(AND($IT$2="индексация",IS12<1,IS12*$IV$1>1),1,IF(AND($IT$2="индексация",IS12=1),1,IF(AND($IT$2="скидка",IS12=1),1,IS12*$IV$1))),IS12*$IV$1) -> 0.99
